#VRML_SIM R2020a utf8
DEF wall5 WorldInfo {
}
Robot {
  translation 0.426570572956098 5.501808236851612 0.08332075632750639
  rotation -0.06894513363545762 0.9632373170944496 0.25965446174613616 -0.14299749002000964
  children [
    Display {
      name "Lidar_Display"
    }
    HokuyoUtm30lx {
      translation 0 0.1 0
      rotation 0 1 0 -1.5708
    }
    Compass {
      name "Hexabot_Compass"
    }
    Gyro {
      name "Hexabot_Gyro"
    }
    GPS {
      name "Hexabot_GPS"
    }
    Camera {
      translation 0.1 -1.12008e-13 -1.49482e-07
      rotation 8.684229999951365e-07 -0.9999999999943995 3.2321499999818985e-06 1.5707853071795865
      children [
        DEF CAM_SHAPE Shape {
          appearance MattePaint {
            baseColor 0.7 0.1 0.1
          }
          geometry Cylinder {
            height 0.05
            radius 0.0125
          }
        }
      ]
      name "Hexabot_Camera"
      boundingObject USE CAM_SHAPE
      physics Physics {
      }
      lens Lens {
      }
      focus Focus {
      }
      recognition Recognition {
      }
    }
    DEF BODY_TRAN Transform {
      children [
        DEF BODY Shape {
          appearance MattePaint {
            baseColor 0.1 0.1 0.7
          }
          geometry Box {
            size 0.2 0.05 0.125
          }
        }
      ]
    }
    Hinge2Joint {
      jointParameters HingeJointParameters {
        position -0.1234334613487402
      }
      jointParameters2 JointParameters {
        position -0.10487756309931862
        axis 0 1 0
      }
      device [
        DEF SHOULDER_2_x RotationalMotor {
          name "Hexabot_Leg0_Motor1"
        }
      ]
      device2 [
        DEF SHOULDER_0_y RotationalMotor {
          name "Hexabot_Leg0_Motor2"
        }
      ]
      endPoint DEF SHOULDER_0 Solid {
        translation 0.08438087092635028 -0.00709799543251984 0.03967672116556953
        rotation 0.976376298693868 0.042130326200631396 -0.21193008036399907 1.9588649054822234
        children [
          Transform {
            children [
              DEF FEMUR_0 Solid {
                translation 0 0.025981 -0.0450019
                rotation 1 0 0 0.523599
                children [
                  HingeJoint {
                    jointParameters HingeJointParameters {
                      position -0.37498190066332415
                      axis 0 0 1
                    }
                    device [
                      DEF ELBOW_0 RotationalMotor {
                        name "Hexabot_Leg0_Motor3"
                      }
                    ]
                    endPoint Solid {
                      translation -0.00023574644339153134 -0.0006966206027653184 -0.058563902416361606
                      rotation -0.7445302728669337 -0.6492592300581672 -0.15536127242322992 2.8395772255680063
                      children [
                        Transform {
                          children [
                            Solid {
                              translation 0.0824507 0 0.0210637
                              rotation 0 -1 0 1.8325953071795864
                              children [
                                Shape {
                                  appearance MattePaint {
                                    baseColor 0.1 0.1 0.6
                                  }
                                  geometry DEF TIBIA_SHAPE Box {
                                    size 0.025 0.025 0.15
                                  }
                                }
                              ]
                              boundingObject USE TIBIA_SHAPE
                              physics Physics {
                              }
                            }
                            DEF ELBOW_SHAPE Shape {
                              appearance MattePaint {
                                baseColor 0 0 0
                              }
                              geometry Cylinder {
                                height 0.025
                                radius 0.0125
                              }
                            }
                          ]
                        }
                      ]
                      boundingObject USE ELBOW_SHAPE
                      physics Physics {
                      }
                      linearVelocity 0.013570745948972836 -0.09712037945733232 -0.011621895630079048
                      angularVelocity -0.8804326605697039 0.045780764616322966 -0.1667183345605439
                    }
                  }
                  DEF FEMUR_SHAPE Shape {
                    appearance MattePaint {
                      baseColor 0.2 0.2 1
                    }
                    geometry Box {
                      size 0.025 0.025 0.1
                    }
                  }
                ]
                boundingObject USE FEMUR_SHAPE
                physics Physics {
                }
              }
              Shape {
                appearance MattePaint {
                  baseColor 0 0 0
                }
                geometry DEF SHOULDER_SHAPE Sphere {
                  radius 0.02
                }
              }
            ]
          }
        ]
        name "solid(5)"
        boundingObject USE SHOULDER_SHAPE
        physics Physics {
        }
        linearVelocity 0.013567343688423071 -0.17253032804639734 -0.031996080827296144
        angularVelocity -0.9325552264306736 -0.07032633539784588 -0.32598593284070504
      }
    }
    Hinge2Joint {
      jointParameters HingeJointParameters {
        position 0.523418877971202
      }
      jointParameters2 JointParameters {
        position -0.2951722193466352
        axis 0 1 0
      }
      device [
        DEF SHOULDER_2_x RotationalMotor {
          name "Hexabot_Leg1_Motor1"
        }
      ]
      device2 [
        DEF SHOULDER_0_y RotationalMotor {
          name "Hexabot_Leg1_Motor2"
        }
      ]
      endPoint DEF SHOULDER_0 Solid {
        translation -0.006601839103966254 -0.020813829137144017 0.055713252192976126
        rotation 0.9981464173048253 -0.026187059919332577 -0.05493603111185641 1.8094737949591642
        children [
          Transform {
            children [
              DEF FEMUR_0 Solid {
                translation 0 0.025981 -0.0450019
                rotation 1 0 0 0.523599
                children [
                  HingeJoint {
                    jointParameters HingeJointParameters {
                      position -0.2250188264744657
                      axis 0 0 1
                    }
                    device [
                      DEF ELBOW_0 RotationalMotor {
                        name "Hexabot_Leg1_Motor3"
                      }
                    ]
                    endPoint Solid {
                      translation -0.00013525401078252962 -0.0006123265410029945 -0.05861795080600522
                      rotation -0.6950369166981943 -0.704478655207515 -0.1436436868911354 2.81695177919303
                      children [
                        Transform {
                          children [
                            Solid {
                              translation 0.0824507 0 0.0210637
                              rotation 0 -1 0 1.8325953071795864
                              children [
                                Shape {
                                  appearance MattePaint {
                                    baseColor 0.1 0.1 0.6
                                  }
                                  geometry DEF TIBIA_SHAPE Box {
                                    size 0.025 0.025 0.15
                                  }
                                }
                              ]
                              boundingObject USE TIBIA_SHAPE
                              physics Physics {
                              }
                            }
                            DEF ELBOW_SHAPE Shape {
                              appearance MattePaint {
                                baseColor 0 0 0
                              }
                              geometry Cylinder {
                                height 0.025
                                radius 0.0125
                              }
                            }
                          ]
                        }
                      ]
                      boundingObject USE ELBOW_SHAPE
                      physics Physics {
                      }
                      linearVelocity -0.037894677778141664 -0.14793133432634528 -0.03660164385947551
                      angularVelocity -0.34492918829125196 -0.3622232437437445 -0.4228130176636374
                    }
                  }
                  DEF FEMUR_SHAPE Shape {
                    appearance MattePaint {
                      baseColor 0.2 0.2 1
                    }
                    geometry Box {
                      size 0.025 0.025 0.1
                    }
                  }
                ]
                boundingObject USE FEMUR_SHAPE
                physics Physics {
                }
              }
              Shape {
                appearance MattePaint {
                  baseColor 0 0 0
                }
                geometry DEF SHOULDER_SHAPE Sphere {
                  radius 0.02
                }
              }
            ]
          }
        ]
        name "solid(4)"
        boundingObject USE SHOULDER_SHAPE
        physics Physics {
        }
        linearVelocity -0.00010380854493757807 -0.1854180901296457 -0.0347365222103799
        angularVelocity -0.34152898666763887 -0.2196572700408746 -0.27709400186081434
      }
    }
    Hinge2Joint {
      jointParameters HingeJointParameters {
        position 1.0765981985910775
      }
      jointParameters2 JointParameters {
        position -0.10479223388663177
        axis 0 1 0
      }
      device [
        DEF SHOULDER_2_x RotationalMotor {
          name "Hexabot_Leg2_Motor1"
        }
      ]
      device2 [
        DEF SHOULDER_0_y RotationalMotor {
          name "Hexabot_Leg2_Motor2"
        }
      ]
      endPoint DEF SHOULDER_0 Solid {
        translation -0.08538038106852228 -0.002474962635363922 0.054687747267011685
        rotation 0.9959116638051234 0.010251580755345688 -0.08974888851081901 2.1497466506978467
        children [
          Transform {
            children [
              DEF FEMUR_0 Solid {
                translation 0 0.025981 -0.0450019
                rotation 1 0 0 0.523599
                children [
                  HingeJoint {
                    jointParameters HingeJointParameters {
                      position -0.3749820081084574
                      axis 0 0 1
                    }
                    device [
                      DEF ELBOW_0 RotationalMotor {
                        name "Hexabot_Leg2_Motor3"
                      }
                    ]
                    endPoint Solid {
                      translation -0.00023210919946659727 -0.000660781681586242 -0.05857588456507884
                      rotation -0.751388039299857 -0.6574538636692064 -0.056306585259178435 3.0106815738292014
                      children [
                        Transform {
                          children [
                            Solid {
                              translation 0.0824507 0 0.0210637
                              rotation 0 -1 0 1.8325953071795864
                              children [
                                Shape {
                                  appearance MattePaint {
                                    baseColor 0.1 0.1 0.6
                                  }
                                  geometry DEF TIBIA_SHAPE Box {
                                    size 0.025 0.025 0.15
                                  }
                                }
                              ]
                              boundingObject USE TIBIA_SHAPE
                              physics Physics {
                              }
                            }
                            DEF ELBOW_SHAPE Shape {
                              appearance MattePaint {
                                baseColor 0 0 0
                              }
                              geometry Cylinder {
                                height 0.025
                                radius 0.0125
                              }
                            }
                          ]
                        }
                      ]
                      boundingObject USE ELBOW_SHAPE
                      physics Physics {
                      }
                      linearVelocity 0.006434227366052411 -0.025369704061662078 -0.02034010342250999
                      angularVelocity -0.9334433043702637 -0.024578054633203505 -0.07163621376021317
                    }
                  }
                  DEF FEMUR_SHAPE Shape {
                    appearance MattePaint {
                      baseColor 0.2 0.2 1
                    }
                    geometry Box {
                      size 0.025 0.025 0.1
                    }
                  }
                ]
                boundingObject USE FEMUR_SHAPE
                physics Physics {
                }
              }
              Shape {
                appearance MattePaint {
                  baseColor 0 0 0
                }
                geometry DEF SHOULDER_SHAPE Sphere {
                  radius 0.02
                }
              }
            ]
          }
        ]
        name "solid(3)"
        boundingObject USE SHOULDER_SHAPE
        physics Physics {
        }
        linearVelocity 0.011569648504670665 -0.12341967526112521 -0.052035192476295594
        angularVelocity -0.9432973493961696 -0.10902804533763433 -0.256940647803925
      }
    }
    Hinge2Joint {
      jointParameters HingeJointParameters {
        position -0.076559146547076
      }
      jointParameters2 JointParameters {
        position -0.1243099741955651
        axis 0 1 0
      }
      device [
        DEF SHOULDER_3_x RotationalMotor {
          name "Hexabot_Leg3_Motor1"
        }
      ]
      device2 [
        DEF SHOULDER_3_y RotationalMotor {
          name "Hexabot_Leg3_Motor2"
        }
      ]
      endPoint DEF SHOULDER_0 Solid {
        translation -0.09153508710028854 0.007538354973496201 -0.03296970138999053
        rotation -0.48580178224540105 0.873454129170826 -0.03277975902330423 0.15733643739207637
        children [
          Transform {
            translation 0 0 -0.01
            children [
              DEF FEMUR_0 Solid {
                translation 0 0.0259808 -0.045
                rotation 1 0 0 0.523599
                children [
                  HingeJoint {
                    jointParameters HingeJointParameters {
                      position -0.33744690745552847
                      axis 0 0 1
                    }
                    device [
                      DEF ELBOW_3 RotationalMotor {
                        name "Hexabot_Leg3_Motor3"
                      }
                    ]
                    endPoint Solid {
                      translation -1.1479493977053187e-05 -2.239212386136585e-05 -0.06002055998798714
                      rotation 3.99069109661266e-05 4.970056850730249e-05 -0.999999997968646 1.6464453001507884
                      children [
                        Transform {
                          children [
                            Solid {
                              translation 0.0824507 0 0.0210637
                              rotation 0 -1 0 1.8325953071795864
                              children [
                                Shape {
                                  appearance MattePaint {
                                    baseColor 0.1 0.1 0.6
                                  }
                                  geometry DEF TIBIA_SHAPE Box {
                                    size 0.025 0.025 0.15
                                  }
                                }
                              ]
                              boundingObject USE TIBIA_SHAPE
                              physics Physics {
                              }
                            }
                            DEF ELBOW_SHAPE Shape {
                              appearance MattePaint {
                                baseColor 0 0 0
                              }
                              geometry Cylinder {
                                height 0.025
                                radius 0.0125
                              }
                            }
                          ]
                        }
                      ]
                      boundingObject USE ELBOW_SHAPE
                      physics Physics {
                      }
                      linearVelocity 0.09095448035522587 -0.25570765873162327 -0.058913499666819344
                      angularVelocity -0.35416925033232527 -0.4620248299290052 0.012602298677074575
                    }
                  }
                  DEF FEMUR_SHAPE Shape {
                    appearance MattePaint {
                      baseColor 0.2 0.2 1
                    }
                    geometry Box {
                      size 0.025 0.025 0.1
                    }
                  }
                ]
                boundingObject USE FEMUR_SHAPE
                physics Physics {
                }
              }
              Shape {
                appearance MattePaint {
                  baseColor 0 0 0
                }
                geometry DEF SHOULDER_SHAPE Sphere {
                  radius 0.02
                }
              }
            ]
          }
        ]
        name "solid(2)"
        boundingObject USE SHOULDER_SHAPE
        physics Physics {
        }
        linearVelocity 0.049649251072389655 -0.22419917262170785 -0.06862264726824496
        angularVelocity -0.35145653215452455 -0.3366154847031607 -0.23110540399277624
      }
    }
    Hinge2Joint {
      jointParameters HingeJointParameters {
        position -0.02343568253722232
      }
      jointParameters2 JointParameters {
        position -0.27568748680404676
        axis 0 1 0
      }
      device [
        DEF SHOULDER_4_x RotationalMotor {
          name "Hexabot_Leg4_Motor1"
        }
      ]
      device2 [
        DEF SHOULDER_4_y RotationalMotor {
          name "Hexabot_Leg4_Motor2"
        }
      ]
      endPoint DEF SHOULDER_0 Solid {
        translation -0.005628336847734087 -0.0012461506104046748 -0.05355910933225212
        rotation -0.08416740013871594 -0.9963832193985338 0.011675994814247494 0.276675511242742
        children [
          Transform {
            translation 0 0 -0.01
            children [
              DEF FEMUR_0 Solid {
                translation 0 0.0259808 -0.045
                rotation 1 0 0 0.523599
                children [
                  HingeJoint {
                    jointParameters HingeJointParameters {
                      position 0.1374468969196723
                      axis 0 0 1
                    }
                    device [
                      DEF ELBOW_4 RotationalMotor {
                        name "Hexabot_Leg4_Motor3"
                      }
                    ]
                    endPoint Solid {
                      translation -3.398746018216428e-12 2.4571790636458065e-11 -0.05999999999999947
                      rotation 2.0671468022233448e-10 2.3727508761883196e-10 -1 1.4333484102597607
                      children [
                        Transform {
                          children [
                            Solid {
                              translation 0.0824507 0 0.0210637
                              rotation 0 -1 0 1.8325953071795864
                              children [
                                Shape {
                                  appearance MattePaint {
                                    baseColor 0.1 0.1 0.6
                                  }
                                  geometry DEF TIBIA_SHAPE Box {
                                    size 0.025 0.025 0.15
                                  }
                                }
                              ]
                              boundingObject USE TIBIA_SHAPE
                              physics Physics {
                              }
                            }
                            DEF ELBOW_SHAPE Shape {
                              appearance MattePaint {
                                baseColor 0 0 0
                              }
                              geometry Cylinder {
                                height 0.025
                                radius 0.0125
                              }
                            }
                          ]
                        }
                      ]
                      boundingObject USE ELBOW_SHAPE
                      physics Physics {
                      }
                      linearVelocity -0.011970102373690839 -0.3918430118239734 -0.02837053195135651
                      angularVelocity -0.8310858655338176 0.17445059183469624 -0.531459574183253
                    }
                  }
                  DEF FEMUR_SHAPE Shape {
                    appearance MattePaint {
                      baseColor 0.2 0.2 1
                    }
                    geometry Box {
                      size 0.025 0.025 0.1
                    }
                  }
                ]
                boundingObject USE FEMUR_SHAPE
                physics Physics {
                }
              }
              Shape {
                appearance MattePaint {
                  baseColor 0 0 0
                }
                geometry DEF SHOULDER_SHAPE Sphere {
                  radius 0.02
                }
              }
            ]
          }
        ]
        name "solid(1)"
        boundingObject USE SHOULDER_SHAPE
        physics Physics {
        }
        linearVelocity 0.018928812237332757 -0.30145585459619617 -0.0478910458695709
        angularVelocity -0.930521135957835 0.03657019144702478 -0.3164650372976267
      }
    }
    Hinge2Joint {
      jointParameters HingeJointParameters {
        position 0.023438431727409184
      }
      jointParameters2 JointParameters {
        position -0.1243176760179073
        axis 0 1 0
      }
      device [
        DEF SHOULDER_5_x RotationalMotor {
          name "Hexabot_Leg5_Motor1"
        }
      ]
      device2 [
        DEF SHOULDER_5_y RotationalMotor {
          name "Hexabot_Leg5_Motor2"
        }
      ]
      endPoint DEF SHOULDER_0 Solid {
        translation 0.08682245390747477 0.001175369786979423 -0.04960317226300538
        rotation 0.18503791034889147 -0.9826638999037965 -0.011516577598270758 0.12650508661246418
        children [
          Transform {
            translation 0 0 -0.01
            children [
              DEF FEMUR_0 Solid {
                translation 0 0.0259808 -0.045
                rotation 1 0 0 0.523599
                children [
                  HingeJoint {
                    jointParameters HingeJointParameters {
                      position 0.0625531316091828
                      axis 0 0 1
                    }
                    device [
                      DEF ELBOW_5 RotationalMotor {
                        name "Hexabot_Leg5_Motor3"
                      }
                    ]
                    endPoint Solid {
                      translation 9.928128066390408e-24 -1.5850805856783443e-22 -0.06000000000000025
                      rotation -1.1940536631538939e-20 -4.086935770206737e-21 -1 1.508242175570366
                      children [
                        Transform {
                          children [
                            Solid {
                              translation 0.0824507 0 0.0210637
                              rotation 0 -1 0 1.8325953071795864
                              children [
                                Shape {
                                  appearance MattePaint {
                                    baseColor 0.1 0.1 0.6
                                  }
                                  geometry DEF TIBIA_SHAPE Box {
                                    size 0.025 0.025 0.15
                                  }
                                }
                              ]
                              boundingObject USE TIBIA_SHAPE
                              physics Physics {
                              }
                            }
                            DEF ELBOW_SHAPE Shape {
                              appearance MattePaint {
                                baseColor 0 0 0
                              }
                              geometry Cylinder {
                                height 0.025
                                radius 0.0125
                              }
                            }
                          ]
                        }
                      ]
                      boundingObject USE ELBOW_SHAPE
                      physics Physics {
                      }
                      recognitionColors [
                        0 0 0
                      ]
                      linearVelocity 0.0866740711214814 -0.3038545234053467 0.022633540782773853
                      angularVelocity -0.41223827976105276 -0.48369023812143164 -0.02612874998461262
                    }
                  }
                  DEF FEMUR_SHAPE Shape {
                    appearance MattePaint {
                      baseColor 0.2 0.2 1
                    }
                    geometry Box {
                      size 0.025 0.025 0.1
                    }
                  }
                ]
                boundingObject USE FEMUR_SHAPE
                physics Physics {
                }
              }
              Shape {
                appearance MattePaint {
                  baseColor 0 0 0
                }
                geometry DEF SHOULDER_SHAPE Sphere {
                  radius 0.02
                }
              }
            ]
          }
        ]
        boundingObject USE SHOULDER_SHAPE
        physics Physics {
        }
        linearVelocity 0.04492808219713797 -0.2665570843334425 -0.0023320094369348038
        angularVelocity -0.34910931295824865 -0.3366831129335232 -0.2486839843617843
      }
    }
  ]
  name "Hexabot(1)"
  boundingObject USE BODY_TRAN
  physics Physics {
  }
  controller "my_controller_c"
  linearVelocity 0.02182546875121804 -0.21588269166765886 -0.04304807808432845
  angularVelocity -0.6401738301841231 -0.15012595063517453 -0.2798323870472848
}
Viewpoint {
  orientation -0.13138606187266694 0.9319721254386593 0.3378840927758212 2.7376050516793335
  position 2.406955854428269 13.509880428270906 -7.2712333572407175
  followType "None"
}
TexturedBackground {
}
TexturedBackgroundLight {
}
RectangleArena {
  translation -4.97 -0.05 0
  floorSize 20 10
  floorTileSize 2.5 2.5
  floorAppearance RoughConcrete {
  }
  wallThickness 1
  wallHeight 5
  wallAppearance FormedConcrete {
  }
}
DEF Terrain_Subway Group {
  children [
    Group {
    }
    DEF wall3 Solid {
      translation -11.4943 2.46975 1.85952
      rotation 1 0 0 0
      children [
        Shape {
          appearance StonePavement {
          }
          geometry DEF wall3shape Box {
            size 7.25 5.5 0.75
          }
        }
      ]
      name "wall1(1)"
      boundingObject USE wall3shape
    }
    DEF wall3 Solid {
      translation -11.378 2.66017 -1.85691
      rotation 1 0 0 0
      children [
        Shape {
          appearance StonePavement {
          }
          geometry DEF wall3shape Box {
            size 7.25 5.5 0.75
          }
        }
      ]
      name "wall1(8)"
      boundingObject USE wall3shape
    }
    DEF wall2 Solid {
      translation -4.69226 2.65163 -1.89359
      rotation 0.0064122004361044 -0.999972017837339 0.003853210075779024 1.5861709297021291
      children [
        Shape {
          appearance StonePavement {
          }
          geometry DEF Wall2Shape Box {
            size 6.25 5.5 0.75
          }
        }
      ]
      name "wall2(1)"
      boundingObject USE Wall2Shape
    }
    DEF wall5 Solid {
      translation -1.18164 2.65795 -0.717194
      rotation -0.018116628923701052 -0.9997683507864505 -0.01162034948620672 0.013011261552344378
      children [
        DEF wall5 Shape {
          appearance StonePavement {
          }
          geometry Box {
            size 6.25 5.5 4
          }
        }
      ]
      name "wall5(1)"
      boundingObject USE wall5
    }
  ]
}
