#VRML_SIM R2020a utf8
WorldInfo {
  basicTimeStep 8
}
Robot {
  translation 0.1275338492047036 0.33335263599408727 -0.05174195970671479
  rotation -0.11978525142684487 0.9711506223574498 0.20619884149855372 -0.8043163168810424
  children [
    Display {
      name "Lidar_Display"
    }
    HokuyoUtm30lx {
      translation 0 0.1 0
      rotation 0 1 0 -1.5708
    }
    Compass {
      name "Hexabot_Compass"
    }
    Gyro {
      name "Hexabot_Gyro"
    }
    GPS {
      name "Hexabot_GPS"
    }
    Camera {
      translation 0.1 -1.12008e-13 -1.49482e-07
      rotation 8.684229999951365e-07 -0.9999999999943995 3.2321499999818985e-06 1.5707853071795865
      children [
        DEF CAM_SHAPE Shape {
          appearance MattePaint {
            baseColor 0.7 0.1 0.1
          }
          geometry Cylinder {
            height 0.05
            radius 0.0125
          }
        }
      ]
      name "Hexabot_Camera"
      boundingObject USE CAM_SHAPE
      physics Physics {
      }
      lens Lens {
      }
      focus Focus {
      }
      recognition Recognition {
      }
    }
    DEF BODY_TRAN Transform {
      children [
        DEF BODY Shape {
          appearance MattePaint {
            baseColor 0.1 0.1 0.7
          }
          geometry Box {
            size 0.2 0.05 0.125
          }
        }
      ]
    }
    Hinge2Joint {
      jointParameters HingeJointParameters {
        position -0.020775768394503208
      }
      jointParameters2 JointParameters {
        position -0.28190699024458665
        axis 0 1 0
      }
      device [
        DEF SHOULDER_2_x RotationalMotor {
          name "Hexabot_Leg0_Motor1"
        }
      ]
      device2 [
        DEF SHOULDER_0_y RotationalMotor {
          name "Hexabot_Leg0_Motor2"
        }
      ]
      endPoint DEF SHOULDER_0 Solid {
        translation 0.07628184150434222 -0.010830391836984608 0.05299564500280764
        rotation 0.993392202415054 -0.00024230052223361446 -0.11476878265201435 2.054067154285597
        children [
          Transform {
            children [
              DEF FEMUR_0 Solid {
                translation 0 0.025981 -0.0450019
                rotation 1 0 0 0.523599
                children [
                  HingeJoint {
                    jointParameters HingeJointParameters {
                      position -0.20431150047498434
                      axis 0 0 1
                    }
                    device [
                      DEF ELBOW_0 RotationalMotor {
                        name "Hexabot_Leg0_Motor3"
                      }
                    ]
                    endPoint Solid {
                      translation -0.00011400514699126976 -0.0007265393838109333 -0.0585639024163616
                      rotation -0.6878684175480271 -0.7117872081784069 -0.14211266802633152 2.814176013022017
                      children [
                        Transform {
                          children [
                            Solid {
                              translation 0.0824507 0 0.0210637
                              rotation 0 -1 0 1.8325953071795864
                              children [
                                Shape {
                                  appearance MattePaint {
                                    baseColor 0.1 0.1 0.6
                                  }
                                  geometry DEF TIBIA_SHAPE Box {
                                    size 0.025 0.025 0.15
                                  }
                                }
                              ]
                              boundingObject USE TIBIA_SHAPE
                              physics Physics {
                              }
                            }
                            DEF ELBOW_SHAPE Shape {
                              appearance MattePaint {
                                baseColor 0 0 0
                              }
                              geometry Cylinder {
                                height 0.025
                                radius 0.0125
                              }
                            }
                          ]
                        }
                      ]
                      boundingObject USE ELBOW_SHAPE
                      physics Physics {
                      }
                      linearVelocity -0.0025187747774119917 -0.007061137804363231 0.04065256593904446
                      angularVelocity -0.14659764248039783 -0.04719775182944633 -0.03290335327202808
                    }
                  }
                  DEF FEMUR_SHAPE Shape {
                    appearance MattePaint {
                      baseColor 0.2 0.2 1
                    }
                    geometry Box {
                      size 0.025 0.025 0.1
                    }
                  }
                ]
                boundingObject USE FEMUR_SHAPE
                physics Physics {
                }
              }
              Shape {
                appearance MattePaint {
                  baseColor 0 0 0
                }
                geometry DEF SHOULDER_SHAPE Sphere {
                  radius 0.02
                }
              }
            ]
          }
        ]
        name "solid(5)"
        boundingObject USE SHOULDER_SHAPE
        physics Physics {
        }
        linearVelocity 0.001713945174787141 -0.01901476235913573 0.03890133650002709
        angularVelocity -0.15634817841910162 -0.03555247098471756 -0.012896291187468083
      }
    }
    Hinge2Joint {
      jointParameters HingeJointParameters {
        position 0.4207721907064833
      }
      jointParameters2 JointParameters {
        position -0.11809042728036706
        axis 0 1 0
      }
      device [
        DEF SHOULDER_2_x RotationalMotor {
          name "Hexabot_Leg1_Motor1"
        }
      ]
      device2 [
        DEF SHOULDER_0_y RotationalMotor {
          name "Hexabot_Leg1_Motor2"
        }
      ]
      endPoint DEF SHOULDER_0 Solid {
        translation 0.003834422557887911 -0.015095879462317269 0.05777696651547042
        rotation 0.9915577100164179 0.07640995362578433 -0.10476080705064586 1.7049452127392188
        children [
          Transform {
            children [
              DEF FEMUR_0 Solid {
                translation 0 0.025981 -0.0450019
                rotation 1 0 0 0.523599
                children [
                  HingeJoint {
                    jointParameters HingeJointParameters {
                      position -0.39568862055740284
                      axis 0 0 1
                    }
                    device [
                      DEF ELBOW_0 RotationalMotor {
                        name "Hexabot_Leg1_Motor3"
                      }
                    ]
                    endPoint Solid {
                      translation -0.00023728797603660514 -0.0005804583160554285 -0.0586179508060052
                      rotation -0.7510358567851211 -0.6413819018871609 -0.15676223318978105 2.842603232601053
                      children [
                        Transform {
                          children [
                            Solid {
                              translation 0.0824507 0 0.0210637
                              rotation 0 -1 0 1.8325953071795864
                              children [
                                Shape {
                                  appearance MattePaint {
                                    baseColor 0.1 0.1 0.6
                                  }
                                  geometry DEF TIBIA_SHAPE Box {
                                    size 0.025 0.025 0.15
                                  }
                                }
                              ]
                              boundingObject USE TIBIA_SHAPE
                              physics Physics {
                              }
                            }
                            DEF ELBOW_SHAPE Shape {
                              appearance MattePaint {
                                baseColor 0 0 0
                              }
                              geometry Cylinder {
                                height 0.025
                                radius 0.0125
                              }
                            }
                          ]
                        }
                      ]
                      boundingObject USE ELBOW_SHAPE
                      physics Physics {
                      }
                      linearVelocity 0.034327220786588994 -0.06497528173167805 0.05568793833920724
                      angularVelocity 0.020700885574111233 0.20944070007000934 0.2753816097153888
                    }
                  }
                  DEF FEMUR_SHAPE Shape {
                    appearance MattePaint {
                      baseColor 0.2 0.2 1
                    }
                    geometry Box {
                      size 0.025 0.025 0.1
                    }
                  }
                ]
                boundingObject USE FEMUR_SHAPE
                physics Physics {
                }
              }
              Shape {
                appearance MattePaint {
                  baseColor 0 0 0
                }
                geometry DEF SHOULDER_SHAPE Sphere {
                  radius 0.02
                }
              }
            ]
          }
        ]
        name "solid(4)"
        boundingObject USE SHOULDER_SHAPE
        physics Physics {
        }
        linearVelocity 0.015737195186016843 -0.05118447689504345 0.04659607268458521
        angularVelocity 0.026656662890877186 0.19078668779014082 0.2596477660438242
      }
    }
    Hinge2Joint {
      jointParameters HingeJointParameters {
        position 1.1792364928398213
      }
      jointParameters2 JointParameters {
        position -0.2819143490411884
        axis 0 1 0
      }
      device [
        DEF SHOULDER_2_x RotationalMotor {
          name "Hexabot_Leg2_Motor1"
        }
      ]
      device2 [
        DEF SHOULDER_0_y RotationalMotor {
          name "Hexabot_Leg2_Motor2"
        }
      ]
      endPoint DEF SHOULDER_0 Solid {
        translation -0.08899902525156875 0.00624669376106024 0.04823729816147702
        rotation 0.9923615853859384 -0.08278798048821263 -0.09145837379371084 2.2688972872918995
        children [
          Transform {
            children [
              DEF FEMUR_0 Solid {
                translation 0 0.025981 -0.0450019
                rotation 1 0 0 0.523599
                children [
                  HingeJoint {
                    jointParameters HingeJointParameters {
                      position -0.20431100249603845
                      axis 0 0 1
                    }
                    device [
                      DEF ELBOW_0 RotationalMotor {
                        name "Hexabot_Leg2_Motor3"
                      }
                    ]
                    endPoint Solid {
                      translation -0.00011650732160054048 -0.0006906034717625124 -0.058575884565078846
                      rotation -0.6928321078271149 -0.7193263132155868 -0.050530441117297153 3.001558985334011
                      children [
                        Transform {
                          children [
                            Solid {
                              translation 0.0824507 0 0.0210637
                              rotation 0 -1 0 1.8325953071795864
                              children [
                                Shape {
                                  appearance MattePaint {
                                    baseColor 0.1 0.1 0.6
                                  }
                                  geometry DEF TIBIA_SHAPE Box {
                                    size 0.025 0.025 0.15
                                  }
                                }
                              ]
                              boundingObject USE TIBIA_SHAPE
                              physics Physics {
                              }
                            }
                            DEF ELBOW_SHAPE Shape {
                              appearance MattePaint {
                                baseColor 0 0 0
                              }
                              geometry Cylinder {
                                height 0.025
                                radius 0.0125
                              }
                            }
                          ]
                        }
                      ]
                      boundingObject USE ELBOW_SHAPE
                      physics Physics {
                      }
                      linearVelocity 0.007378538270178838 -0.014256108139888726 0.04782775773605887
                      angularVelocity -0.034010270547590045 0.05104833896115614 -0.11865646454967807
                    }
                  }
                  DEF FEMUR_SHAPE Shape {
                    appearance MattePaint {
                      baseColor 0.2 0.2 1
                    }
                    geometry Box {
                      size 0.025 0.025 0.1
                    }
                  }
                ]
                boundingObject USE FEMUR_SHAPE
                physics Physics {
                }
              }
              Shape {
                appearance MattePaint {
                  baseColor 0 0 0
                }
                geometry DEF SHOULDER_SHAPE Sphere {
                  radius 0.02
                }
              }
            ]
          }
        ]
        name "solid(3)"
        boundingObject USE SHOULDER_SHAPE
        physics Physics {
        }
        linearVelocity 0.008999414524066647 -0.025934111843225267 0.04234253324133635
        angularVelocity -0.04695472303159422 0.057949559181183455 -0.09826389194588378
      }
    }
    Hinge2Joint {
      jointParameters HingeJointParameters {
        position -0.020864110081010023
      }
      jointParameters2 JointParameters {
        position -0.28187125233903537
        axis 0 1 0
      }
      device [
        DEF SHOULDER_3_x RotationalMotor {
          name "Hexabot_Leg3_Motor1"
        }
      ]
      device2 [
        DEF SHOULDER_3_y RotationalMotor {
          name "Hexabot_Leg3_Motor2"
        }
      ]
      endPoint DEF SHOULDER_0 Solid {
        translation -0.08533357260533357 0.009070667115121833 -0.0464586327866619
        rotation -0.7207015300885831 -0.6931601513057403 0.010877001874549872 0.028954525732323246
        children [
          Transform {
            translation 0 0 -0.01
            children [
              DEF FEMUR_0 Solid {
                translation 0 0.0259808 -0.045
                rotation 1 0 0 0.523599
                children [
                  HingeJoint {
                    jointParameters HingeJointParameters {
                      position -0.2043823175861506
                      axis 0 0 1
                    }
                    device [
                      DEF ELBOW_3 RotationalMotor {
                        name "Hexabot_Leg3_Motor3"
                      }
                    ]
                    endPoint Solid {
                      translation -8.407201150133992e-06 -2.371718705523774e-05 -0.06002055998798718
                      rotation 3.9004712822606295e-05 5.5806869590119416e-05 -0.9999999976821129 1.5133807105699335
                      children [
                        Transform {
                          children [
                            Solid {
                              translation 0.0824507 0 0.0210637
                              rotation 0 -1 0 1.8325953071795864
                              children [
                                Shape {
                                  appearance MattePaint {
                                    baseColor 0.1 0.1 0.6
                                  }
                                  geometry DEF TIBIA_SHAPE Box {
                                    size 0.025 0.025 0.15
                                  }
                                }
                              ]
                              boundingObject USE TIBIA_SHAPE
                              physics Physics {
                              }
                            }
                            DEF ELBOW_SHAPE Shape {
                              appearance MattePaint {
                                baseColor 0 0 0
                              }
                              geometry Cylinder {
                                height 0.025
                                radius 0.0125
                              }
                            }
                          ]
                        }
                      ]
                      boundingObject USE ELBOW_SHAPE
                      physics Physics {
                      }
                      linearVelocity 0.01376479837191768 -0.0659096994884693 0.03960343512328856
                      angularVelocity -0.17350211360447965 -0.04886659584974874 0.0015925852013670562
                    }
                  }
                  DEF FEMUR_SHAPE Shape {
                    appearance MattePaint {
                      baseColor 0.2 0.2 1
                    }
                    geometry Box {
                      size 0.025 0.025 0.1
                    }
                  }
                ]
                boundingObject USE FEMUR_SHAPE
                physics Physics {
                }
              }
              Shape {
                appearance MattePaint {
                  baseColor 0 0 0
                }
                geometry DEF SHOULDER_SHAPE Sphere {
                  radius 0.02
                }
              }
            ]
          }
        ]
        name "solid(2)"
        boundingObject USE SHOULDER_SHAPE
        physics Physics {
        }
        linearVelocity 0.010564498461746182 -0.054728135241920696 0.03069582389043314
        angularVelocity -0.1557351430991329 -0.03612335119379694 -0.012273733806900212
      }
    }
    Hinge2Joint {
      jointParameters HingeJointParameters {
        position -0.0791350926196133
      }
      jointParameters2 JointParameters {
        position -0.11812885858635186
        axis 0 1 0
      }
      device [
        DEF SHOULDER_4_x RotationalMotor {
          name "Hexabot_Leg4_Motor1"
        }
      ]
      device2 [
        DEF SHOULDER_4_y RotationalMotor {
          name "Hexabot_Leg4_Motor2"
        }
      ]
      endPoint DEF SHOULDER_0 Solid {
        translation -0.013964722935722188 -0.004103613747213893 -0.0518647869659338
        rotation -0.5560140020139679 -0.8305223705571992 0.03287889244578714 0.14216013982001788
        children [
          Transform {
            translation 0 0 -0.01
            children [
              DEF FEMUR_0 Solid {
                translation 0 0.0259808 -0.045
                rotation 1 0 0 0.523599
                children [
                  HingeJoint {
                    jointParameters HingeJointParameters {
                      position 0.004382477829058096
                      axis 0 0 1
                    }
                    device [
                      DEF ELBOW_4 RotationalMotor {
                        name "Hexabot_Leg4_Motor3"
                      }
                    ]
                    endPoint Solid {
                      translation -1.087102251472122e-13 2.4805494384616056e-11 -0.05999999999999946
                      rotation 2.0671464998812446e-10 2.0762235157206565e-10 -1 1.5664128293503747
                      children [
                        Transform {
                          children [
                            Solid {
                              translation 0.0824507 0 0.0210637
                              rotation 0 -1 0 1.8325953071795864
                              children [
                                Shape {
                                  appearance MattePaint {
                                    baseColor 0.1 0.1 0.6
                                  }
                                  geometry DEF TIBIA_SHAPE Box {
                                    size 0.025 0.025 0.15
                                  }
                                }
                              ]
                              boundingObject USE TIBIA_SHAPE
                              physics Physics {
                              }
                            }
                            DEF ELBOW_SHAPE Shape {
                              appearance MattePaint {
                                baseColor 0 0 0
                              }
                              geometry Cylinder {
                                height 0.025
                                radius 0.0125
                              }
                            }
                          ]
                        }
                      ]
                      boundingObject USE ELBOW_SHAPE
                      physics Physics {
                      }
                      linearVelocity -0.016077820246288087 -0.0009905393303534242 0.00859682915465285
                      angularVelocity 0.09806854136310517 0.21639297046431416 0.19688240802672174
                    }
                  }
                  DEF FEMUR_SHAPE Shape {
                    appearance MattePaint {
                      baseColor 0.2 0.2 1
                    }
                    geometry Box {
                      size 0.025 0.025 0.1
                    }
                  }
                ]
                boundingObject USE FEMUR_SHAPE
                physics Physics {
                }
              }
              Shape {
                appearance MattePaint {
                  baseColor 0 0 0
                }
                geometry DEF SHOULDER_SHAPE Sphere {
                  radius 0.02
                }
              }
            ]
          }
        ]
        name "solid(1)"
        boundingObject USE SHOULDER_SHAPE
        physics Physics {
        }
        linearVelocity -0.010861066457334636 -0.01976845470483827 0.026591230327541255
        angularVelocity 0.07855341455596024 0.2053484956355872 0.20982492280652668
      }
    }
    Hinge2Joint {
      jointParameters HingeJointParameters {
        position 0.07913648156930723
      }
      jointParameters2 JointParameters {
        position -0.28187159121106053
        axis 0 1 0
      }
      device [
        DEF SHOULDER_5_x RotationalMotor {
          name "Hexabot_Leg5_Motor1"
        }
      ]
      device2 [
        DEF SHOULDER_5_y RotationalMotor {
          name "Hexabot_Leg5_Motor2"
        }
      ]
      endPoint DEF SHOULDER_0 Solid {
        translation 0.09353213957310423 0.0028094085761616316 -0.03526812704886176
        rotation 0.26857536637388074 -0.9625047112491729 -0.03810450629889085 0.29269891181182683
        children [
          Transform {
            translation 0 0 -0.01
            children [
              DEF FEMUR_0 Solid {
                translation 0 0.0259808 -0.045
                rotation 1 0 0 0.523599
                children [
                  HingeJoint {
                    jointParameters HingeJointParameters {
                      position 0.19561767974679664
                      axis 0 0 1
                    }
                    device [
                      DEF ELBOW_5 RotationalMotor {
                        name "Hexabot_Leg5_Motor3"
                      }
                    ]
                    endPoint Solid {
                      translation 3.0869978845573406e-23 -1.5578965550998736e-22 -0.06000000000000025
                      rotation -1.2559096851472399e-20 -5.2553258562763044e-21 -1 1.3751776274327514
                      children [
                        Transform {
                          children [
                            Solid {
                              translation 0.0824507 0 0.0210637
                              rotation 0 -1 0 1.8325953071795864
                              children [
                                Shape {
                                  appearance MattePaint {
                                    baseColor 0.1 0.1 0.6
                                  }
                                  geometry DEF TIBIA_SHAPE Box {
                                    size 0.025 0.025 0.15
                                  }
                                }
                              ]
                              boundingObject USE TIBIA_SHAPE
                              physics Physics {
                              }
                            }
                            DEF ELBOW_SHAPE Shape {
                              appearance MattePaint {
                                baseColor 0 0 0
                              }
                              geometry Cylinder {
                                height 0.025
                                radius 0.0125
                              }
                            }
                          ]
                        }
                      ]
                      boundingObject USE ELBOW_SHAPE
                      physics Physics {
                      }
                      recognitionColors [
                        0 0 0
                      ]
                      linearVelocity 0.006473688462638145 -0.04340841399077153 0.05000051287825788
                      angularVelocity -0.1656488510566917 -0.04904357348112315 -0.01472977789552647
                    }
                  }
                  DEF FEMUR_SHAPE Shape {
                    appearance MattePaint {
                      baseColor 0.2 0.2 1
                    }
                    geometry Box {
                      size 0.025 0.025 0.1
                    }
                  }
                ]
                boundingObject USE FEMUR_SHAPE
                physics Physics {
                }
              }
              Shape {
                appearance MattePaint {
                  baseColor 0 0 0
                }
                geometry DEF SHOULDER_SHAPE Sphere {
                  radius 0.02
                }
              }
            ]
          }
        ]
        boundingObject USE SHOULDER_SHAPE
        physics Physics {
        }
        linearVelocity 0.005111211000899108 -0.035987499949501074 0.0409029166352134
        angularVelocity -0.14518585123435016 -0.03532599500083536 -0.022693537267805902
      }
    }
  ]
  name "Hexabot(1)"
  boundingObject USE BODY_TRAN
  physics Physics {
  }
  controller "my_controller_c"
  linearVelocity 0.0043242734174098185 -0.03657374613633031 0.03614889598446164
  angularVelocity -0.04166869992986847 0.08471936492005544 0.10190657748689382
}
Viewpoint {
  orientation 0.4500218440230472 -0.8412723414154897 -0.29956833522820137 4.941846003622756
  position 3.462333186332624 3.482614844314682 1.1693963316030307
}
TexturedBackground {
}
TexturedBackgroundLight {
}
RectangleArena {
  floorSize 10 10
  floorTileSize 1 1
  wallThickness 0.025
  wallHeight 2
  wallAppearance SandyGround {
    colorOverride 0.25 0.25 0.25
  }
}
DEF Cave_system Group {
  children [
    Pit {
      translation 0 0.12 0
      size 10 10 10
      xDimension 10
      zDimension 10
      appearance SandyGround {
        colorOverride 0.25 0.25 0.25
      }
      noiseAmplitude 0.85
      pitRadius 2.5
    }
  ]
}
