#VRML_SIM R2020a utf8
WorldInfo {
}
Viewpoint {
  orientation 0.026173871065123297 0.9718296856005014 0.2342263662765084 3.8438187092583345
  position -1.0558303566777696 0.6478907691356871 -1.2894714358810762
  follow "Hexabot"
  followType "None"
}
TexturedBackground {
}
TexturedBackgroundLight {
}
RectangleArena {
  translation 0 -0.05 0
  floorSize 10 10
  wallHeight 0.5
}
Robot {
  translation 0.189586 0.0512957 -0.235634
  rotation -3.5053609396316234e-06 0.9999999999830885 -4.6406114290966904e-06 2.5830846964557397
  children [
    Camera {
      translation 0.09 0 0
      rotation 0 1 0 -1.8325953071795862
      children [
        Transform {
          children [
            Shape {
              appearance PBRAppearance {
              }
              geometry Cylinder {
                height 0.1
                radius 0.05
              }
            }
          ]
        }
      ]
    }
    DEF BODY_TRAN Transform {
      children [
        DEF BODY Shape {
          appearance MattePaint {
            baseColor 0.1 0.1 0.7
          }
          geometry Box {
            size 0.2 0.05 0.125
          }
        }
      ]
    }
    Hinge2Joint {
      jointParameters HingeJointParameters {
        position -1.9580114951696162e-06
      }
      jointParameters2 JointParameters {
        position -1.2911037878917661e-06
      }
      device [
        DEF SHOULDER_2_x RotationalMotor {
        }
      ]
      device2 [
        DEF SHOULDER_0_y RotationalMotor {
        }
      ]
      endPoint DEF SHOULDER_0 Solid {
        translation 0.08000000039097527 9.19016637803368e-06 0.07000009492901925
        rotation 6.455509834459378e-07 0.9999999999993125 -9.79006522868459e-07 3.1415907939881227
        children [
          Transform {
            children [
              DEF FEMUR_0 Solid {
                translation 0 0.025981 -0.0450019
                rotation 1 0 0 0.523599
                children [
                  HingeJoint {
                    jointParameters HingeJointParameters {
                      position 9.980587167943932e-07
                      axis 1 1 0
                    }
                    device [
                      DEF ELBOW_0 RotationalMotor {
                      }
                    ]
                    endPoint Solid {
                      translation -4.2344045200052145e-08 4.233478175275451e-08 -0.05999999999996963
                      rotation -7.735356000387467e-11 7.056577690365873e-07 -0.9999999999997509 1.5707953071789544
                      children [
                        Transform {
                          children [
                            Solid {
                              translation 0.0824507 0 0.0210637
                              rotation 0 -1 0 1.8325953071795864
                              children [
                                Shape {
                                  appearance MattePaint {
                                    baseColor 0.1 0.1 0.6
                                  }
                                  geometry DEF TIBIA_SHAPE Box {
                                    size 0.025 0.025 0.15
                                  }
                                }
                              ]
                              boundingObject USE TIBIA_SHAPE
                              physics Physics {
                              }
                            }
                            DEF ELBOW_SHAPE Shape {
                              appearance MattePaint {
                                baseColor 0 0 0
                              }
                              geometry Cylinder {
                                height 0.025
                                radius 0.0125
                              }
                            }
                          ]
                        }
                      ]
                      boundingObject USE ELBOW_SHAPE
                      physics Physics {
                      }
                    }
                  }
                  DEF FEMUR_SHAPE Shape {
                    appearance MattePaint {
                      baseColor 0.2 0.2 1
                    }
                    geometry Box {
                      size 0.025 0.025 0.1
                    }
                  }
                ]
                boundingObject USE FEMUR_SHAPE
                physics Physics {
                }
              }
              Shape {
                appearance MattePaint {
                  baseColor 0 0 0
                }
                geometry DEF SHOULDER_SHAPE Sphere {
                  radius 0.02
                }
              }
            ]
          }
        ]
        name "solid(5)"
        boundingObject USE SHOULDER_SHAPE
        physics Physics {
        }
      }
    }
    Hinge2Joint {
      jointParameters HingeJointParameters {
        position -2.847974262834086e-06
      }
      jointParameters2 JointParameters {
        position -2.3384772967297396e-06
      }
      device [
        DEF SHOULDER_1_x RotationalMotor {
        }
      ]
      device2 [
        DEF SHOULDER_1_y RotationalMotor {
        }
      ]
      endPoint DEF SHOULDER_0 Solid {
        translation -2.162500948433913e-10 6.154974232453079e-06 0.06999999946631269
        rotation 1.1692367590299212e-06 0.9999999999983026 -1.4239886828271817e-06 3.141589999954202
        children [
          Transform {
            children [
              DEF FEMUR_0 Solid {
                translation 0 0.0259808 -0.045
                rotation 1 0 0 0.523599
                children [
                  HingeJoint {
                    jointParameters HingeJointParameters {
                      position 1.5472960499499474e-06
                    }
                    device [
                      DEF ELBOW_1 RotationalMotor {
                      }
                    ]
                    endPoint Solid {
                      translation 0 9.28249886908067e-08 -0.059999999999928194
                      rotation 7.735425377202011e-07 7.735413957034688e-07 -0.9999999999994016 1.5707953071818181
                      children [
                        Transform {
                          children [
                            Solid {
                              translation 0.0824507 0 0.0210637
                              rotation 0 -1 0 1.8325953071795864
                              children [
                                Shape {
                                  appearance MattePaint {
                                    baseColor 0.1 0.1 0.6
                                  }
                                  geometry DEF TIBIA_SHAPE Box {
                                    size 0.025 0.025 0.15
                                  }
                                }
                              ]
                              boundingObject USE TIBIA_SHAPE
                              physics Physics {
                              }
                            }
                            DEF ELBOW_SHAPE Shape {
                              appearance MattePaint {
                                baseColor 0 0 0
                              }
                              geometry Cylinder {
                                height 0.025
                                radius 0.0125
                              }
                            }
                          ]
                        }
                      ]
                      boundingObject USE ELBOW_SHAPE
                      physics Physics {
                      }
                    }
                  }
                  DEF FEMUR_SHAPE Shape {
                    appearance MattePaint {
                      baseColor 0.2 0.2 1
                    }
                    geometry Box {
                      size 0.025 0.025 0.1
                    }
                  }
                ]
                boundingObject USE FEMUR_SHAPE
                physics Physics {
                }
              }
              Shape {
                appearance MattePaint {
                  baseColor 0 0 0
                }
                geometry DEF SHOULDER_SHAPE Sphere {
                  radius 0.02
                }
              }
            ]
          }
        ]
        name "solid(4)"
        boundingObject USE SHOULDER_SHAPE
        physics Physics {
        }
      }
    }
    Hinge2Joint {
      jointParameters HingeJointParameters {
        position -3.575894301411539e-06
      }
      jointParameters2 JointParameters {
        position -3.233066296996325e-06
      }
      device [
        DEF SHOULDER_2_x RotationalMotor {
        }
      ]
      device2 [
        DEF SHOULDER_2_y RotationalMotor {
        }
      ]
      endPoint DEF SHOULDER_0 Solid {
        translation -0.08000000070301903 6.420959855759137e-06 0.06999999864628009
        rotation 1.6165307760627801e-06 0.9999999999970952 -1.7879492954890432e-06 3.1415899997514773
        children [
          Transform {
            children [
              DEF FEMUR_0 Solid {
                translation 0 0.0259808 -0.045
                rotation 1 0 0 0.523599
                children [
                  HingeJoint {
                    jointParameters HingeJointParameters {
                      position 1.8575289116833262e-06
                    }
                    device [
                      DEF ELBOW_2 RotationalMotor {
                      }
                    ]
                    endPoint Solid {
                      translation 0 1.1143827941726479e-07 -0.059999999999897385
                      rotation 9.286532753459176e-07 9.28652328477197e-07 -0.9999999999991375 1.5707953071803311
                      children [
                        Transform {
                          children [
                            Solid {
                              translation 0.0824507 0 0.0210637
                              rotation 0 -1 0 1.8325953071795864
                              children [
                                Shape {
                                  appearance MattePaint {
                                    baseColor 0.1 0.1 0.6
                                  }
                                  geometry DEF TIBIA_SHAPE Box {
                                    size 0.025 0.025 0.15
                                  }
                                }
                              ]
                              boundingObject USE TIBIA_SHAPE
                              physics Physics {
                              }
                            }
                            DEF ELBOW_SHAPE Shape {
                              appearance MattePaint {
                                baseColor 0 0 0
                              }
                              geometry Cylinder {
                                height 0.025
                                radius 0.0125
                              }
                            }
                          ]
                        }
                      ]
                      boundingObject USE ELBOW_SHAPE
                      physics Physics {
                      }
                    }
                  }
                  DEF FEMUR_SHAPE Shape {
                    appearance MattePaint {
                      baseColor 0.2 0.2 1
                    }
                    geometry Box {
                      size 0.025 0.025 0.1
                    }
                  }
                ]
                boundingObject USE FEMUR_SHAPE
                physics Physics {
                }
              }
              Shape {
                appearance MattePaint {
                  baseColor 0 0 0
                }
                geometry DEF SHOULDER_SHAPE Sphere {
                  radius 0.02
                }
              }
            ]
          }
        ]
        name "solid(3)"
        boundingObject USE SHOULDER_SHAPE
        physics Physics {
        }
      }
    }
    Hinge2Joint {
      jointParameters HingeJointParameters {
        position 3.3695360484632025e-06
      }
      jointParameters2 JointParameters {
        position 2.7021223452235303e-06
      }
      device [
        DEF SHOULDER_3_x RotationalMotor {
        }
      ]
      device2 [
        DEF SHOULDER_3_y RotationalMotor {
        }
      ]
      endPoint DEF SHOULDER_0 Solid {
        translation -0.08000000038018595 5.818146243605731e-06 -0.0599999985742173
        rotation 0.7801348981792273 -1.0540099703300283e-06 0.6256113335304723 4.3191781078567115e-06
        children [
          Transform {
            translation 0 0 -0.01
            children [
              DEF FEMUR_0 Solid {
                translation 0 0.0259808 -0.045
                rotation 1 0 0 0.523599
                children [
                  HingeJoint {
                    jointParameters HingeJointParameters {
                      position 1.8369735593510696e-06
                    }
                    device [
                      DEF ELBOW_3 RotationalMotor {
                      }
                    ]
                    endPoint Solid {
                      translation 0 1.1021994375802258e-07 -0.05999999999989872
                      rotation 9.185004678336261e-07 9.184995313168565e-07 -0.9999999999991563 1.5707953071803098
                      children [
                        Transform {
                          children [
                            Solid {
                              translation 0.0824507 0 0.0210637
                              rotation 0 -1 0 1.8325953071795864
                              children [
                                Shape {
                                  appearance MattePaint {
                                    baseColor 0.1 0.1 0.6
                                  }
                                  geometry DEF TIBIA_SHAPE Box {
                                    size 0.025 0.025 0.15
                                  }
                                }
                              ]
                              boundingObject USE TIBIA_SHAPE
                              physics Physics {
                              }
                            }
                            DEF ELBOW_SHAPE Shape {
                              appearance MattePaint {
                                baseColor 0 0 0
                              }
                              geometry Cylinder {
                                height 0.025
                                radius 0.0125
                              }
                            }
                          ]
                        }
                      ]
                      boundingObject USE ELBOW_SHAPE
                      physics Physics {
                      }
                    }
                  }
                  DEF FEMUR_SHAPE Shape {
                    appearance MattePaint {
                      baseColor 0.2 0.2 1
                    }
                    geometry Box {
                      size 0.025 0.025 0.1
                    }
                  }
                ]
                boundingObject USE FEMUR_SHAPE
                physics Physics {
                }
              }
              Shape {
                appearance MattePaint {
                  baseColor 0 0 0
                }
                geometry DEF SHOULDER_SHAPE Sphere {
                  radius 0.02
                }
              }
            ]
          }
        ]
        name "solid(2)"
        boundingObject USE SHOULDER_SHAPE
        physics Physics {
        }
      }
    }
    Hinge2Joint {
      jointParameters HingeJointParameters {
        position 2.447449944993273e-06
      }
      jointParameters2 JointParameters {
        position 1.9404816582969944e-06
      }
      device [
        DEF SHOULDER_4_x RotationalMotor {
        }
      ]
      device2 [
        DEF SHOULDER_4_y RotationalMotor {
        }
      ]
      endPoint DEF SHOULDER_0 Solid {
        translation 7.173041569848733e-11 6.006677068563836e-06 -0.05999999778798757
        rotation 0.7835910921594966 -7.60272070970445e-07 0.621276911117506 3.123419882434662e-06
        children [
          Transform {
            translation 0 0 -0.01
            children [
              DEF FEMUR_0 Solid {
                translation 0 0.0259808 -0.045
                rotation 1 0 0 0.523599
                children [
                  HingeJoint {
                    jointParameters HingeJointParameters {
                      position 1.3058382470087465e-06
                    }
                    device [
                      DEF ELBOW_4 RotationalMotor {
                      }
                    ]
                    endPoint Solid {
                      translation 0 7.837510055309817e-08 -0.05999999999994898
                      rotation 6.531265038800034e-07 6.531258379424855e-07 -0.9999999999995733 1.5707953071798955
                      children [
                        Transform {
                          children [
                            Solid {
                              translation 0.0824507 0 0.0210637
                              rotation 0 -1 0 1.8325953071795864
                              children [
                                Shape {
                                  appearance MattePaint {
                                    baseColor 0.1 0.1 0.6
                                  }
                                  geometry DEF TIBIA_SHAPE Box {
                                    size 0.025 0.025 0.15
                                  }
                                }
                              ]
                              boundingObject USE TIBIA_SHAPE
                              physics Physics {
                              }
                            }
                            DEF ELBOW_SHAPE Shape {
                              appearance MattePaint {
                                baseColor 0 0 0
                              }
                              geometry Cylinder {
                                height 0.025
                                radius 0.0125
                              }
                            }
                          ]
                        }
                      ]
                      boundingObject USE ELBOW_SHAPE
                      physics Physics {
                      }
                    }
                  }
                  DEF FEMUR_SHAPE Shape {
                    appearance MattePaint {
                      baseColor 0.2 0.2 1
                    }
                    geometry Box {
                      size 0.025 0.025 0.1
                    }
                  }
                ]
                boundingObject USE FEMUR_SHAPE
                physics Physics {
                }
              }
              Shape {
                appearance MattePaint {
                  baseColor 0 0 0
                }
                geometry DEF SHOULDER_SHAPE Sphere {
                  radius 0.02
                }
              }
            ]
          }
        ]
        name "solid(1)"
        boundingObject USE SHOULDER_SHAPE
        physics Physics {
        }
      }
    }
    Hinge2Joint {
      jointParameters HingeJointParameters {
        position 2.5648940579349636e-06
      }
      jointParameters2 JointParameters {
        position 2.2200433992310925e-06
      }
      device [
        DEF SHOULDER_5_x RotationalMotor {
        }
      ]
      device2 [
        DEF SHOULDER_5_y RotationalMotor {
        }
      ]
      endPoint DEF SHOULDER_0 Solid {
        translation 0.08000000054625708 6.209701186372095e-06 -0.059999996942485236
        rotation 0.7561068979147383 -8.39295063914701e-07 0.6544481331053262 3.3922322452387573e-06
        children [
          Transform {
            translation 0 0 -0.01
            children [
              DEF FEMUR_0 Solid {
                translation 0 0.0259808 -0.045
                rotation 1 0 0 0.523599
                children [
                  HingeJoint {
                    jointParameters HingeJointParameters {
                      position 1.7562484503607192e-06
                    }
                    device [
                      DEF ELBOW_5 RotationalMotor {
                      }
                    ]
                    endPoint Solid {
                      translation 0 1.0537490702158879e-07 -0.05999999999990735
                      rotation 8.781251205292708e-07 8.781242251799092e-07 -0.9999999999992288 1.5707953071803546
                      children [
                        Transform {
                          children [
                            Solid {
                              translation 0.0824507 0 0.0210637
                              rotation 0 -1 0 1.8325953071795864
                              children [
                                Shape {
                                  appearance MattePaint {
                                    baseColor 0.1 0.1 0.6
                                  }
                                  geometry DEF TIBIA_SHAPE Box {
                                    size 0.025 0.025 0.15
                                  }
                                }
                              ]
                              boundingObject USE TIBIA_SHAPE
                              physics Physics {
                              }
                            }
                            DEF ELBOW_SHAPE Shape {
                              appearance MattePaint {
                                baseColor 0 0 0
                              }
                              geometry Cylinder {
                                height 0.025
                                radius 0.0125
                              }
                            }
                          ]
                        }
                      ]
                      boundingObject USE ELBOW_SHAPE
                      physics Physics {
                      }
                      recognitionColors [
                        0 0 0
                      ]
                    }
                  }
                  DEF FEMUR_SHAPE Shape {
                    appearance MattePaint {
                      baseColor 0.2 0.2 1
                    }
                    geometry Box {
                      size 0.025 0.025 0.1
                    }
                  }
                ]
                boundingObject USE FEMUR_SHAPE
                physics Physics {
                }
              }
              Shape {
                appearance MattePaint {
                  baseColor 0 0 0
                }
                geometry DEF SHOULDER_SHAPE Sphere {
                  radius 0.02
                }
              }
            ]
          }
        ]
        boundingObject USE SHOULDER_SHAPE
        physics Physics {
        }
      }
    }
  ]
  name "Hexabot"
  boundingObject USE BODY_TRAN
  physics Physics {
  }
  controller "camera_func"
}
