#VRML_SIM R2020a utf8
WorldInfo {
}
Viewpoint {
  orientation 0.10784636971742295 0.9635514370327397 0.2448219531229072 4.455289338214946
  position -1.734415560043389 0.945718020204476 -0.2733006031394486
  follow "Hexabot"
  followType "None"
}
TexturedBackground {
}
TexturedBackgroundLight {
}
RectangleArena {
  translation 0 -0.05 0
  floorSize 10 10
  wallHeight 0.5
}
Robot {
  translation 0.2489447989283 0.051290713533472025 -0.19854126745998327
  rotation -3.371728290094292e-05 0.9999999993426126 -1.3338649836130358e-05 2.583084997715762
  children [
    Camera {
      translation 0.08 0.03 0
      rotation 0 0 1 -1.5707953071795862
      children [
        DEF CAM_SHAPE Shape {
          appearance MattePaint {
            baseColor 0.7 0.1 0.1
          }
          geometry Cylinder {
            height 0.05
            radius 0.0125
          }
        }
      ]
      boundingObject USE CAM_SHAPE
      physics Physics {
      }
    }
    DEF BODY_TRAN Transform {
      children [
        DEF BODY Shape {
          appearance MattePaint {
            baseColor 0.1 0.1 0.7
          }
          geometry Box {
            size 0.2 0.05 0.125
          }
        }
      ]
    }
    Hinge2Joint {
      jointParameters HingeJointParameters {
        position -2.481784204918034e-06
      }
      jointParameters2 JointParameters {
        position -1.786978402258507e-06
      }
      device [
        DEF SHOULDER_2_x RotationalMotor {
        }
      ]
      device2 [
        DEF SHOULDER_0_y RotationalMotor {
        }
      ]
      endPoint DEF SHOULDER_0 Solid {
        translation 0.07999999832293384 1.2419576758776823e-05 0.0700000762049899
        rotation 8.934880476917448e-07 0.999999999998831 -1.2408931088787489e-06 3.141590795066436
        children [
          Transform {
            children [
              DEF FEMUR_0 Solid {
                translation 0 0.025981 -0.0450019
                rotation 1 0 0 0.523599
                children [
                  HingeJoint {
                    jointParameters HingeJointParameters {
                      position 1.1866767699026016e-06
                      axis 1 1 0
                    }
                    device [
                      DEF ELBOW_0 RotationalMotor {
                      }
                    ]
                    endPoint Solid {
                      translation -5.034643146446844e-08 5.033716801717081e-08 -0.05999999999995734
                      rotation -7.728556528084128e-11 8.390309414382489e-07 -0.999999999999648 1.5707953071790581
                      children [
                        Transform {
                          children [
                            Solid {
                              translation 0.0824507 0 0.0210637
                              rotation 0 -1 0 1.8325953071795864
                              children [
                                Shape {
                                  appearance MattePaint {
                                    baseColor 0.1 0.1 0.6
                                  }
                                  geometry DEF TIBIA_SHAPE Box {
                                    size 0.025 0.025 0.15
                                  }
                                }
                              ]
                              boundingObject USE TIBIA_SHAPE
                              physics Physics {
                              }
                            }
                            DEF ELBOW_SHAPE Shape {
                              appearance MattePaint {
                                baseColor 0 0 0
                              }
                              geometry Cylinder {
                                height 0.025
                                radius 0.0125
                              }
                            }
                          ]
                        }
                      ]
                      boundingObject USE ELBOW_SHAPE
                      physics Physics {
                      }
                      linearVelocity -1.9386533202057026e-07 3.4977029945222022e-06 -1.4861367390684948e-07
                      angularVelocity -1.5002198432823433e-06 -2.9015813473844772e-08 2.4000884297592104e-06
                    }
                  }
                  DEF FEMUR_SHAPE Shape {
                    appearance MattePaint {
                      baseColor 0.2 0.2 1
                    }
                    geometry Box {
                      size 0.025 0.025 0.1
                    }
                  }
                ]
                boundingObject USE FEMUR_SHAPE
                physics Physics {
                }
              }
              Shape {
                appearance MattePaint {
                  baseColor 0 0 0
                }
                geometry DEF SHOULDER_SHAPE Sphere {
                  radius 0.02
                }
              }
            ]
          }
        ]
        name "solid(5)"
        boundingObject USE SHOULDER_SHAPE
        physics Physics {
        }
        linearVelocity -2.8109405856649594e-07 3.2699243755905326e-06 -1.8893149637995686e-07
        angularVelocity -1.499363827250272e-06 -1.1943455160883981e-09 2.4197833935081112e-06
      }
    }
    Hinge2Joint {
      jointParameters HingeJointParameters {
        position -3.3661672995104374e-06
      }
      jointParameters2 JointParameters {
        position -2.847894478681955e-06
      }
      device [
        DEF SHOULDER_1_x RotationalMotor {
        }
      ]
      device2 [
        DEF SHOULDER_1_y RotationalMotor {
        }
      ]
      endPoint DEF SHOULDER_0 Solid {
        translation 2.9107282758242383e-10 9.46590354657892e-06 0.06999997663508055
        rotation 1.4239450060954884e-06 0.9999999999975699 -1.6830855389950364e-06 3.1415900000485184
        children [
          Transform {
            children [
              DEF FEMUR_0 Solid {
                translation 0 0.0259808 -0.045
                rotation 1 0 0 0.523599
                children [
                  HingeJoint {
                    jointParameters HingeJointParameters {
                      position 1.8085597920605393e-06
                    }
                    device [
                      DEF ELBOW_1 RotationalMotor {
                      }
                    ]
                    endPoint Solid {
                      translation 0 1.0850081321742019e-07 -0.05999999999990192
                      rotation 9.041745419694229e-07 9.04173266758581e-07 -0.9999999999991824 1.5707953071820377
                      children [
                        Transform {
                          children [
                            Solid {
                              translation 0.0824507 0 0.0210637
                              rotation 0 -1 0 1.8325953071795864
                              children [
                                Shape {
                                  appearance MattePaint {
                                    baseColor 0.1 0.1 0.6
                                  }
                                  geometry DEF TIBIA_SHAPE Box {
                                    size 0.025 0.025 0.15
                                  }
                                }
                              ]
                              boundingObject USE TIBIA_SHAPE
                              physics Physics {
                              }
                            }
                            DEF ELBOW_SHAPE Shape {
                              appearance MattePaint {
                                baseColor 0 0 0
                              }
                              geometry Cylinder {
                                height 0.025
                                radius 0.0125
                              }
                            }
                          ]
                        }
                      ]
                      boundingObject USE ELBOW_SHAPE
                      physics Physics {
                      }
                      linearVelocity -2.0922589964502316e-07 3.721205435179531e-06 -1.2538780095330617e-07
                      angularVelocity -1.5001680953931728e-06 -2.3625078641419716e-10 2.419225775077199e-06
                    }
                  }
                  DEF FEMUR_SHAPE Shape {
                    appearance MattePaint {
                      baseColor 0.2 0.2 1
                    }
                    geometry Box {
                      size 0.025 0.025 0.1
                    }
                  }
                ]
                boundingObject USE FEMUR_SHAPE
                physics Physics {
                }
              }
              Shape {
                appearance MattePaint {
                  baseColor 0 0 0
                }
                geometry DEF SHOULDER_SHAPE Sphere {
                  radius 0.02
                }
              }
            ]
          }
        ]
        name "solid(4)"
        boundingObject USE SHOULDER_SHAPE
        physics Physics {
        }
        linearVelocity -2.8835784840719547e-07 3.495134148417357e-06 -1.7675092716236364e-07
        angularVelocity -1.500113664800363e-06 -2.900984803994967e-10 2.4193680969511714e-06
      }
    }
    Hinge2Joint {
      jointParameters HingeJointParameters {
        position -4.079913684275544e-06
      }
      jointParameters2 JointParameters {
        position -3.738524705981665e-06
      }
      device [
        DEF SHOULDER_2_x RotationalMotor {
        }
      ]
      device2 [
        DEF SHOULDER_2_y RotationalMotor {
        }
      ]
      endPoint DEF SHOULDER_0 Solid {
        translation -0.07999999738098708 9.750347590547311e-06 0.06999997415562131
        rotation 1.8692596447994354e-06 0.9999999999961724 -2.039959321158962e-06 3.141589998469731
        children [
          Transform {
            children [
              DEF FEMUR_0 Solid {
                translation 0 0.0259808 -0.045
                rotation 1 0 0 0.523599
                children [
                  HingeJoint {
                    jointParameters HingeJointParameters {
                      position 2.1128850025132297e-06
                    }
                    device [
                      DEF ELBOW_2 RotationalMotor {
                      }
                    ]
                    endPoint Solid {
                      translation 0 1.2675964486702902e-07 -0.05999999999986699
                      rotation 1.0563314509431889e-06 1.056330373891897e-06 -0.9999999999988841 1.5707953071805845
                      children [
                        Transform {
                          children [
                            Solid {
                              translation 0.0824507 0 0.0210637
                              rotation 0 -1 0 1.8325953071795864
                              children [
                                Shape {
                                  appearance MattePaint {
                                    baseColor 0.1 0.1 0.6
                                  }
                                  geometry DEF TIBIA_SHAPE Box {
                                    size 0.025 0.025 0.15
                                  }
                                }
                              ]
                              boundingObject USE TIBIA_SHAPE
                              physics Physics {
                              }
                            }
                            DEF ELBOW_SHAPE Shape {
                              appearance MattePaint {
                                baseColor 0 0 0
                              }
                              geometry Cylinder {
                                height 0.025
                                radius 0.0125
                              }
                            }
                          ]
                        }
                      ]
                      boundingObject USE ELBOW_SHAPE
                      physics Physics {
                      }
                      linearVelocity -2.0945161519642365e-07 3.93816645291773e-06 -1.2535508918543087e-07
                      angularVelocity -1.5002061950035679e-06 -3.709746204427223e-10 2.4191844104193576e-06
                    }
                  }
                  DEF FEMUR_SHAPE Shape {
                    appearance MattePaint {
                      baseColor 0.2 0.2 1
                    }
                    geometry Box {
                      size 0.025 0.025 0.1
                    }
                  }
                ]
                boundingObject USE FEMUR_SHAPE
                physics Physics {
                }
              }
              Shape {
                appearance MattePaint {
                  baseColor 0 0 0
                }
                geometry DEF SHOULDER_SHAPE Sphere {
                  radius 0.02
                }
              }
            ]
          }
        ]
        name "solid(3)"
        boundingObject USE SHOULDER_SHAPE
        physics Physics {
        }
        linearVelocity -2.884856942323946e-07 3.7174796403408696e-06 -1.7672500472983176e-07
        angularVelocity -1.5001380631551368e-06 -4.323467599980335e-10 2.4193486972499406e-06
      }
    }
    Hinge2Joint {
      jointParameters HingeJointParameters {
        position 3.872030921978614e-06
      }
      jointParameters2 JointParameters {
        position 3.208850934447069e-06
      }
      device [
        DEF SHOULDER_3_x RotationalMotor {
        }
      ]
      device2 [
        DEF SHOULDER_3_y RotationalMotor {
        }
      ]
      endPoint DEF SHOULDER_0 Solid {
        translation -0.07999999818447036 9.024286433237897e-06 -0.05999997831697011
        rotation 0.7699632597141898 -1.2353486627129546e-06 0.6380882217129331 5.028827313015927e-06
        children [
          Transform {
            translation 0 0 -0.01
            children [
              DEF FEMUR_0 Solid {
                translation 0 0.0259808 -0.045
                rotation 1 0 0 0.523599
                children [
                  HingeJoint {
                    jointParameters HingeJointParameters {
                      position 2.090324093355427e-06
                    }
                    device [
                      DEF ELBOW_3 RotationalMotor {
                      }
                    ]
                    endPoint Solid {
                      translation 0 1.2542097579825469e-07 -0.05999999999986885
                      rotation 1.0451758639956834e-06 1.0451747983187915e-06 -0.9999999999989074 1.570795307180558
                      children [
                        Transform {
                          children [
                            Solid {
                              translation 0.0824507 0 0.0210637
                              rotation 0 -1 0 1.8325953071795864
                              children [
                                Shape {
                                  appearance MattePaint {
                                    baseColor 0.1 0.1 0.6
                                  }
                                  geometry DEF TIBIA_SHAPE Box {
                                    size 0.025 0.025 0.15
                                  }
                                }
                              ]
                              boundingObject USE TIBIA_SHAPE
                              physics Physics {
                              }
                            }
                            DEF ELBOW_SHAPE Shape {
                              appearance MattePaint {
                                baseColor 0 0 0
                              }
                              geometry Cylinder {
                                height 0.025
                                radius 0.0125
                              }
                            }
                          ]
                        }
                      ]
                      boundingObject USE ELBOW_SHAPE
                      physics Physics {
                      }
                      linearVelocity -2.067041227934428e-07 3.930938775889416e-06 -1.236788197511709e-07
                      angularVelocity -1.4990181530445315e-06 -3.1956377154044287e-10 2.4202987070307003e-06
                    }
                  }
                  DEF FEMUR_SHAPE Shape {
                    appearance MattePaint {
                      baseColor 0.2 0.2 1
                    }
                    geometry Box {
                      size 0.025 0.025 0.1
                    }
                  }
                ]
                boundingObject USE FEMUR_SHAPE
                physics Physics {
                }
              }
              Shape {
                appearance MattePaint {
                  baseColor 0 0 0
                }
                geometry DEF SHOULDER_SHAPE Sphere {
                  radius 0.02
                }
              }
            ]
          }
        ]
        name "solid(2)"
        boundingObject USE SHOULDER_SHAPE
        physics Physics {
        }
        linearVelocity -2.87141489683056e-07 3.7138422272927844e-06 -1.758671386472454e-07
        angularVelocity -1.5002202163990486e-06 -3.978811569381253e-10 2.4194156489573667e-06
      }
    }
    Hinge2Joint {
      jointParameters HingeJointParameters {
        position 2.9629629962699967e-06
      }
      jointParameters2 JointParameters {
        position 2.447592610145698e-06
      }
      device [
        DEF SHOULDER_4_x RotationalMotor {
        }
      ]
      device2 [
        DEF SHOULDER_4_y RotationalMotor {
        }
      ]
      endPoint DEF SHOULDER_0 Solid {
        translation -5.761196717454603e-10 9.26619612656331e-06 -0.05999997586348071
        rotation 0.7709710109670059 -9.435114745401716e-07 0.6368702381550128 3.843113183500836e-06
        children [
          Transform {
            translation 0 0 -0.01
            children [
              DEF FEMUR_0 Solid {
                translation 0 0.0259808 -0.045
                rotation 1 0 0 0.523599
                children [
                  HingeJoint {
                    jointParameters HingeJointParameters {
                      position 1.5644481235657562e-06
                    }
                    device [
                      DEF ELBOW_4 RotationalMotor {
                      }
                    ]
                    endPoint Solid {
                      translation 0 9.38916931465028e-08 -0.059999999999926716
                      rotation 7.824315739997521e-07 7.82430776220857e-07 -0.9999999999993877 1.570795307180081
                      children [
                        Transform {
                          children [
                            Solid {
                              translation 0.0824507 0 0.0210637
                              rotation 0 -1 0 1.8325953071795864
                              children [
                                Shape {
                                  appearance MattePaint {
                                    baseColor 0.1 0.1 0.6
                                  }
                                  geometry DEF TIBIA_SHAPE Box {
                                    size 0.025 0.025 0.15
                                  }
                                }
                              ]
                              boundingObject USE TIBIA_SHAPE
                              physics Physics {
                              }
                            }
                            DEF ELBOW_SHAPE Shape {
                              appearance MattePaint {
                                baseColor 0 0 0
                              }
                              geometry Cylinder {
                                height 0.025
                                radius 0.0125
                              }
                            }
                          ]
                        }
                      ]
                      boundingObject USE ELBOW_SHAPE
                      physics Physics {
                      }
                      linearVelocity -2.0731628754611069e-07 3.7132480032582502e-06 -1.2239986566984866e-07
                      angularVelocity -1.5005308599078055e-06 -1.4210238904927526e-10 2.419362310199983e-06
                    }
                  }
                  DEF FEMUR_SHAPE Shape {
                    appearance MattePaint {
                      baseColor 0.2 0.2 1
                    }
                    geometry Box {
                      size 0.025 0.025 0.1
                    }
                  }
                ]
                boundingObject USE FEMUR_SHAPE
                physics Physics {
                }
              }
              Shape {
                appearance MattePaint {
                  baseColor 0 0 0
                }
                geometry DEF SHOULDER_SHAPE Sphere {
                  radius 0.02
                }
              }
            ]
          }
        ]
        name "solid(1)"
        boundingObject USE SHOULDER_SHAPE
        physics Physics {
        }
        linearVelocity -2.874119299951324e-07 3.4910665237211115e-06 -1.752689970758052e-07
        angularVelocity -1.5002744391672994e-06 -2.2472472965050772e-10 2.4193827312386276e-06
      }
    }
    Hinge2Joint {
      jointParameters HingeJointParameters {
        position 3.0928712155469448e-06
      }
      jointParameters2 JointParameters {
        position 2.736213823681239e-06
      }
      device [
        DEF SHOULDER_5_x RotationalMotor {
        }
      ]
      device2 [
        DEF SHOULDER_5_y RotationalMotor {
        }
      ]
      endPoint DEF SHOULDER_0 Solid {
        translation 0.07999999705146296 9.518929267817433e-06 -0.059999973211982235
        rotation 0.7489710409300652 -1.024672457865525e-06 0.6626027315421245 4.129423383455463e-06
        children [
          Transform {
            translation 0 0 -0.01
            children [
              DEF FEMUR_0 Solid {
                translation 0 0.0259808 -0.045
                rotation 1 0 0 0.523599
                children [
                  HingeJoint {
                    jointParameters HingeJointParameters {
                      position 2.020029080030827e-06
                    }
                    device [
                      DEF ELBOW_5 RotationalMotor {
                      }
                    ]
                    endPoint Solid {
                      translation 0 1.21201744801767e-07 -0.05999999999987751
                      rotation 1.0100155698415426e-06 1.0100145400147277e-06 -0.9999999999989798 1.5707953071806033
                      children [
                        Transform {
                          children [
                            Solid {
                              translation 0.0824507 0 0.0210637
                              rotation 0 -1 0 1.8325953071795864
                              children [
                                Shape {
                                  appearance MattePaint {
                                    baseColor 0.1 0.1 0.6
                                  }
                                  geometry DEF TIBIA_SHAPE Box {
                                    size 0.025 0.025 0.15
                                  }
                                }
                              ]
                              boundingObject USE TIBIA_SHAPE
                              physics Physics {
                              }
                            }
                            DEF ELBOW_SHAPE Shape {
                              appearance MattePaint {
                                baseColor 0 0 0
                              }
                              geometry Cylinder {
                                height 0.025
                                radius 0.0125
                              }
                            }
                          ]
                        }
                      ]
                      boundingObject USE ELBOW_SHAPE
                      physics Physics {
                      }
                      recognitionColors [
                        0 0 0
                      ]
                      linearVelocity -2.083592336534215e-07 3.49503122155523e-06 -1.212716774085806e-07
                      angularVelocity -1.5006160745936339e-06 8.68568981987928e-11 2.4192415846415395e-06
                    }
                  }
                  DEF FEMUR_SHAPE Shape {
                    appearance MattePaint {
                      baseColor 0.2 0.2 1
                    }
                    geometry Box {
                      size 0.025 0.025 0.1
                    }
                  }
                ]
                boundingObject USE FEMUR_SHAPE
                physics Physics {
                }
              }
              Shape {
                appearance MattePaint {
                  baseColor 0 0 0
                }
                geometry DEF SHOULDER_SHAPE Sphere {
                  radius 0.02
                }
              }
            ]
          }
        ]
        boundingObject USE SHOULDER_SHAPE
        physics Physics {
        }
        linearVelocity -2.8792291623359654e-07 3.268089043561877e-06 -1.7470125913212699e-07
        angularVelocity -1.5003177746322605e-06 1.8517561316600987e-11 2.419314557878268e-06
      }
    }
  ]
  name "Hexabot"
  boundingObject USE BODY_TRAN
  physics Physics {
  }
  linearVelocity -2.471970967139735e-07 3.3341508646941217e-06 -1.5352201916746422e-07
  angularVelocity -1.5000747600221935e-06 -4.201028490568581e-10 2.419441004849048e-06
}
