#VRML_SIM R2020a utf8
WorldInfo {
}
Viewpoint {
  orientation 0.5015773690437272 0.6312174428742108 0.591595032665518 4.305496363837945
  position -4.368625830635835 20.630502349364516 4.0449810814843055
  follow "Hexabot"
  followType "None"
}
Background {
  skyColor [
    0.15 0.45 1
  ]
}
Robot {
  translation 0.24511663347423515 0.06535842604269655 0.006609961505893032
  rotation 0.6187076656471301 0.30064057977407543 -0.7258209601978899 0.030942345254220786
  children [
    Compass {
      name "Hexabot_Compass"
    }
    Gyro {
      name "Hexabot_Gyro"
    }
    GPS {
      name "Hexabot_GPS"
    }
    Camera {
      translation 0.1 -1.12008e-13 -1.49482e-07
      rotation 8.684229999951365e-07 -0.9999999999943995 3.2321499999818985e-06 1.5707853071795865
      children [
        DEF CAM_SHAPE Shape {
          appearance MattePaint {
            baseColor 0.7 0.1 0.1
          }
          geometry Cylinder {
            height 0.05
            radius 0.0125
          }
        }
      ]
      name "Hexabot_Camera"
      boundingObject USE CAM_SHAPE
      physics Physics {
      }
      lens Lens {
      }
      focus Focus {
      }
    }
    DEF BODY_TRAN Transform {
      children [
        DEF BODY Shape {
          appearance MattePaint {
            baseColor 0.1 0.1 0.7
          }
          geometry Box {
            size 0.2 0.05 0.125
          }
        }
      ]
    }
    Hinge2Joint {
      jointParameters HingeJointParameters {
        position -0.012981386956526595
      }
      jointParameters2 JointParameters {
        position -0.1914088472341802
        axis 0 1 0
      }
      device [
        DEF SHOULDER_2_x RotationalMotor {
          name "Hexabot_Leg0_Motor1"
        }
      ]
      device2 [
        DEF SHOULDER_0_y RotationalMotor {
          name "Hexabot_Leg0_Motor2"
        }
      ]
      endPoint DEF SHOULDER_0 Solid {
        translation 0.08073778011817012 -0.011335420000952754 0.04580037374183617
        rotation 0.9868197563602719 0.026715344969901033 -0.15960281576523982 2.063189639554886
        children [
          Transform {
            children [
              DEF FEMUR_0 Solid {
                translation 0 0.025981 -0.0450019
                rotation 1 0 0 0.523599
                children [
                  HingeJoint {
                    jointParameters HingeJointParameters {
                      position -0.25977402345509154
                      axis 0 0 1
                    }
                    device [
                      DEF ELBOW_0 RotationalMotor {
                        name "Hexabot_Leg0_Motor3"
                      }
                    ]
                    endPoint Solid {
                      translation -0.00015410489837316502 -0.0007191024475457341 -0.05856390241636135
                      rotation -0.7068784544687741 -0.6919885328314755 -0.1465425570869406 2.8221813289988873
                      children [
                        Transform {
                          children [
                            Solid {
                              translation 0.0824507 0 0.0210637
                              rotation 0 -1 0 1.8325953071795864
                              children [
                                Shape {
                                  appearance MattePaint {
                                    baseColor 0.1 0.1 0.6
                                  }
                                  geometry DEF TIBIA_SHAPE Box {
                                    size 0.025 0.025 0.15
                                  }
                                }
                              ]
                              boundingObject USE TIBIA_SHAPE
                              physics Physics {
                              }
                            }
                            DEF ELBOW_SHAPE Shape {
                              appearance MattePaint {
                                baseColor 0 0 0
                              }
                              geometry Cylinder {
                                height 0.025
                                radius 0.0125
                              }
                            }
                          ]
                        }
                      ]
                      boundingObject USE ELBOW_SHAPE
                      physics Physics {
                      }
                      linearVelocity 9.778713039583917e-07 9.515462554272973e-07 -4.471013196736783e-06
                      angularVelocity -1.2259596889723016e-06 -1.6606730770898224e-06 -6.633554576140502e-06
                    }
                  }
                  DEF FEMUR_SHAPE Shape {
                    appearance MattePaint {
                      baseColor 0.2 0.2 1
                    }
                    geometry Box {
                      size 0.025 0.025 0.1
                    }
                  }
                ]
                boundingObject USE FEMUR_SHAPE
                physics Physics {
                }
              }
              Shape {
                appearance MattePaint {
                  baseColor 0 0 0
                }
                geometry DEF SHOULDER_SHAPE Sphere {
                  radius 0.02
                }
              }
            ]
          }
        ]
        name "solid(5)"
        boundingObject USE SHOULDER_SHAPE
        physics Physics {
        }
        linearVelocity 1.3767139223946718e-06 8.58916710071534e-07 -4.551122222047229e-06
        angularVelocity -8.58477407241956e-07 -1.0239458979665353e-06 -5.596240496173811e-06
      }
    }
    Hinge2Joint {
      jointParameters HingeJointParameters {
        position 0.4129818785409305
      }
      jointParameters2 JointParameters {
        position -0.20859115362248712
        axis 0 1 0
      }
      device [
        DEF SHOULDER_2_x RotationalMotor {
          name "Hexabot_Leg1_Motor1"
        }
      ]
      device2 [
        DEF SHOULDER_0_y RotationalMotor {
          name "Hexabot_Leg1_Motor2"
        }
      ]
      endPoint DEF SHOULDER_0 Solid {
        translation -0.0015048001434579284 -0.014687662239573056 0.05798943341064404
        rotation 0.9965392549450917 0.021688308141101648 -0.08024419383019593 1.696532678337353
        children [
          Transform {
            children [
              DEF FEMUR_0 Solid {
                translation 0 0.025981 -0.0450019
                rotation 1 0 0 0.523599
                children [
                  HingeJoint {
                    jointParameters HingeJointParameters {
                      position -0.3402260025306397
                      axis 0 0 1
                    }
                    device [
                      DEF ELBOW_0 RotationalMotor {
                        name "Hexabot_Leg1_Motor3"
                      }
                    ]
                    endPoint Solid {
                      translation -0.00020474587337447197 -0.000592719636578355 -0.05861795080600522
                      rotation -0.7334436943051195 -0.662393953892334 -0.15262567651263298 2.834022926549562
                      children [
                        Transform {
                          children [
                            Solid {
                              translation 0.0824507 0 0.0210637
                              rotation 0 -1 0 1.8325953071795864
                              children [
                                Shape {
                                  appearance MattePaint {
                                    baseColor 0.1 0.1 0.6
                                  }
                                  geometry DEF TIBIA_SHAPE Box {
                                    size 0.025 0.025 0.15
                                  }
                                }
                              ]
                              boundingObject USE TIBIA_SHAPE
                              physics Physics {
                              }
                            }
                            DEF ELBOW_SHAPE Shape {
                              appearance MattePaint {
                                baseColor 0 0 0
                              }
                              geometry Cylinder {
                                height 0.025
                                radius 0.0125
                              }
                            }
                          ]
                        }
                      ]
                      boundingObject USE ELBOW_SHAPE
                      physics Physics {
                      }
                      linearVelocity 1.7739527310864669e-06 1.2766296957319047e-06 -4.6949751818471604e-06
                      angularVelocity -6.65266235034541e-07 9.737284283321918e-08 -4.720844042665684e-06
                    }
                  }
                  DEF FEMUR_SHAPE Shape {
                    appearance MattePaint {
                      baseColor 0.2 0.2 1
                    }
                    geometry Box {
                      size 0.025 0.025 0.1
                    }
                  }
                ]
                boundingObject USE FEMUR_SHAPE
                physics Physics {
                }
              }
              Shape {
                appearance MattePaint {
                  baseColor 0 0 0
                }
                geometry DEF SHOULDER_SHAPE Sphere {
                  radius 0.02
                }
              }
            ]
          }
        ]
        name "solid(4)"
        boundingObject USE SHOULDER_SHAPE
        physics Physics {
        }
        linearVelocity 1.7812779585048622e-06 1.31745258850928e-06 -4.693534899831549e-06
        angularVelocity -8.584705345668556e-07 -1.0239543991642805e-06 -5.59592060427731e-06
      }
    }
    Hinge2Joint {
      jointParameters HingeJointParameters {
        position 1.1870160870141497
      }
      jointParameters2 JointParameters {
        position -0.19140966380763363
        axis 0 1 0
      }
      device [
        DEF SHOULDER_2_x RotationalMotor {
          name "Hexabot_Leg2_Motor1"
        }
      ]
      device2 [
        DEF SHOULDER_0_y RotationalMotor {
          name "Hexabot_Leg2_Motor2"
        }
      ]
      endPoint DEF SHOULDER_0 Solid {
        translation -0.08749281516760399 -0.0015395029390341194 0.051276913297713535
        rotation 0.9954758480648371 -0.032826412160537395 -0.08916424498788536 2.267078900328975
        children [
          Transform {
            children [
              DEF FEMUR_0 Solid {
                translation 0 0.025981 -0.0450019
                rotation 1 0 0 0.523599
                children [
                  HingeJoint {
                    jointParameters HingeJointParameters {
                      position -0.2597760786438759
                      axis 0 0 1
                    }
                    device [
                      DEF ELBOW_0 RotationalMotor {
                        name "Hexabot_Leg2_Motor3"
                      }
                    ]
                    endPoint Solid {
                      translation -0.000154612894854569 -0.0006830826918767996 -0.05857588456507883
                      rotation -0.7124412603019447 -0.6997688169207998 -0.052450486028641954 3.004415093024306
                      children [
                        Transform {
                          children [
                            Solid {
                              translation 0.0824507 0 0.0210637
                              rotation 0 -1 0 1.8325953071795864
                              children [
                                Shape {
                                  appearance MattePaint {
                                    baseColor 0.1 0.1 0.6
                                  }
                                  geometry DEF TIBIA_SHAPE Box {
                                    size 0.025 0.025 0.15
                                  }
                                }
                              ]
                              boundingObject USE TIBIA_SHAPE
                              physics Physics {
                              }
                            }
                            DEF ELBOW_SHAPE Shape {
                              appearance MattePaint {
                                baseColor 0 0 0
                              }
                              geometry Cylinder {
                                height 0.025
                                radius 0.0125
                              }
                            }
                          ]
                        }
                      ]
                      boundingObject USE ELBOW_SHAPE
                      physics Physics {
                      }
                      linearVelocity 1.1317829466809742e-05 1.679044756520472e-06 -1.8421843960162452e-05
                      angularVelocity 4.226641171887176e-06 6.705378043381184e-06 1.5722782191154806e-05
                    }
                  }
                  DEF FEMUR_SHAPE Shape {
                    appearance MattePaint {
                      baseColor 0.2 0.2 1
                    }
                    geometry Box {
                      size 0.025 0.025 0.1
                    }
                  }
                ]
                boundingObject USE FEMUR_SHAPE
                physics Physics {
                }
              }
              Shape {
                appearance MattePaint {
                  baseColor 0 0 0
                }
                geometry DEF SHOULDER_SHAPE Sphere {
                  radius 0.02
                }
              }
            ]
          }
        ]
        name "solid(3)"
        boundingObject USE SHOULDER_SHAPE
        physics Physics {
        }
        linearVelocity 6.04151971419951e-06 1.757359041574908e-06 -1.1485609235446028e-05
        angularVelocity -4.418207703466695e-07 -7.53601398167101e-07 -5.383423776058425e-06
      }
    }
    Hinge2Joint {
      jointParameters HingeJointParameters {
        position -0.18701842185931378
      }
      jointParameters2 JointParameters {
        position -0.11898370058349454
        axis 0 1 0
      }
      device [
        DEF SHOULDER_3_x RotationalMotor {
          name "Hexabot_Leg3_Motor1"
        }
      ]
      device2 [
        DEF SHOULDER_3_y RotationalMotor {
          name "Hexabot_Leg3_Motor2"
        }
      ]
      endPoint DEF SHOULDER_0 Solid {
        translation -0.09170580821432645 0.003948738262834848 -0.033120271463227165
        rotation -0.7938313835395976 0.6055229219440555 -0.05633582792452322 0.23518297487320616
        children [
          Transform {
            translation 0 0 -0.01
            children [
              DEF FEMUR_0 Solid {
                translation 0 0.0259808 -0.045
                rotation 1 0 0 0.523599
                children [
                  HingeJoint {
                    jointParameters HingeJointParameters {
                      position -0.39920276136958666
                      axis 0 0 1
                    }
                    device [
                      DEF ELBOW_3 RotationalMotor {
                        name "Hexabot_Leg3_Motor3"
                      }
                    ]
                    endPoint Solid {
                      translation -1.2839576688147887e-05 -2.164096262787587e-05 -0.06002055998798724
                      rotation 4.0288381794553625e-05 4.7118679204244495e-05 -0.9999999980783381 1.7082011539428552
                      children [
                        Transform {
                          children [
                            Solid {
                              translation 0.0824507 0 0.0210637
                              rotation 0 -1 0 1.8325953071795864
                              children [
                                Shape {
                                  appearance MattePaint {
                                    baseColor 0.1 0.1 0.6
                                  }
                                  geometry DEF TIBIA_SHAPE Box {
                                    size 0.025 0.025 0.15
                                  }
                                }
                              ]
                              boundingObject USE TIBIA_SHAPE
                              physics Physics {
                              }
                            }
                            DEF ELBOW_SHAPE Shape {
                              appearance MattePaint {
                                baseColor 0 0 0
                              }
                              geometry Cylinder {
                                height 0.025
                                radius 0.0125
                              }
                            }
                          ]
                        }
                      ]
                      boundingObject USE ELBOW_SHAPE
                      physics Physics {
                      }
                      linearVelocity 9.40726011229784e-06 1.9536944752935172e-06 -9.540904912457863e-06
                      angularVelocity -4.284818163271234e-07 -1.6687004369279603e-06 -5.080824560418999e-06
                    }
                  }
                  DEF FEMUR_SHAPE Shape {
                    appearance MattePaint {
                      baseColor 0.2 0.2 1
                    }
                    geometry Box {
                      size 0.025 0.025 0.1
                    }
                  }
                ]
                boundingObject USE FEMUR_SHAPE
                physics Physics {
                }
              }
              Shape {
                appearance MattePaint {
                  baseColor 0 0 0
                }
                geometry DEF SHOULDER_SHAPE Sphere {
                  radius 0.02
                }
              }
            ]
          }
        ]
        name "solid(2)"
        boundingObject USE SHOULDER_SHAPE
        physics Physics {
        }
        linearVelocity 5.8949428896056744e-06 1.68000848301144e-06 -7.200624744599345e-06
        angularVelocity -7.033358165855895e-07 -1.5388828605496726e-06 -5.232782142153964e-06
      }
    }
    Hinge2Joint {
      jointParameters HingeJointParameters {
        position 0.08701811606898441
      }
      jointParameters2 JointParameters {
        position -0.2810160031576002
        axis 0 1 0
      }
      device [
        DEF SHOULDER_4_x RotationalMotor {
          name "Hexabot_Leg4_Motor1"
        }
      ]
      device2 [
        DEF SHOULDER_4_y RotationalMotor {
          name "Hexabot_Leg4_Motor2"
        }
      ]
      endPoint DEF SHOULDER_0 Solid {
        translation -0.005342790473218071 0.004667769100993287 -0.05339921142731073
        rotation 0.29393351841055 -0.9549213016405199 -0.041573963342095226 0.2940956366714626
        children [
          Transform {
            translation 0 0 -0.01
            children [
              DEF FEMUR_0 Solid {
                translation 0 0.0259808 -0.045
                rotation 1 0 0 0.523599
                children [
                  HingeJoint {
                    jointParameters HingeJointParameters {
                      position 0.1992026944130039
                      axis 0 0 1
                    }
                    device [
                      DEF ELBOW_4 RotationalMotor {
                        name "Hexabot_Leg4_Motor3"
                      }
                    ]
                    endPoint Solid {
                      translation -4.9087532192350704e-12 2.4315190959787157e-11 -0.05999999999999945
                      rotation 2.0671469586441863e-10 2.526163384385089e-10 -1 1.3715926127664353
                      children [
                        Transform {
                          children [
                            Solid {
                              translation 0.0824507 0 0.0210637
                              rotation 0 -1 0 1.8325953071795864
                              children [
                                Shape {
                                  appearance MattePaint {
                                    baseColor 0.1 0.1 0.6
                                  }
                                  geometry DEF TIBIA_SHAPE Box {
                                    size 0.025 0.025 0.15
                                  }
                                }
                              ]
                              boundingObject USE TIBIA_SHAPE
                              physics Physics {
                              }
                            }
                            DEF ELBOW_SHAPE Shape {
                              appearance MattePaint {
                                baseColor 0 0 0
                              }
                              geometry Cylinder {
                                height 0.025
                                radius 0.0125
                              }
                            }
                          ]
                        }
                      ]
                      boundingObject USE ELBOW_SHAPE
                      physics Physics {
                      }
                      linearVelocity 1.7858538344427358e-06 9.34595716290874e-07 -4.572110332437871e-06
                      angularVelocity -1.1723347499608385e-06 -1.7644249051347151e-06 -4.604300307049419e-06
                    }
                  }
                  DEF FEMUR_SHAPE Shape {
                    appearance MattePaint {
                      baseColor 0.2 0.2 1
                    }
                    geometry Box {
                      size 0.025 0.025 0.1
                    }
                  }
                ]
                boundingObject USE FEMUR_SHAPE
                physics Physics {
                }
              }
              Shape {
                appearance MattePaint {
                  baseColor 0 0 0
                }
                geometry DEF SHOULDER_SHAPE Sphere {
                  radius 0.02
                }
              }
            ]
          }
        ]
        name "solid(1)"
        boundingObject USE SHOULDER_SHAPE
        physics Physics {
        }
        linearVelocity 1.9460597163139086e-06 1.1039194522870914e-06 -4.692077491058093e-06
        angularVelocity -8.584773836950821e-07 -1.0240350787063927e-06 -5.59591867376193e-06
      }
    }
    Hinge2Joint {
      jointParameters HingeJointParameters {
        position -0.08701627280834168
      }
      jointParameters2 JointParameters {
        position -0.11898417985910363
        axis 0 1 0
      }
      device [
        DEF SHOULDER_5_x RotationalMotor {
          name "Hexabot_Leg5_Motor1"
        }
      ]
      device2 [
        DEF SHOULDER_5_y RotationalMotor {
          name "Hexabot_Leg5_Motor2"
        }
      ]
      endPoint DEF SHOULDER_0 Solid {
        translation 0.08655658770013892 -0.004339744727665627 -0.049891065699299304
        rotation -0.5897342366292587 -0.8068331278510577 0.03512597257563752 0.1473775102861309
        children [
          Transform {
            translation 0 0 -0.01
            children [
              DEF FEMUR_0 Solid {
                translation 0 0.0259808 -0.045
                rotation 1 0 0 0.523599
                children [
                  HingeJoint {
                    jointParameters HingeJointParameters {
                      position 0.0007996067244468903
                      axis 0 0 1
                    }
                    device [
                      DEF ELBOW_5 RotationalMotor {
                        name "Hexabot_Leg5_Motor3"
                      }
                    ]
                    endPoint Solid {
                      translation 1.2699246905232321e-25 -1.5881862683816266e-22 -0.06000000000000026
                      rotation -1.1682623402025153e-20 -3.599766937295845e-21 -1 1.5699957004551022
                      children [
                        Transform {
                          children [
                            Solid {
                              translation 0.0824507 0 0.0210637
                              rotation 0 -1 0 1.8325953071795864
                              children [
                                Shape {
                                  appearance MattePaint {
                                    baseColor 0.1 0.1 0.6
                                  }
                                  geometry DEF TIBIA_SHAPE Box {
                                    size 0.025 0.025 0.15
                                  }
                                }
                              ]
                              boundingObject USE TIBIA_SHAPE
                              physics Physics {
                              }
                            }
                            DEF ELBOW_SHAPE Shape {
                              appearance MattePaint {
                                baseColor 0 0 0
                              }
                              geometry Cylinder {
                                height 0.025
                                radius 0.0125
                              }
                            }
                          ]
                        }
                      ]
                      boundingObject USE ELBOW_SHAPE
                      physics Physics {
                      }
                      recognitionColors [
                        0 0 0
                      ]
                      linearVelocity -1.2069386407225282e-05 4.419173776871287e-07 1.3731118450166065e-05
                      angularVelocity -5.0717030357556205e-06 -1.0502084167193623e-05 1.3497972628236533e-05
                    }
                  }
                  DEF FEMUR_SHAPE Shape {
                    appearance MattePaint {
                      baseColor 0.2 0.2 1
                    }
                    geometry Box {
                      size 0.025 0.025 0.1
                    }
                  }
                ]
                boundingObject USE FEMUR_SHAPE
                physics Physics {
                }
              }
              Shape {
                appearance MattePaint {
                  baseColor 0 0 0
                }
                geometry DEF SHOULDER_SHAPE Sphere {
                  radius 0.02
                }
              }
            ]
          }
        ]
        boundingObject USE SHOULDER_SHAPE
        physics Physics {
        }
        linearVelocity -5.971225489087732e-06 5.723360318288113e-07 4.418911407256005e-06
        angularVelocity -1.4314308930597198e-06 -7.095794882563402e-07 -6.457550840189216e-06
      }
    }
  ]
  name "Hexabot"
  boundingObject USE BODY_TRAN
  physics Physics {
  }
  controller "my_controller_c"
  linearVelocity 1.7679761470910059e-06 1.3032385814662283e-06 -4.680517571199234e-06
  angularVelocity -8.584756123230371e-07 -1.0240057121499225e-06 -5.5959078007096345e-06
}
RectangleArena {
  translation 0 -0.05 0
  floorSize 10 10
  wallHeight 0.5
}
OilBarrel {
  translation -3.01 0.44 -2.67
}
OilBarrel {
  translation -3.01 0.44 3.02
  name "oil barrel(2)"
}
OilBarrel {
  translation 3.04 0.44 -2.67
  name "oil barrel(1)"
}
OilBarrel {
  translation 3.04 0.44 2.99
  name "oil barrel(3)"
}
