#VRML_SIM R2020a utf8
WorldInfo {
}
Viewpoint {
  orientation 0.5015773690437272 0.6312174428742108 0.591595032665518 4.305496363837945
  position -4.368625830635835 20.630502349364516 4.0449810814843055
  follow "Hexabot"
  followType "None"
}
Background {
  skyColor [
    0.15 0.45 1
  ]
}
Robot {
  translation -0.0532704964855096 0.06414219654386595 -0.038556236979239836
  rotation -0.025346587054716322 0.9996677205082789 0.004690319654257242 -1.9850085185901623
  children [
    Compass {
      name "Hexabot_Compass"
    }
    Gyro {
      name "Hexabot_Gyro"
    }
    GPS {
      name "Hexabot_GPS"
    }
    Camera {
      translation 0.1 -1.12008e-13 -1.49482e-07
      rotation 8.684229999951365e-07 -0.9999999999943995 3.2321499999818985e-06 1.5707853071795865
      children [
        DEF CAM_SHAPE Shape {
          appearance MattePaint {
            baseColor 0.7 0.1 0.1
          }
          geometry Cylinder {
            height 0.05
            radius 0.0125
          }
        }
      ]
      name "Hexabot_Camera"
      boundingObject USE CAM_SHAPE
      physics Physics {
      }
      lens Lens {
      }
      focus Focus {
      }
    }
    DEF BODY_TRAN Transform {
      children [
        DEF BODY Shape {
          appearance MattePaint {
            baseColor 0.1 0.1 0.7
          }
          geometry Box {
            size 0.2 0.05 0.125
          }
        }
      ]
    }
    Hinge2Joint {
      jointParameters HingeJointParameters {
        position -0.012982230922916074
      }
      jointParameters2 JointParameters {
        position -0.19140895236254968
        axis 0 1 0
      }
      device [
        DEF SHOULDER_2_x RotationalMotor {
          name "Hexabot_Leg0_Motor1"
        }
      ]
      device2 [
        DEF SHOULDER_0_y RotationalMotor {
          name "Hexabot_Leg0_Motor2"
        }
      ]
      endPoint DEF SHOULDER_0 Solid {
        translation 0.08073777531912592 -0.011335381236784773 0.045800391795649015
        rotation 0.9868197590121875 0.026715253525359917 -0.15960281467506787 2.0631888036860655
        children [
          Transform {
            children [
              DEF FEMUR_0 Solid {
                translation 0 0.025981 -0.0450019
                rotation 1 0 0 0.523599
                children [
                  HingeJoint {
                    jointParameters HingeJointParameters {
                      position -0.2597741271187516
                      axis 0 0 1
                    }
                    device [
                      DEF ELBOW_0 RotationalMotor {
                        name "Hexabot_Leg0_Motor3"
                      }
                    ]
                    endPoint Solid {
                      translation -0.000154104972917956 -0.0007191024315706528 -0.058563902416361405
                      rotation -0.7068784894709568 -0.6919884953460402 -0.1465425652565894 2.822181344190025
                      children [
                        Transform {
                          children [
                            Solid {
                              translation 0.0824507 0 0.0210637
                              rotation 0 -1 0 1.8325953071795864
                              children [
                                Shape {
                                  appearance MattePaint {
                                    baseColor 0.1 0.1 0.6
                                  }
                                  geometry DEF TIBIA_SHAPE Box {
                                    size 0.025 0.025 0.15
                                  }
                                }
                              ]
                              boundingObject USE TIBIA_SHAPE
                              physics Physics {
                              }
                            }
                            DEF ELBOW_SHAPE Shape {
                              appearance MattePaint {
                                baseColor 0 0 0
                              }
                              geometry Cylinder {
                                height 0.025
                                radius 0.0125
                              }
                            }
                          ]
                        }
                      ]
                      boundingObject USE ELBOW_SHAPE
                      physics Physics {
                      }
                      linearVelocity 1.3613378320210096e-05 3.0317152279482474e-06 1.2343336980430657e-06
                      angularVelocity -1.611884353735564e-06 -2.115685729755241e-06 -8.637430685228792e-06
                    }
                  }
                  DEF FEMUR_SHAPE Shape {
                    appearance MattePaint {
                      baseColor 0.2 0.2 1
                    }
                    geometry Box {
                      size 0.025 0.025 0.1
                    }
                  }
                ]
                boundingObject USE FEMUR_SHAPE
                physics Physics {
                }
              }
              Shape {
                appearance MattePaint {
                  baseColor 0 0 0
                }
                geometry DEF SHOULDER_SHAPE Sphere {
                  radius 0.02
                }
              }
            ]
          }
        ]
        name "solid(5)"
        boundingObject USE SHOULDER_SHAPE
        physics Physics {
        }
        linearVelocity 9.912412631487192e-06 2.2438328517422946e-06 1.8116465305065881e-06
        angularVelocity -1.6425218649633654e-06 -2.109998586646064e-06 -9.223211802739621e-06
      }
    }
    Hinge2Joint {
      jointParameters HingeJointParameters {
        position 0.41298187864214786
      }
      jointParameters2 JointParameters {
        position -0.20859114997567718
        axis 0 1 0
      }
      device [
        DEF SHOULDER_2_x RotationalMotor {
          name "Hexabot_Leg1_Motor1"
        }
      ]
      device2 [
        DEF SHOULDER_0_y RotationalMotor {
          name "Hexabot_Leg1_Motor2"
        }
      ]
      endPoint DEF SHOULDER_0 Solid {
        translation -0.0015047999282635591 -0.014687662247645039 0.05798943341418375
        rotation 0.9965392548152796 0.021688310346196026 -0.08024419484632077 1.6965326783932186
        children [
          Transform {
            children [
              DEF FEMUR_0 Solid {
                translation 0 0.025981 -0.0450019
                rotation 1 0 0 0.523599
                children [
                  HingeJoint {
                    jointParameters HingeJointParameters {
                      position -0.34022585915464654
                      axis 0 0 1
                    }
                    device [
                      DEF ELBOW_0 RotationalMotor {
                        name "Hexabot_Leg1_Motor3"
                      }
                    ]
                    endPoint Solid {
                      translation -0.0002047457883927031 -0.0005927196659339916 -0.05861795080600518
                      rotation -0.7334436480633552 -0.6623940075948731 -0.1526256656592203 2.8340229046667047
                      children [
                        Transform {
                          children [
                            Solid {
                              translation 0.0824507 0 0.0210637
                              rotation 0 -1 0 1.8325953071795864
                              children [
                                Shape {
                                  appearance MattePaint {
                                    baseColor 0.1 0.1 0.6
                                  }
                                  geometry DEF TIBIA_SHAPE Box {
                                    size 0.025 0.025 0.15
                                  }
                                }
                              ]
                              boundingObject USE TIBIA_SHAPE
                              physics Physics {
                              }
                            }
                            DEF ELBOW_SHAPE Shape {
                              appearance MattePaint {
                                baseColor 0 0 0
                              }
                              geometry Cylinder {
                                height 0.025
                                radius 0.0125
                              }
                            }
                          ]
                        }
                      ]
                      boundingObject USE ELBOW_SHAPE
                      physics Physics {
                      }
                      linearVelocity 6.540846810476896e-06 2.7578341129491294e-06 2.188337145810928e-06
                      angularVelocity -1.652079203941616e-06 -1.955991509223769e-06 -9.451990300394181e-06
                    }
                  }
                  DEF FEMUR_SHAPE Shape {
                    appearance MattePaint {
                      baseColor 0.2 0.2 1
                    }
                    geometry Box {
                      size 0.025 0.025 0.1
                    }
                  }
                ]
                boundingObject USE FEMUR_SHAPE
                physics Physics {
                }
              }
              Shape {
                appearance MattePaint {
                  baseColor 0 0 0
                }
                geometry DEF SHOULDER_SHAPE Sphere {
                  radius 0.02
                }
              }
            ]
          }
        ]
        name "solid(4)"
        boundingObject USE SHOULDER_SHAPE
        physics Physics {
        }
        linearVelocity 6.32295262365442e-06 1.8649965566849516e-06 2.3623944720125817e-06
        angularVelocity -1.819810304293043e-06 -2.1093743425052755e-06 -9.555028847801891e-06
      }
    }
    Hinge2Joint {
      jointParameters HingeJointParameters {
        position 1.1870167617091236
      }
      jointParameters2 JointParameters {
        position -0.19140931083843443
        axis 0 1 0
      }
      device [
        DEF SHOULDER_2_x RotationalMotor {
          name "Hexabot_Leg2_Motor1"
        }
      ]
      device2 [
        DEF SHOULDER_0_y RotationalMotor {
          name "Hexabot_Leg2_Motor2"
        }
      ]
      endPoint DEF SHOULDER_0 Solid {
        translation -0.087492807886887 -0.0015395661710801214 0.05127692382218525
        rotation 0.9954758567672949 -0.03282618339108787 -0.089164232051842 2.2670795384503433
        children [
          Transform {
            children [
              DEF FEMUR_0 Solid {
                translation 0 0.025981 -0.0450019
                rotation 1 0 0 0.523599
                children [
                  HingeJoint {
                    jointParameters HingeJointParameters {
                      position -0.2597738971191752
                      axis 0 0 1
                    }
                    device [
                      DEF ELBOW_0 RotationalMotor {
                        name "Hexabot_Leg2_Motor3"
                      }
                    ]
                    endPoint Solid {
                      translation -0.00015461140469243614 -0.0006830830291670235 -0.05857588456507889
                      rotation -0.7124404998200736 -0.6997695967747197 -0.05245041130315192 3.0044149786023566
                      children [
                        Transform {
                          children [
                            Solid {
                              translation 0.0824507 0 0.0210637
                              rotation 0 -1 0 1.8325953071795864
                              children [
                                Shape {
                                  appearance MattePaint {
                                    baseColor 0.1 0.1 0.6
                                  }
                                  geometry DEF TIBIA_SHAPE Box {
                                    size 0.025 0.025 0.15
                                  }
                                }
                              ]
                              boundingObject USE TIBIA_SHAPE
                              physics Physics {
                              }
                            }
                            DEF ELBOW_SHAPE Shape {
                              appearance MattePaint {
                                baseColor 0 0 0
                              }
                              geometry Cylinder {
                                height 0.025
                                radius 0.0125
                              }
                            }
                          ]
                        }
                      ]
                      boundingObject USE ELBOW_SHAPE
                      physics Physics {
                      }
                      linearVelocity 1.7773195337503873e-05 2.1752809990022094e-06 1.3725318104793152e-05
                      angularVelocity -2.635688716273325e-06 -1.615596897248314e-06 -8.364073333656103e-06
                    }
                  }
                  DEF FEMUR_SHAPE Shape {
                    appearance MattePaint {
                      baseColor 0.2 0.2 1
                    }
                    geometry Box {
                      size 0.025 0.025 0.1
                    }
                  }
                ]
                boundingObject USE FEMUR_SHAPE
                physics Physics {
                }
              }
              Shape {
                appearance MattePaint {
                  baseColor 0 0 0
                }
                geometry DEF SHOULDER_SHAPE Sphere {
                  radius 0.02
                }
              }
            ]
          }
        ]
        name "solid(3)"
        boundingObject USE SHOULDER_SHAPE
        physics Physics {
        }
        linearVelocity 1.2212397938658477e-05 1.3753286587331648e-06 8.117320222612016e-06
        angularVelocity -2.205213584001162e-06 -2.006764812307076e-06 -9.183526482352579e-06
      }
    }
    Hinge2Joint {
      jointParameters HingeJointParameters {
        position -0.012981866352193103
      }
      jointParameters2 JointParameters {
        position -0.19140885997712537
        axis 0 1 0
      }
      device [
        DEF SHOULDER_3_x RotationalMotor {
          name "Hexabot_Leg3_Motor1"
        }
      ]
      device2 [
        DEF SHOULDER_3_y RotationalMotor {
          name "Hexabot_Leg3_Motor2"
        }
      ]
      endPoint DEF SHOULDER_0 Solid {
        translation -0.08916366958934793 0.00953910908729519 -0.03848825274147122
        rotation -0.1812857234285751 0.9834182247769797 -0.004907306539440991 0.07157701062488575
        children [
          Transform {
            translation 0 0 -0.01
            children [
              DEF FEMUR_0 Solid {
                translation 0 0.0259808 -0.045
                rotation 1 0 0 0.523599
                children [
                  HingeJoint {
                    jointParameters HingeJointParameters {
                      position -0.25977414038219093
                      axis 0 0 1
                    }
                    device [
                      DEF ELBOW_3 RotationalMotor {
                        name "Hexabot_Leg3_Motor3"
                      }
                    ]
                    endPoint Solid {
                      translation -9.707373245044193e-06 -2.3215359089907495e-05 -0.060020559987987235
                      rotation 3.9394843985103656e-05 5.3166365000568614e-05 -0.999999997810692 1.568772533241215
                      children [
                        Transform {
                          children [
                            Solid {
                              translation 0.0824507 0 0.0210637
                              rotation 0 -1 0 1.8325953071795864
                              children [
                                Shape {
                                  appearance MattePaint {
                                    baseColor 0.1 0.1 0.6
                                  }
                                  geometry DEF TIBIA_SHAPE Box {
                                    size 0.025 0.025 0.15
                                  }
                                }
                              ]
                              boundingObject USE TIBIA_SHAPE
                              physics Physics {
                              }
                            }
                            DEF ELBOW_SHAPE Shape {
                              appearance MattePaint {
                                baseColor 0 0 0
                              }
                              geometry Cylinder {
                                height 0.025
                                radius 0.0125
                              }
                            }
                          ]
                        }
                      ]
                      boundingObject USE ELBOW_SHAPE
                      physics Physics {
                      }
                      linearVelocity 5.961722373772366e-06 -5.928381245911963e-07 2.9587428656433983e-06
                      angularVelocity -1.7063916324857298e-06 -2.2405322941130014e-06 -9.530118484298163e-06
                    }
                  }
                  DEF FEMUR_SHAPE Shape {
                    appearance MattePaint {
                      baseColor 0.2 0.2 1
                    }
                    geometry Box {
                      size 0.025 0.025 0.1
                    }
                  }
                ]
                boundingObject USE FEMUR_SHAPE
                physics Physics {
                }
              }
              Shape {
                appearance MattePaint {
                  baseColor 0 0 0
                }
                geometry DEF SHOULDER_SHAPE Sphere {
                  radius 0.02
                }
              }
            ]
          }
        ]
        name "solid(2)"
        boundingObject USE SHOULDER_SHAPE
        physics Physics {
        }
        linearVelocity 6.4123790811334446e-06 1.1628479641546014e-07 2.7285614456654166e-06
        angularVelocity -1.7582396117463302e-06 -2.1543689486355353e-06 -9.520099562079393e-06
      }
    }
    Hinge2Joint {
      jointParameters HingeJointParameters {
        position -0.08701592211166372
      }
      jointParameters2 JointParameters {
        position -0.20859102018180503
        axis 0 1 0
      }
      device [
        DEF SHOULDER_4_x RotationalMotor {
          name "Hexabot_Leg4_Motor1"
        }
      ]
      device2 [
        DEF SHOULDER_4_y RotationalMotor {
          name "Hexabot_Leg4_Motor2"
        }
      ]
      endPoint DEF SHOULDER_0 Solid {
        translation -0.009207575394764002 -0.004603368837461606 -0.052875692053868606
        rotation -0.3837095333743001 -0.9225799549413869 0.040164919245847454 0.22595244389120542
        children [
          Transform {
            translation 0 0 -0.01
            children [
              DEF FEMUR_0 Solid {
                translation 0 0.0259808 -0.045
                rotation 1 0 0 0.523599
                children [
                  HingeJoint {
                    jointParameters HingeJointParameters {
                      position 0.05977404660326194
                      axis 0 0 1
                    }
                    device [
                      DEF ELBOW_4 RotationalMotor {
                        name "Hexabot_Leg4_Motor3"
                      }
                    ]
                    endPoint Solid {
                      translation -1.4818562184615048e-12 2.4761431132429974e-11 -0.05999999999999946
                      rotation 2.0671466205299464e-10 2.1945518650557417e-10 -1 1.5110212605761784
                      children [
                        Transform {
                          children [
                            Solid {
                              translation 0.0824507 0 0.0210637
                              rotation 0 -1 0 1.8325953071795864
                              children [
                                Shape {
                                  appearance MattePaint {
                                    baseColor 0.1 0.1 0.6
                                  }
                                  geometry DEF TIBIA_SHAPE Box {
                                    size 0.025 0.025 0.15
                                  }
                                }
                              ]
                              boundingObject USE TIBIA_SHAPE
                              physics Physics {
                              }
                            }
                            DEF ELBOW_SHAPE Shape {
                              appearance MattePaint {
                                baseColor 0 0 0
                              }
                              geometry Cylinder {
                                height 0.025
                                radius 0.0125
                              }
                            }
                          ]
                        }
                      ]
                      boundingObject USE ELBOW_SHAPE
                      physics Physics {
                      }
                      linearVelocity -1.398281570584799e-05 -2.7762572752781777e-07 -7.66123620995024e-06
                      angularVelocity -4.334899713980503e-07 -2.4869336762513685e-06 -1.154938264101145e-05
                    }
                  }
                  DEF FEMUR_SHAPE Shape {
                    appearance MattePaint {
                      baseColor 0.2 0.2 1
                    }
                    geometry Box {
                      size 0.025 0.025 0.1
                    }
                  }
                ]
                boundingObject USE FEMUR_SHAPE
                physics Physics {
                }
              }
              Shape {
                appearance MattePaint {
                  baseColor 0 0 0
                }
                geometry DEF SHOULDER_SHAPE Sphere {
                  radius 0.02
                }
              }
            ]
          }
        ]
        name "solid(1)"
        boundingObject USE SHOULDER_SHAPE
        physics Physics {
        }
        linearVelocity -3.630734246609392e-06 4.2050564543876103e-07 -2.5617788232171163e-06
        angularVelocity -1.4220395972496973e-06 -2.2176652687722897e-06 -1.01557255413513e-05
      }
    }
    Hinge2Joint {
      jointParameters HingeJointParameters {
        position 0.087018129353675
      }
      jointParameters2 JointParameters {
        position -0.1914088836532651
        axis 0 1 0
      }
      device [
        DEF SHOULDER_5_x RotationalMotor {
          name "Hexabot_Leg5_Motor1"
        }
      ]
      device2 [
        DEF SHOULDER_5_y RotationalMotor {
          name "Hexabot_Leg5_Motor2"
        }
      ]
      endPoint DEF SHOULDER_0 Solid {
        translation 0.08995349726453687 0.0038090604886597632 -0.04351843383300441
        rotation 0.4127018401434273 -0.9100041598416408 -0.039618432744601216 0.2102055657876163
        children [
          Transform {
            translation 0 0 -0.01
            children [
              DEF FEMUR_0 Solid {
                translation 0 0.0259808 -0.045
                rotation 1 0 0 0.523599
                children [
                  HingeJoint {
                    jointParameters HingeJointParameters {
                      position 0.140225852544186
                      axis 0 0 1
                    }
                    device [
                      DEF ELBOW_5 RotationalMotor {
                        name "Hexabot_Leg5_Motor3"
                      }
                    ]
                    endPoint Solid {
                      translation 2.219757102594219e-23 -1.5725978569995258e-22 -0.06000000000000026
                      rotation -1.2290126179021791e-20 -4.747270768012586e-21 -1 1.4305694546353638
                      children [
                        Transform {
                          children [
                            Solid {
                              translation 0.0824507 0 0.0210637
                              rotation 0 -1 0 1.8325953071795864
                              children [
                                Shape {
                                  appearance MattePaint {
                                    baseColor 0.1 0.1 0.6
                                  }
                                  geometry DEF TIBIA_SHAPE Box {
                                    size 0.025 0.025 0.15
                                  }
                                }
                              ]
                              boundingObject USE TIBIA_SHAPE
                              physics Physics {
                              }
                            }
                            DEF ELBOW_SHAPE Shape {
                              appearance MattePaint {
                                baseColor 0 0 0
                              }
                              geometry Cylinder {
                                height 0.025
                                radius 0.0125
                              }
                            }
                          ]
                        }
                      ]
                      boundingObject USE ELBOW_SHAPE
                      physics Physics {
                      }
                      recognitionColors [
                        0 0 0
                      ]
                      linearVelocity 5.5778316966636494e-06 5.722915255987723e-07 2.6175385144677397e-06
                      angularVelocity -1.6823137906385733e-06 -2.2286112367560707e-06 -9.518384609078143e-06
                    }
                  }
                  DEF FEMUR_SHAPE Shape {
                    appearance MattePaint {
                      baseColor 0.2 0.2 1
                    }
                    geometry Box {
                      size 0.025 0.025 0.1
                    }
                  }
                ]
                boundingObject USE FEMUR_SHAPE
                physics Physics {
                }
              }
              Shape {
                appearance MattePaint {
                  baseColor 0 0 0
                }
                geometry DEF SHOULDER_SHAPE Sphere {
                  radius 0.02
                }
              }
            ]
          }
        ]
        boundingObject USE SHOULDER_SHAPE
        physics Physics {
        }
        linearVelocity 6.004254437964744e-06 1.1109271226929201e-06 2.4644396048014615e-06
        angularVelocity -1.7549264816888002e-06 -2.138780358697861e-06 -9.517970909712658e-06
      }
    }
  ]
  name "Hexabot"
  boundingObject USE BODY_TRAN
  physics Physics {
  }
  controller "my_controller_c"
  linearVelocity 6.072868437252319e-06 1.2360172634565164e-06 2.513526571225594e-06
  angularVelocity -1.8955375217873526e-06 -2.151004668507104e-06 -9.585162788891591e-06
}
RectangleArena {
  translation 0 -0.05 0
  floorSize 10 10
  wallHeight 0.5
}
OilBarrel {
  translation -3.01 0.44 -2.67
}
OilBarrel {
  translation -3.01 0.44 3.02
  name "oil barrel(2)"
}
OilBarrel {
  translation 3.04 0.44 -2.67
  name "oil barrel(1)"
}
OilBarrel {
  translation 3.04 0.44 2.99
  name "oil barrel(3)"
}
