#VRML_SIM R2020a utf8
WorldInfo {
}
Viewpoint {
  orientation 0.42542137978313194 -0.9037078575068394 -0.04825720571908874 5.387758547255961
  position 0.6434985749397251 0.580684252421332 0.34725259956058707
  follow "Hexabot"
  followType "None"
}
TexturedBackground {
}
TexturedBackgroundLight {
}
RectangleArena {
  translation 0 -0.05 0
  floorSize 10 10
  wallHeight 0.5
}
Robot {
  translation 0.24035304561300497 0.05128694651810881 -0.2039032035337391
  rotation -4.209214032428232e-05 0.9999999989903187 -1.5735763036400527e-05 2.5830853199836747
  children [
    Camera {
      translation 0.1 -1.12008e-13 -1.49482e-07
      rotation 8.684229999951365e-07 -0.9999999999943995 3.2321499999818985e-06 1.5707853071795865
      children [
        DEF CAM_SHAPE Shape {
          appearance MattePaint {
            baseColor 0.7 0.1 0.1
          }
          geometry Cylinder {
            height 0.05
            radius 0.0125
          }
        }
      ]
      name "Hexabot_Camera"
      boundingObject USE CAM_SHAPE
      physics Physics {
      }
      lens Lens {
      }
      focus Focus {
      }
    }
    DEF BODY_TRAN Transform {
      children [
        DEF BODY Shape {
          appearance MattePaint {
            baseColor 0.1 0.1 0.7
          }
          geometry Box {
            size 0.2 0.05 0.125
          }
        }
      ]
    }
    Hinge2Joint {
      jointParameters HingeJointParameters {
        position -6.204215249101391e-06
      }
      jointParameters2 JointParameters {
        position -5.504036991428762e-06
      }
      device [
        DEF SHOULDER_2_x RotationalMotor {
        }
      ]
      device2 [
        DEF SHOULDER_0_y RotationalMotor {
        }
      ]
      endPoint DEF SHOULDER_0 Solid {
        translation 0.07999999881727098 1.5802164645541313e-05 0.07000006533279779
        rotation 2.7520156141081375e-06 0.9999999999914017 -3.1021103583089557e-06 3.141590795955076
        children [
          Transform {
            children [
              DEF FEMUR_0 Solid {
                translation 0 0.025981 -0.0450019
                rotation 1 0 0 0.523599
                children [
                  HingeJoint {
                    jointParameters HingeJointParameters {
                      position 2.9696387588322616e-06
                      axis 1 1 0
                    }
                    device [
                      DEF ELBOW_0 RotationalMotor {
                      }
                    ]
                    endPoint Solid {
                      translation -1.2599110224249548e-07 1.2598183879519788e-07 -0.059999999999734994
                      rotation -7.664282719069595e-11 2.0997760971434677e-06 -0.9999999999977953 1.570795307180906
                      children [
                        Transform {
                          children [
                            Solid {
                              translation 0.0824507 0 0.0210637
                              rotation 0 -1 0 1.8325953071795864
                              children [
                                Shape {
                                  appearance MattePaint {
                                    baseColor 0.1 0.1 0.6
                                  }
                                  geometry DEF TIBIA_SHAPE Box {
                                    size 0.025 0.025 0.15
                                  }
                                }
                              ]
                              boundingObject USE TIBIA_SHAPE
                              physics Physics {
                              }
                            }
                            DEF ELBOW_SHAPE Shape {
                              appearance MattePaint {
                                baseColor 0 0 0
                              }
                              geometry Cylinder {
                                height 0.025
                                radius 0.0125
                              }
                            }
                          ]
                        }
                      ]
                      boundingObject USE ELBOW_SHAPE
                      physics Physics {
                      }
                      linearVelocity -2.600819492504197e-07 8.168390054473918e-08 6.622456360398693e-08
                      angularVelocity 1.2995626716004176e-06 2.9816995992277363e-06 3.686228318675081e-06
                    }
                  }
                  DEF FEMUR_SHAPE Shape {
                    appearance MattePaint {
                      baseColor 0.2 0.2 1
                    }
                    geometry Box {
                      size 0.025 0.025 0.1
                    }
                  }
                ]
                boundingObject USE FEMUR_SHAPE
                physics Physics {
                }
              }
              Shape {
                appearance MattePaint {
                  baseColor 0 0 0
                }
                geometry DEF SHOULDER_SHAPE Sphere {
                  radius 0.02
                }
              }
            ]
          }
        ]
        name "solid(5)"
        boundingObject USE SHOULDER_SHAPE
        physics Physics {
        }
        linearVelocity -1.6892621802068924e-07 -1.330923127699559e-07 1.1704602750300068e-07
        angularVelocity -6.2061223084919e-07 1.0756528387627737e-07 5.257633147095765e-07
      }
    }
    Hinge2Joint {
      jointParameters HingeJointParameters {
        position -7.032433904904736e-06
      }
      jointParameters2 JointParameters {
        position -6.514237599705199e-06
      }
      device [
        DEF SHOULDER_1_x RotationalMotor {
        }
      ]
      device2 [
        DEF SHOULDER_1_y RotationalMotor {
        }
      ]
      endPoint DEF SHOULDER_0 Solid {
        translation 6.261378116522675e-10 1.3088746626089327e-05 0.06999996639363552
        rotation 3.2571141345371374e-06 0.9999999999885137 -3.5162212738894514e-06 3.1415900000756123
        children [
          Transform {
            children [
              DEF FEMUR_0 Solid {
                translation 0 0.0259808 -0.045
                rotation 1 0 0 0.523599
                children [
                  HingeJoint {
                    jointParameters HingeJointParameters {
                      position 3.662681951577358e-06
                    }
                    device [
                      DEF ELBOW_1 RotationalMotor {
                      }
                    ]
                    endPoint Solid {
                      translation 0 2.1974814278799724e-07 -0.059999999999597625
                      rotation 1.831236566968873e-06 1.8312343465133886e-06 -0.9999999999966466 1.5707953071845706
                      children [
                        Transform {
                          children [
                            Solid {
                              translation 0.0824507 0 0.0210637
                              rotation 0 -1 0 1.8325953071795864
                              children [
                                Shape {
                                  appearance MattePaint {
                                    baseColor 0.1 0.1 0.6
                                  }
                                  geometry DEF TIBIA_SHAPE Box {
                                    size 0.025 0.025 0.15
                                  }
                                }
                              ]
                              boundingObject USE TIBIA_SHAPE
                              physics Physics {
                              }
                            }
                            DEF ELBOW_SHAPE Shape {
                              appearance MattePaint {
                                baseColor 0 0 0
                              }
                              geometry Cylinder {
                                height 0.025
                                radius 0.0125
                              }
                            }
                          ]
                        }
                      ]
                      boundingObject USE ELBOW_SHAPE
                      physics Physics {
                      }
                      linearVelocity -5.476343629720602e-08 -8.328788818862666e-08 -4.063474364566318e-08
                      angularVelocity -5.995158590006412e-07 9.913970146455421e-08 5.38290433321782e-07
                    }
                  }
                  DEF FEMUR_SHAPE Shape {
                    appearance MattePaint {
                      baseColor 0.2 0.2 1
                    }
                    geometry Box {
                      size 0.025 0.025 0.1
                    }
                  }
                ]
                boundingObject USE FEMUR_SHAPE
                physics Physics {
                }
              }
              Shape {
                appearance MattePaint {
                  baseColor 0 0 0
                }
                geometry DEF SHOULDER_SHAPE Sphere {
                  radius 0.02
                }
              }
            ]
          }
        ]
        name "solid(4)"
        boundingObject USE SHOULDER_SHAPE
        physics Physics {
        }
        linearVelocity -8.527416775197447e-08 -6.531255582840631e-08 -3.531461403450975e-08
        angularVelocity -6.041992265067385e-07 9.96608939641705e-08 5.344740910499358e-07
      }
    }
    Hinge2Joint {
      jointParameters HingeJointParameters {
        position -7.642304955971226e-06
      }
      jointParameters2 JointParameters {
        position -7.302996998897093e-06
      }
      device [
        DEF SHOULDER_2_x RotationalMotor {
        }
      ]
      device2 [
        DEF SHOULDER_2_y RotationalMotor {
        }
      ]
      endPoint DEF SHOULDER_0 Solid {
        translation -0.07999999730994684 1.353399009870592e-05 0.0699999616738585
        rotation 3.651493424717411e-06 0.9999999999860328 -3.821157322201295e-06 3.141589997469327
        children [
          Transform {
            children [
              DEF FEMUR_0 Solid {
                translation 0 0.0259808 -0.045
                rotation 1 0 0 0.523599
                children [
                  HingeJoint {
                    jointParameters HingeJointParameters {
                      position 3.827753404837914e-06
                    }
                    device [
                      DEF ELBOW_2 RotationalMotor {
                      }
                    ]
                    endPoint Solid {
                      translation 0 2.2965174900604523e-07 -0.05999999999956142
                      rotation 1.9137665263552347e-06 1.913764575050356e-06 -0.9999999999963374 1.5707953071831273
                      children [
                        Transform {
                          children [
                            Solid {
                              translation 0.0824507 0 0.0210637
                              rotation 0 -1 0 1.8325953071795864
                              children [
                                Shape {
                                  appearance MattePaint {
                                    baseColor 0.1 0.1 0.6
                                  }
                                  geometry DEF TIBIA_SHAPE Box {
                                    size 0.025 0.025 0.15
                                  }
                                }
                              ]
                              boundingObject USE TIBIA_SHAPE
                              physics Physics {
                              }
                            }
                            DEF ELBOW_SHAPE Shape {
                              appearance MattePaint {
                                baseColor 0 0 0
                              }
                              geometry Cylinder {
                                height 0.025
                                radius 0.0125
                              }
                            }
                          ]
                        }
                      ]
                      boundingObject USE ELBOW_SHAPE
                      physics Physics {
                      }
                      linearVelocity -5.392253964629631e-08 -2.3936300528958424e-08 -4.208459251357709e-08
                      angularVelocity -6.004550055385473e-07 1.0108338168158985e-07 5.377987177180404e-07
                    }
                  }
                  DEF FEMUR_SHAPE Shape {
                    appearance MattePaint {
                      baseColor 0.2 0.2 1
                    }
                    geometry Box {
                      size 0.025 0.025 0.1
                    }
                  }
                ]
                boundingObject USE FEMUR_SHAPE
                physics Physics {
                }
              }
              Shape {
                appearance MattePaint {
                  baseColor 0 0 0
                }
                geometry DEF SHOULDER_SHAPE Sphere {
                  radius 0.02
                }
              }
            ]
          }
        ]
        name "solid(3)"
        boundingObject USE SHOULDER_SHAPE
        physics Physics {
        }
        linearVelocity -8.270006570802641e-08 -4.6846491785346285e-09 -3.9516893806135885e-08
        angularVelocity -6.04733834473746e-07 1.0161819710985921e-07 5.342118560080383e-07
      }
    }
    Hinge2Joint {
      jointParameters HingeJointParameters {
        position 7.422370666810361e-06
      }
      jointParameters2 JointParameters {
        position 6.762189955742541e-06
      }
      device [
        DEF SHOULDER_3_x RotationalMotor {
        }
      ]
      device2 [
        DEF SHOULDER_3_y RotationalMotor {
        }
      ]
      endPoint DEF SHOULDER_0 Solid {
        translation -0.07999999883137958 1.2169586536305776e-05 -0.059999969832900506
        rotation 0.7392168849938571 -2.4993624974198983e-06 0.6734674431134232 1.0040861953896805e-05
        children [
          Transform {
            translation 0 0 -0.01
            children [
              DEF FEMUR_0 Solid {
                translation 0 0.0259808 -0.045
                rotation 1 0 0 0.523599
                children [
                  HingeJoint {
                    jointParameters HingeJointParameters {
                      position 3.983018281015377e-06
                    }
                    device [
                      DEF ELBOW_3 RotationalMotor {
                      }
                    ]
                    endPoint Solid {
                      translation 0 2.3898262705731103e-07 -0.05999999999952397
                      rotation 1.991523922731752e-06 1.991521892144263e-06 -0.9999999999960337 1.5707953071834289
                      children [
                        Transform {
                          children [
                            Solid {
                              translation 0.0824507 0 0.0210637
                              rotation 0 -1 0 1.8325953071795864
                              children [
                                Shape {
                                  appearance MattePaint {
                                    baseColor 0.1 0.1 0.6
                                  }
                                  geometry DEF TIBIA_SHAPE Box {
                                    size 0.025 0.025 0.15
                                  }
                                }
                              ]
                              boundingObject USE TIBIA_SHAPE
                              physics Physics {
                              }
                            }
                            DEF ELBOW_SHAPE Shape {
                              appearance MattePaint {
                                baseColor 0 0 0
                              }
                              geometry Cylinder {
                                height 0.025
                                radius 0.0125
                              }
                            }
                          ]
                        }
                      ]
                      boundingObject USE ELBOW_SHAPE
                      physics Physics {
                      }
                      linearVelocity -4.8736716961073106e-08 5.7721418024127765e-08 -3.8845097103431096e-08
                      angularVelocity -5.986224028290019e-07 1.0007596380920787e-07 5.343943913494105e-07
                    }
                  }
                  DEF FEMUR_SHAPE Shape {
                    appearance MattePaint {
                      baseColor 0.2 0.2 1
                    }
                    geometry Box {
                      size 0.025 0.025 0.1
                    }
                  }
                ]
                boundingObject USE FEMUR_SHAPE
                physics Physics {
                }
              }
              Shape {
                appearance MattePaint {
                  baseColor 0 0 0
                }
                geometry DEF SHOULDER_SHAPE Sphere {
                  radius 0.02
                }
              }
            ]
          }
        ]
        name "solid(2)"
        boundingObject USE SHOULDER_SHAPE
        physics Physics {
        }
        linearVelocity -7.933000585322939e-08 3.825000926742803e-08 -3.73835308660704e-08
        angularVelocity -6.036357311431383e-07 1.0090837471990389e-07 5.327257708708833e-07
      }
    }
    Hinge2Joint {
      jointParameters HingeJointParameters {
        position 6.615757795147336e-06
      }
      jointParameters2 JointParameters {
        position 6.1003294472656436e-06
      }
      device [
        DEF SHOULDER_4_x RotationalMotor {
        }
      ]
      device2 [
        DEF SHOULDER_4_y RotationalMotor {
        }
      ]
      endPoint DEF SHOULDER_0 Solid {
        translation -1.3503885204108796e-09 1.2805128950182633e-05 -0.05999996476373557
        rotation 0.7351646609669863 -2.242373314949939e-06 0.6778885758443403 8.999018388221831e-06
        children [
          Transform {
            translation 0 0 -0.01
            children [
              DEF FEMUR_0 Solid {
                translation 0 0.0259808 -0.045
                rotation 1 0 0 0.523599
                children [
                  HingeJoint {
                    jointParameters HingeJointParameters {
                      position 3.392281203421644e-06
                    }
                    device [
                      DEF ELBOW_4 RotationalMotor {
                      }
                    ]
                    endPoint Solid {
                      translation 0 2.0356167793750406e-07 -0.05999999999965484
                      rotation 1.6963490457686448e-06 1.6963473161458664e-06 -0.9999999999971223 1.570795307182343
                      children [
                        Transform {
                          children [
                            Solid {
                              translation 0.0824507 0 0.0210637
                              rotation 0 -1 0 1.8325953071795864
                              children [
                                Shape {
                                  appearance MattePaint {
                                    baseColor 0.1 0.1 0.6
                                  }
                                  geometry DEF TIBIA_SHAPE Box {
                                    size 0.025 0.025 0.15
                                  }
                                }
                              ]
                              boundingObject USE TIBIA_SHAPE
                              physics Physics {
                              }
                            }
                            DEF ELBOW_SHAPE Shape {
                              appearance MattePaint {
                                baseColor 0 0 0
                              }
                              geometry Cylinder {
                                height 0.025
                                radius 0.0125
                              }
                            }
                          ]
                        }
                      ]
                      boundingObject USE ELBOW_SHAPE
                      physics Physics {
                      }
                      linearVelocity -4.964446263193842e-08 -1.669285598624675e-09 -3.7500011437517464e-08
                      angularVelocity -5.983141666787172e-07 9.812766020579498e-08 5.347474270731965e-07
                    }
                  }
                  DEF FEMUR_SHAPE Shape {
                    appearance MattePaint {
                      baseColor 0.2 0.2 1
                    }
                    geometry Box {
                      size 0.025 0.025 0.1
                    }
                  }
                ]
                boundingObject USE FEMUR_SHAPE
                physics Physics {
                }
              }
              Shape {
                appearance MattePaint {
                  baseColor 0 0 0
                }
                geometry DEF SHOULDER_SHAPE Sphere {
                  radius 0.02
                }
              }
            ]
          }
        ]
        name "solid(1)"
        boundingObject USE SHOULDER_SHAPE
        physics Physics {
        }
        linearVelocity -8.193320521688961e-08 -2.229793602307166e-08 -3.328207534200936e-08
        angularVelocity -6.036138662435958e-07 9.894689083506853e-08 5.328773091462349e-07
      }
    }
    Hinge2Joint {
      jointParameters HingeJointParameters {
        position 6.840821137988202e-06
      }
      jointParameters2 JointParameters {
        position 6.482824944086351e-06
      }
      device [
        DEF SHOULDER_5_x RotationalMotor {
        }
      ]
      device2 [
        DEF SHOULDER_5_y RotationalMotor {
        }
      ]
      endPoint DEF SHOULDER_0 Solid {
        translation 0.07999999618872988 1.3461906181416424e-05 -0.059999959364859516
        rotation 0.7258442338479902 -2.3527605523637386e-06 0.6878591048929195 9.424651676275087e-06
        children [
          Transform {
            translation 0 0 -0.01
            children [
              DEF FEMUR_0 Solid {
                translation 0 0.0259808 -0.045
                rotation 1 0 0 0.523599
                children [
                  HingeJoint {
                    jointParameters HingeJointParameters {
                      position 3.8098365963621478e-06
                    }
                    device [
                      DEF ELBOW_5 RotationalMotor {
                      }
                    ]
                    endPoint Solid {
                      translation 0 2.2859019578117524e-07 -0.05999999999956437
                      rotation 1.9049202404613277e-06 1.904918298176467e-06 -0.9999999999963712 1.570795307183209
                      children [
                        Transform {
                          children [
                            Solid {
                              translation 0.0824507 0 0.0210637
                              rotation 0 -1 0 1.8325953071795864
                              children [
                                Shape {
                                  appearance MattePaint {
                                    baseColor 0.1 0.1 0.6
                                  }
                                  geometry DEF TIBIA_SHAPE Box {
                                    size 0.025 0.025 0.15
                                  }
                                }
                              ]
                              boundingObject USE TIBIA_SHAPE
                              physics Physics {
                              }
                            }
                            DEF ELBOW_SHAPE Shape {
                              appearance MattePaint {
                                baseColor 0 0 0
                              }
                              geometry Cylinder {
                                height 0.025
                                radius 0.0125
                              }
                            }
                          ]
                        }
                      ]
                      boundingObject USE ELBOW_SHAPE
                      physics Physics {
                      }
                      recognitionColors [
                        0 0 0
                      ]
                      linearVelocity -5.051795282509261e-08 -6.105883898249715e-08 -3.6208256179738636e-08
                      angularVelocity -5.979358931415756e-07 9.568958604365032e-08 5.349214106585492e-07
                    }
                  }
                  DEF FEMUR_SHAPE Shape {
                    appearance MattePaint {
                      baseColor 0.2 0.2 1
                    }
                    geometry Box {
                      size 0.025 0.025 0.1
                    }
                  }
                ]
                boundingObject USE FEMUR_SHAPE
                physics Physics {
                }
              }
              Shape {
                appearance MattePaint {
                  baseColor 0 0 0
                }
                geometry DEF SHOULDER_SHAPE Sphere {
                  radius 0.02
                }
              }
            ]
          }
        ]
        boundingObject USE SHOULDER_SHAPE
        physics Physics {
        }
        linearVelocity -8.442217302014557e-08 -8.284751449808998e-08 -2.9355875928186418e-08
        angularVelocity -6.03501758451855e-07 9.649163821102443e-08 5.328551258685234e-07
      }
    }
  ]
  name "Hexabot"
  boundingObject USE BODY_TRAN
  physics Physics {
  }
  controller "my_controller_c"
  linearVelocity -8.785268707918812e-08 -4.5789335875548144e-08 9.833913725479437e-10
  angularVelocity -6.067158970072445e-07 1.008652175661172e-07 5.321509318695604e-07
}
Solid {
  translation -0.52 0.04794657811366633 -0.8
  children [
    DEF TEST_SHAPE Shape {
      appearance GenericTireAppearance {
      }
      geometry Capsule {
        height 0.1
        radius 0.05
      }
    }
  ]
  boundingObject USE TEST_SHAPE
  physics Physics {
  }
  linearVelocity 0 -9.337405245946841e-06 0
}
