#VRML_SIM R2020a utf8
WorldInfo {
}
Viewpoint {
  orientation -0.5114971879628789 -0.722867117295571 -0.4645791185996832 1.5528602423989453
  position -1.781366003482807 6.7824734725724 1.4747056755282517
  follow "Hexabot"
  followType "None"
}
Background {
  skyColor [
    0.15 0.45 1
  ]
}
Robot {
  translation 1.51053 0.0842616 0.529916
  rotation 0.1909004653916892 0.8878581220518571 0.4186465901208157 0.3059408563898958
  children [
    Display {
      name "Path_Display"
    }
    Display {
      name "Lidar_Display"
    }
    HokuyoUtm30lx {
      translation 0 0.1 0
      rotation 0 1 0 -1.5708
    }
    Compass {
      name "Hexabot_Compass"
    }
    Gyro {
      name "Hexabot_Gyro"
    }
    GPS {
      name "Hexabot_GPS"
    }
    Camera {
      translation 0.1 -1.12008e-13 -1.49482e-07
      rotation 8.684229999951365e-07 -0.9999999999943995 3.2321499999818985e-06 1.5707853071795865
      children [
        DEF CAM_SHAPE Shape {
          appearance MattePaint {
            baseColor 0.7 0.1 0.1
          }
          geometry Cylinder {
            height 0.05
            radius 0.0125
          }
        }
      ]
      name "Hexabot_Camera"
      boundingObject USE CAM_SHAPE
      physics Physics {
      }
      lens Lens {
      }
      focus Focus {
      }
      recognition Recognition {
      }
    }
    DEF BODY_TRAN Transform {
      children [
        DEF BODY Shape {
          appearance MattePaint {
            baseColor 0.1 0.1 0.7
          }
          geometry Box {
            size 0.2 0.05 0.125
          }
        }
      ]
    }
    Hinge2Joint {
      jointParameters HingeJointParameters {
        position -0.1889992861947664
      }
      jointParameters2 JointParameters {
        position -0.19666782077794176
        axis 0 1 0
      }
      device [
        DEF SHOULDER_2_x RotationalMotor {
          name "Hexabot_Leg0_Motor1"
        }
      ]
      device2 [
        DEF SHOULDER_0_y RotationalMotor {
          name "Hexabot_Leg0_Motor2"
        }
      ]
      endPoint DEF SHOULDER_0 Solid {
        translation 0.0804965959269466 -0.0030604996386819202 0.047494068114189006
        rotation 0.9857235437654975 0.011945223530305428 -0.16794763142479946 1.889393633995709
        children [
          Transform {
            children [
              DEF FEMUR_0 Solid {
                translation 0 0.025981 -0.0450019
                rotation 1 0 0 0.523599
                children [
                  HingeJoint {
                    jointParameters HingeJointParameters {
                      position -0.3491162644705206
                      axis 0 0 1
                    }
                    device [
                      DEF ELBOW_0 RotationalMotor {
                        name "Hexabot_Leg0_Motor3"
                      }
                    ]
                    endPoint Solid {
                      translation -0.0002176510609501726 -0.0007024846371531113 -0.05856390241636143
                      rotation -0.7362966780569563 -0.6590350968000446 -0.15342732177825072 2.835583660687505
                      children [
                        Transform {
                          children [
                            Solid {
                              translation 0.0824507 0 0.0210637
                              rotation 0 -1 0 1.8325953071795864
                              children [
                                Shape {
                                  appearance MattePaint {
                                    baseColor 0.1 0.1 0.6
                                  }
                                  geometry DEF TIBIA_SHAPE Box {
                                    size 0.025 0.025 0.15
                                  }
                                }
                              ]
                              boundingObject USE TIBIA_SHAPE
                              physics Physics {
                              }
                            }
                            DEF ELBOW_SHAPE Shape {
                              appearance MattePaint {
                                baseColor 0 0 0
                              }
                              geometry Cylinder {
                                height 0.025
                                radius 0.0125
                              }
                            }
                          ]
                        }
                      ]
                      boundingObject USE ELBOW_SHAPE
                      physics Physics {
                      }
                    }
                  }
                  DEF FEMUR_SHAPE Shape {
                    appearance MattePaint {
                      baseColor 0.2 0.2 1
                    }
                    geometry Box {
                      size 0.025 0.025 0.1
                    }
                  }
                ]
                boundingObject USE FEMUR_SHAPE
                physics Physics {
                }
              }
              Shape {
                appearance MattePaint {
                  baseColor 0 0 0
                }
                geometry DEF SHOULDER_SHAPE Sphere {
                  radius 0.02
                }
              }
            ]
          }
        ]
        name "solid(5)"
        boundingObject USE SHOULDER_SHAPE
        physics Physics {
        }
      }
    }
    Hinge2Joint {
      jointParameters HingeJointParameters {
        position 0.589161502102922
      }
      jointParameters2 JointParameters {
        position -0.20324524820086104
        axis 0 1 0
      }
      device [
        DEF SHOULDER_2_x RotationalMotor {
          name "Hexabot_Leg1_Motor1"
        }
      ]
      device2 [
        DEF SHOULDER_0_y RotationalMotor {
          name "Hexabot_Leg1_Motor2"
        }
      ]
      endPoint DEF SHOULDER_0 Solid {
        translation -0.0011893239627858467 -0.024628091772914532 0.05452347051462714
        rotation 0.996826366219461 0.029820543875828862 -0.07381009939469632 1.8720531300281404
        children [
          Transform {
            children [
              DEF FEMUR_0 Solid {
                translation 0 0.025981 -0.0450019
                rotation 1 0 0 0.523599
                children [
                  HingeJoint {
                    jointParameters HingeJointParameters {
                      position -0.25084706474493623
                      axis 0 0 1
                    }
                    device [
                      DEF ELBOW_0 RotationalMotor {
                        name "Hexabot_Leg1_Motor3"
                      }
                    ]
                    endPoint Solid {
                      translation -0.00015102245692270505 -0.0006086293270575108 -0.05861795080600464
                      rotation -0.703862301210338 -0.6952328691728801 -0.14570215700713723 2.820688480780739
                      children [
                        Transform {
                          children [
                            Solid {
                              translation 0.0824507 0 0.0210637
                              rotation 0 -1 0 1.8325953071795864
                              children [
                                Shape {
                                  appearance MattePaint {
                                    baseColor 0.1 0.1 0.6
                                  }
                                  geometry DEF TIBIA_SHAPE Box {
                                    size 0.025 0.025 0.15
                                  }
                                }
                              ]
                              boundingObject USE TIBIA_SHAPE
                              physics Physics {
                              }
                            }
                            DEF ELBOW_SHAPE Shape {
                              appearance MattePaint {
                                baseColor 0 0 0
                              }
                              geometry Cylinder {
                                height 0.025
                                radius 0.0125
                              }
                            }
                          ]
                        }
                      ]
                      boundingObject USE ELBOW_SHAPE
                      physics Physics {
                      }
                    }
                  }
                  DEF FEMUR_SHAPE Shape {
                    appearance MattePaint {
                      baseColor 0.2 0.2 1
                    }
                    geometry Box {
                      size 0.025 0.025 0.1
                    }
                  }
                ]
                boundingObject USE FEMUR_SHAPE
                physics Physics {
                }
              }
              Shape {
                appearance MattePaint {
                  baseColor 0 0 0
                }
                geometry DEF SHOULDER_SHAPE Sphere {
                  radius 0.02
                }
              }
            ]
          }
        ]
        name "solid(4)"
        boundingObject USE SHOULDER_SHAPE
        physics Physics {
        }
      }
    }
    Hinge2Joint {
      jointParameters HingeJointParameters {
        position 1.0106932729042444
      }
      jointParameters2 JointParameters {
        position -0.19682945538123398
        axis 0 1 0
      }
      device [
        DEF SHOULDER_2_x RotationalMotor {
          name "Hexabot_Leg2_Motor1"
        }
      ]
      device2 [
        DEF SHOULDER_0_y RotationalMotor {
          name "Hexabot_Leg2_Motor2"
        }
      ]
      endPoint DEF SHOULDER_0 Solid {
        translation -0.08760332389475789 0.007880871391321119 0.05049984278486852
        rotation 0.994913325171007 -0.04556288321053203 -0.08984152197460782 2.09212974308068
        children [
          Transform {
            children [
              DEF FEMUR_0 Solid {
                translation 0 0.025981 -0.0450019
                rotation 1 0 0 0.523599
                children [
                  HingeJoint {
                    jointParameters HingeJointParameters {
                      position -0.34912128006189774
                      axis 0 0 1
                    }
                    device [
                      DEF ELBOW_0 RotationalMotor {
                        name "Hexabot_Leg2_Motor3"
                      }
                    ]
                    endPoint Solid {
                      translation -0.00021494519839663253 -0.000666562579870192 -0.05857588456507857
                      rotation -0.7428597245937394 -0.667146126605545 -0.055456968288321425 3.009236410063246
                      children [
                        Transform {
                          children [
                            Solid {
                              translation 0.0824507 0 0.0210637
                              rotation 0 -1 0 1.8325953071795864
                              children [
                                Shape {
                                  appearance MattePaint {
                                    baseColor 0.1 0.1 0.6
                                  }
                                  geometry DEF TIBIA_SHAPE Box {
                                    size 0.025 0.025 0.15
                                  }
                                }
                              ]
                              boundingObject USE TIBIA_SHAPE
                              physics Physics {
                              }
                            }
                            DEF ELBOW_SHAPE Shape {
                              appearance MattePaint {
                                baseColor 0 0 0
                              }
                              geometry Cylinder {
                                height 0.025
                                radius 0.0125
                              }
                            }
                          ]
                        }
                      ]
                      boundingObject USE ELBOW_SHAPE
                      physics Physics {
                      }
                    }
                  }
                  DEF FEMUR_SHAPE Shape {
                    appearance MattePaint {
                      baseColor 0.2 0.2 1
                    }
                    geometry Box {
                      size 0.025 0.025 0.1
                    }
                  }
                ]
                boundingObject USE FEMUR_SHAPE
                physics Physics {
                }
              }
              Shape {
                appearance MattePaint {
                  baseColor 0 0 0
                }
                geometry DEF SHOULDER_SHAPE Sphere {
                  radius 0.02
                }
              }
            ]
          }
        ]
        name "solid(3)"
        boundingObject USE SHOULDER_SHAPE
        physics Physics {
        }
      }
    }
    Hinge2Joint {
      jointParameters HingeJointParameters {
        position -0.07475175902577069
      }
      jointParameters2 JointParameters {
        position -0.24405985409940456
        axis 0 1 0
      }
      device [
        DEF SHOULDER_3_x RotationalMotor {
          name "Hexabot_Leg3_Motor1"
        }
      ]
      device2 [
        DEF SHOULDER_3_y RotationalMotor {
          name "Hexabot_Leg3_Motor2"
        }
      ]
      endPoint DEF SHOULDER_0 Solid {
        translation -0.08702129052212623 0.006798545253237952 -0.04362997770125865
        rotation -0.9729649283792982 0.23083890386544545 -0.00725593591942531 0.07682904224590226
        children [
          Transform {
            translation 0 0 -0.01
            children [
              DEF FEMUR_0 Solid {
                translation 0 0.0259808 -0.045
                rotation 1 0 0 0.523599
                children [
                  HingeJoint {
                    jointParameters HingeJointParameters {
                      position -0.2575531733335056
                      axis 0 0 1
                    }
                    device [
                      DEF ELBOW_3 RotationalMotor {
                        name "Hexabot_Leg3_Motor3"
                      }
                    ]
                    endPoint Solid {
                      translation -9.655788798126683e-06 -2.3236861571174202e-05 -0.06002055998798635
                      rotation 3.9379622619503606e-05 5.3269386982932686e-05 -0.999999997805809 1.5665515661973757
                      children [
                        Transform {
                          children [
                            Solid {
                              translation 0.0824507 0 0.0210637
                              rotation 0 -1 0 1.8325953071795864
                              children [
                                Shape {
                                  appearance MattePaint {
                                    baseColor 0.1 0.1 0.6
                                  }
                                  geometry DEF TIBIA_SHAPE Box {
                                    size 0.025 0.025 0.15
                                  }
                                }
                              ]
                              boundingObject USE TIBIA_SHAPE
                              physics Physics {
                              }
                            }
                            DEF ELBOW_SHAPE Shape {
                              appearance MattePaint {
                                baseColor 0 0 0
                              }
                              geometry Cylinder {
                                height 0.025
                                radius 0.0125
                              }
                            }
                          ]
                        }
                      ]
                      boundingObject USE ELBOW_SHAPE
                      physics Physics {
                      }
                    }
                  }
                  DEF FEMUR_SHAPE Shape {
                    appearance MattePaint {
                      baseColor 0.2 0.2 1
                    }
                    geometry Box {
                      size 0.025 0.025 0.1
                    }
                  }
                ]
                boundingObject USE FEMUR_SHAPE
                physics Physics {
                }
              }
              Shape {
                appearance MattePaint {
                  baseColor 0 0 0
                }
                geometry DEF SHOULDER_SHAPE Sphere {
                  radius 0.02
                }
              }
            ]
          }
        ]
        name "solid(2)"
        boundingObject USE SHOULDER_SHAPE
        physics Physics {
        }
      }
    }
    Hinge2Joint {
      jointParameters HingeJointParameters {
        position -0.02519941278824092
      }
      jointParameters2 JointParameters {
        position -0.15601065116411625
        axis 0 1 0
      }
      device [
        DEF SHOULDER_4_x RotationalMotor {
          name "Hexabot_Leg4_Motor1"
        }
      ]
      device2 [
        DEF SHOULDER_4_y RotationalMotor {
          name "Hexabot_Leg4_Motor2"
        }
      ]
      endPoint DEF SHOULDER_0 Solid {
        translation -0.01198430430268205 -0.001314025536817867 -0.052501990883669795
        rotation -0.1591374990053931 -0.9871780651766353 0.012438812018162665 0.15802862135755644
        children [
          Transform {
            translation 0 0 -0.01
            children [
              DEF FEMUR_0 Solid {
                translation 0 0.0259808 -0.045
                rotation 1 0 0 0.523599
                children [
                  HingeJoint {
                    jointParameters HingeJointParameters {
                      position 0.05768881133268522
                      axis 0 0 1
                    }
                    device [
                      DEF ELBOW_4 RotationalMotor {
                        name "Hexabot_Leg4_Motor3"
                      }
                    ]
                    endPoint Solid {
                      translation -1.4302196246260056e-12 2.4764467315159578e-11 -0.05999999999999914
                      rotation 2.0671466158608884e-10 2.1899725831293881e-10 -1 1.5131064958467237
                      children [
                        Transform {
                          children [
                            Solid {
                              translation 0.0824507 0 0.0210637
                              rotation 0 -1 0 1.8325953071795864
                              children [
                                Shape {
                                  appearance MattePaint {
                                    baseColor 0.1 0.1 0.6
                                  }
                                  geometry DEF TIBIA_SHAPE Box {
                                    size 0.025 0.025 0.15
                                  }
                                }
                              ]
                              boundingObject USE TIBIA_SHAPE
                              physics Physics {
                              }
                            }
                            DEF ELBOW_SHAPE Shape {
                              appearance MattePaint {
                                baseColor 0 0 0
                              }
                              geometry Cylinder {
                                height 0.025
                                radius 0.0125
                              }
                            }
                          ]
                        }
                      ]
                      boundingObject USE ELBOW_SHAPE
                      physics Physics {
                      }
                    }
                  }
                  DEF FEMUR_SHAPE Shape {
                    appearance MattePaint {
                      baseColor 0.2 0.2 1
                    }
                    geometry Box {
                      size 0.025 0.025 0.1
                    }
                  }
                ]
                boundingObject USE FEMUR_SHAPE
                physics Physics {
                }
              }
              Shape {
                appearance MattePaint {
                  baseColor 0 0 0
                }
                geometry DEF SHOULDER_SHAPE Sphere {
                  radius 0.02
                }
              }
            ]
          }
        ]
        name "solid(1)"
        boundingObject USE SHOULDER_SHAPE
        physics Physics {
        }
      }
    }
    Hinge2Joint {
      jointParameters HingeJointParameters {
        position 0.025216178017430174
      }
      jointParameters2 JointParameters {
        position -0.24410598755442905
        axis 0 1 0
      }
      device [
        DEF SHOULDER_5_x RotationalMotor {
          name "Hexabot_Leg5_Motor1"
        }
      ]
      device2 [
        DEF SHOULDER_5_y RotationalMotor {
          name "Hexabot_Leg5_Motor2"
        }
      ]
      endPoint DEF SHOULDER_0 Solid {
        translation 0.09212962422065699 0.0009929831404942775 -0.03887339733865694
        rotation 0.10224526781000574 -0.994680155356845 -0.012541680499168043 0.24539850893431264
        children [
          Transform {
            translation 0 0 -0.01
            children [
              DEF FEMUR_0 Solid {
                translation 0 0.0259808 -0.045
                rotation 1 0 0 0.523599
                children [
                  HingeJoint {
                    jointParameters HingeJointParameters {
                      position 0.1424381763118376
                      axis 0 0 1
                    }
                    device [
                      DEF ELBOW_5 RotationalMotor {
                        name "Hexabot_Leg5_Motor3"
                      }
                    ]
                    endPoint Solid {
                      translation 2.2545425982129635e-23 -1.5721029268190736e-22 -0.06000000000000008
                      rotation -1.2300536784062237e-20 -4.766935219955969e-21 -1 1.4283571308676677
                      children [
                        Transform {
                          children [
                            Solid {
                              translation 0.0824507 0 0.0210637
                              rotation 0 -1 0 1.8325953071795864
                              children [
                                Shape {
                                  appearance MattePaint {
                                    baseColor 0.1 0.1 0.6
                                  }
                                  geometry DEF TIBIA_SHAPE Box {
                                    size 0.025 0.025 0.15
                                  }
                                }
                              ]
                              boundingObject USE TIBIA_SHAPE
                              physics Physics {
                              }
                            }
                            DEF ELBOW_SHAPE Shape {
                              appearance MattePaint {
                                baseColor 0 0 0
                              }
                              geometry Cylinder {
                                height 0.025
                                radius 0.0125
                              }
                            }
                          ]
                        }
                      ]
                      boundingObject USE ELBOW_SHAPE
                      physics Physics {
                      }
                      recognitionColors [
                        0 0 0
                      ]
                    }
                  }
                  DEF FEMUR_SHAPE Shape {
                    appearance MattePaint {
                      baseColor 0.2 0.2 1
                    }
                    geometry Box {
                      size 0.025 0.025 0.1
                    }
                  }
                ]
                boundingObject USE FEMUR_SHAPE
                physics Physics {
                }
              }
              Shape {
                appearance MattePaint {
                  baseColor 0 0 0
                }
                geometry DEF SHOULDER_SHAPE Sphere {
                  radius 0.02
                }
              }
            ]
          }
        ]
        boundingObject USE SHOULDER_SHAPE
        physics Physics {
        }
      }
    }
  ]
  name "Hexabot"
  boundingObject USE BODY_TRAN
  physics Physics {
  }
  controller "my_controller_c"
}
RectangleArena {
  translation 0 -0.05 0
  floorSize 9.5 9.5
  wallThickness 0.1
  wallHeight 1
}
Group {
  children [
    Wall {
      translation 0 -0.05 -3.92
      name "wall(1)"
      size 5 1 0.2
    }
    Wall {
      translation 2.6 -0.05 -1.52
      rotation 0 1 0 -1.5707953071795862
      name "wall(2)"
      size 5 1 0.2
    }
    Wall {
      translation -0.37 -0.05 -1.44
      rotation 0 1 0 -1.5707953071795862
      name "wall(21)"
      size 5 1 0.2
    }
    Wall {
      translation 3.26 -0.05 -3.91
      rotation 0 1 0 1.01503e-06
      name "wall(3)"
      size 1.5 1 0.2
    }
    Wall {
      translation 4.25 -0.05 -2.9
      rotation 0 1 0 1.01503e-06
      name "wall(4)"
      size 1.5 1 0.2
    }
    Wall {
      translation 3.29 -0.05 -1.47
      rotation 0 1 0 1.01503e-06
      name "wall(5)"
      size 1.5 1 0.2
    }
    Wall {
      translation -1.16 -0.05 -1.47
      rotation 0 1 0 1.01503e-06
      name "wall(10)"
      size 1.5 1 0.2
    }
    Wall {
      translation -1.97 -0.05 -0.82
      rotation 0 1 0 -1.5707953071795862
      name "wall(22)"
      size 1.5 1 0.2
    }
    Wall {
      translation -2.62 -0.05 0.0300007
      rotation 0 1 0 1.01503e-06
      name "wall(23)"
      size 1.5 1 0.2
    }
    Wall {
      translation -3.41 -0.05 -0.629998
      rotation 0 1 0 -1.5707953071795862
      name "wall(24)"
      size 1.5 1 0.2
    }
    Wall {
      translation -4.25 -0.05 -1.28
      rotation 0 1 0 3.14159
      name "wall(25)"
      size 1.5 1 0.2
    }
    Wall {
      translation 4.25 -0.05 -0.05
      rotation 0 1 0 1.01503e-06
      name "wall(6)"
      size 1.5 1 0.2
    }
    Wall {
      translation 1.95 -0.05 1.09
      rotation 0 1 0 1.01503e-06
      name "wall(7)"
      size 1.5 1 0.2
    }
    Wall {
      translation 1.95 -0.05 2.42
      rotation 0 1 0 1.01503e-06
      name "wall(8)"
      size 1.5 1 0.2
    }
    Wall {
      translation 0.45 -0.05 2.42
      rotation 0 1 0 1.01503e-06
      name "wall(9)"
      size 1.5 1 0.2
    }
    Wall {
      translation 0.9 -0.05 3.24
      rotation 0 1 0 1.5708
      name "wall(11)"
      size 1.5 1 0.2
    }
    Wall {
      translation 0.9 -0.05 4.27
      rotation 0 1 0 1.5708
      name "wall(12)"
      size 1.5 1 0.2
    }
    Wall {
      translation 1.74 -0.05 3.62
      rotation 0 1 0 -3.1415853071795863
      name "wall(13)"
      size 1.5 1 0.2
    }
    Wall {
      translation 3.2 -0.05 3.62
      rotation 0 1 0 -3.1415853071795863
      name "wall(14)"
      size 1.5 1 0.2
    }
    Wall {
      translation 4.04 -0.05 2.96
      rotation 0 1 0 1.5708
      name "wall(15)"
      size 1.5 1 0.2
    }
    Wall {
      translation 4.04 -0.05 2.04
      rotation 0 1 0 1.5708
      name "wall(16)"
      size 1.5 1 0.2
    }
    Wall {
      translation -1.23 -0.05 2.42
      rotation 0 1 0 1.01503e-06
      name "wall(17)"
      size 1.5 1 0.2
    }
    Wall {
      translation -0.71 -0.05 2.42
      rotation 0 1 0 1.01503e-06
      name "wall(27)"
      size 1.5 1 0.2
    }
    Wall {
      translation -2.72 -0.05 2.42
      rotation 0 1 0 1.01503e-06
      name "wall(26)"
      size 1.5 1 0.2
    }
    Wall {
      translation -1.23 -0.05 3.9
      rotation 0 1 0 1.01503e-06
      name "wall(20)"
      size 1.5 1 0.2
    }
    Wall {
      translation -1.87 -0.05 3.25
      rotation 0 1 0 -1.5707953071795862
      name "wall(18)"
      size 1.5 1 0.2
    }
    Wall {
      translation -0.37 -0.05 3.25
      rotation 0 1 0 -1.5707953071795862
      name "wall(19)"
      size 1.5 1 0.2
    }
  ]
}
OilBarrel {
  translation 0.661819 0.44 1.60636
  rotation 0 -1 0 -5.307179586466759e-06
}
