#VRML_SIM R2020a utf8
WorldInfo {
}
Viewpoint {
  orientation -0.09785580600822345 -0.9654518932822679 -0.24150959191751664 1.912632134028394
  position -4.954138340376447 1.7438372478717412 1.2660125884217421
  follow "Hexabot"
  followType "None"
}
Background {
  skyColor [
    0.15 0.45 1
  ]
}
Robot {
  translation -2.096754517518388 0.050935900027616776 2.0464316069525395
  rotation -0.2198701235595171 0.5096783663301782 0.8317963041880646 -0.04152200039481807
  children [
    Display {
      name "Path_Display"
    }
    Display {
      name "Lidar_Display"
    }
    HokuyoUtm30lx {
      translation 0 0.1 0
      rotation 0 1 0 -1.5708
    }
    Compass {
      name "Hexabot_Compass"
    }
    Gyro {
      name "Hexabot_Gyro"
    }
    GPS {
      name "Hexabot_GPS"
    }
    Camera {
      translation 0.1 -1.12008e-13 -1.49482e-07
      rotation 8.684229999951365e-07 -0.9999999999943995 3.2321499999818985e-06 1.5707853071795865
      children [
        DEF CAM_SHAPE Shape {
          appearance MattePaint {
            baseColor 0.7 0.1 0.1
          }
          geometry Cylinder {
            height 0.05
            radius 0.0125
          }
        }
      ]
      name "Hexabot_Camera"
      boundingObject USE CAM_SHAPE
      physics Physics {
      }
      lens Lens {
      }
      focus Focus {
      }
      recognition Recognition {
      }
    }
    DEF BODY_TRAN Transform {
      children [
        DEF BODY Shape {
          appearance MattePaint {
            baseColor 0.1 0.1 0.7
          }
          geometry Box {
            size 0.2 0.05 0.125
          }
        }
      ]
    }
    Hinge2Joint {
      jointParameters HingeJointParameters {
        position -0.09095010330543159
      }
      jointParameters2 JointParameters {
        position -0.11612325371425379
        axis 0 1 0
      }
      device [
        DEF SHOULDER_2_x RotationalMotor {
          name "Hexabot_Leg0_Motor1"
        }
      ]
      device2 [
        DEF SHOULDER_0_y RotationalMotor {
          name "Hexabot_Leg0_Motor2"
        }
      ]
      endPoint DEF SHOULDER_0 Solid {
        translation 0.08394257476727449 -0.008296894852144023 0.04036781883075534
        rotation 0.9782251636932069 0.04196699587581375 -0.2032591950553726 1.9898909582867825
        children [
          Transform {
            children [
              DEF FEMUR_0 Solid {
                translation 0 0.025981 -0.0450019
                rotation 1 0 0 0.523599
                children [
                  HingeJoint {
                    jointParameters HingeJointParameters {
                      position -0.3504307580520595
                      axis 0 0 1
                    }
                    device [
                      DEF ELBOW_0 RotationalMotor {
                        name "Hexabot_Leg0_Motor3"
                      }
                    ]
                    endPoint Solid {
                      translation -0.00021857428419202823 -0.000702197929403682 -0.05856390241636156
                      rotation -0.7367182114510609 -0.658540785305107 -0.15352625510342927 2.8357854049484224
                      children [
                        Transform {
                          children [
                            Solid {
                              translation 0.0824507 0 0.0210637
                              rotation 0 -1 0 1.8325953071795864
                              children [
                                Shape {
                                  appearance MattePaint {
                                    baseColor 0.1 0.1 0.6
                                  }
                                  geometry DEF TIBIA_SHAPE Box {
                                    size 0.025 0.025 0.15
                                  }
                                }
                              ]
                              boundingObject USE TIBIA_SHAPE
                              physics Physics {
                              }
                            }
                            DEF ELBOW_SHAPE Shape {
                              appearance MattePaint {
                                baseColor 0 0 0
                              }
                              geometry Cylinder {
                                height 0.025
                                radius 0.0125
                              }
                            }
                          ]
                        }
                      ]
                      boundingObject USE ELBOW_SHAPE
                      physics Physics {
                      }
                      linearVelocity 0.00944141014306249 -0.006452237054872325 -0.03015744810292925
                      angularVelocity -0.057780899297518076 0.040327533052910244 -0.19907564428212127
                    }
                  }
                  DEF FEMUR_SHAPE Shape {
                    appearance MattePaint {
                      baseColor 0.2 0.2 1
                    }
                    geometry Box {
                      size 0.025 0.025 0.1
                    }
                  }
                ]
                boundingObject USE FEMUR_SHAPE
                physics Physics {
                }
              }
              Shape {
                appearance MattePaint {
                  baseColor 0 0 0
                }
                geometry DEF SHOULDER_SHAPE Sphere {
                  radius 0.02
                }
              }
            ]
          }
        ]
        name "solid(5)"
        boundingObject USE SHOULDER_SHAPE
        physics Physics {
        }
        linearVelocity 0.010842939023335342 -0.005102089426439399 -0.030252325171520444
        angularVelocity 0.02536645494975814 0.18206627490810054 -0.009072069614475615
      }
    }
    Hinge2Joint {
      jointParameters HingeJointParameters {
        position 0.49092791617814147
      }
      jointParameters2 JointParameters {
        position -0.2839397878724835
        axis 0 1 0
      }
      device [
        DEF SHOULDER_2_x RotationalMotor {
          name "Hexabot_Leg1_Motor1"
        }
      ]
      device2 [
        DEF SHOULDER_0_y RotationalMotor {
          name "Hexabot_Leg1_Motor2"
        }
      ]
      endPoint DEF SHOULDER_0 Solid {
        translation -0.005942567067553455 -0.019026199831621605 0.056422121986307944
        rotation 0.9980994995285827 -0.020766690145232504 -0.05801839037067956 1.77650531750366
        children [
          Transform {
            children [
              DEF FEMUR_0 Solid {
                translation 0 0.025981 -0.0450019
                rotation 1 0 0 0.523599
                children [
                  HingeJoint {
                    jointParameters HingeJointParameters {
                      position -0.24956773659264134
                      axis 0 0 1
                    }
                    device [
                      DEF ELBOW_0 RotationalMotor {
                        name "Hexabot_Leg1_Motor3"
                      }
                    ]
                    endPoint Solid {
                      translation -0.00015024369691494504 -0.0006088220362197636 -0.05861795080600472
                      rotation -0.703428051530826 -0.6956934554567519 -0.14560079791742256 2.8205021447384904
                      children [
                        Transform {
                          children [
                            Solid {
                              translation 0.0824507 0 0.0210637
                              rotation 0 -1 0 1.8325953071795864
                              children [
                                Shape {
                                  appearance MattePaint {
                                    baseColor 0.1 0.1 0.6
                                  }
                                  geometry DEF TIBIA_SHAPE Box {
                                    size 0.025 0.025 0.15
                                  }
                                }
                              ]
                              boundingObject USE TIBIA_SHAPE
                              physics Physics {
                              }
                            }
                            DEF ELBOW_SHAPE Shape {
                              appearance MattePaint {
                                baseColor 0 0 0
                              }
                              geometry Cylinder {
                                height 0.025
                                radius 0.0125
                              }
                            }
                          ]
                        }
                      ]
                      boundingObject USE ELBOW_SHAPE
                      physics Physics {
                      }
                      linearVelocity 0.09769893084501739 0.09602847349176116 -0.012317160565211835
                      angularVelocity -0.5497770309142125 0.6430834354766637 0.20179633098593938
                    }
                  }
                  DEF FEMUR_SHAPE Shape {
                    appearance MattePaint {
                      baseColor 0.2 0.2 1
                    }
                    geometry Box {
                      size 0.025 0.025 0.1
                    }
                  }
                ]
                boundingObject USE FEMUR_SHAPE
                physics Physics {
                }
              }
              Shape {
                appearance MattePaint {
                  baseColor 0 0 0
                }
                geometry DEF SHOULDER_SHAPE Sphere {
                  radius 0.02
                }
              }
            ]
          }
        ]
        name "solid(4)"
        boundingObject USE SHOULDER_SHAPE
        physics Physics {
        }
        linearVelocity 0.03464820426343106 0.04257293994235556 -0.01359343132735482
        angularVelocity -0.5743534713321383 0.46106603563348636 0.030395000214593654
      }
    }
    Hinge2Joint {
      jointParameters HingeJointParameters {
        position 1.1090865893761128
      }
      jointParameters2 JointParameters {
        position -0.11601949969507322
        axis 0 1 0
      }
      device [
        DEF SHOULDER_2_x RotationalMotor {
          name "Hexabot_Leg2_Motor1"
        }
      ]
      device2 [
        DEF SHOULDER_0_y RotationalMotor {
          name "Hexabot_Leg2_Motor2"
        }
      ]
      endPoint DEF SHOULDER_0 Solid {
        translation -0.08569068883622617 -0.003390275849650206 0.054150683181555026
        rotation 0.9960257432681768 0.005299906143387492 -0.08890798469174326 2.1829542396354125
        children [
          Transform {
            children [
              DEF FEMUR_0 Solid {
                translation 0 0.025981 -0.0450019
                rotation 1 0 0 0.523599
                children [
                  HingeJoint {
                    jointParameters HingeJointParameters {
                      position -0.35043214251424376
                      axis 0 0 1
                    }
                    device [
                      DEF ELBOW_0 RotationalMotor {
                        name "Hexabot_Leg2_Motor3"
                      }
                    ]
                    endPoint Solid {
                      translation -0.00021581878532785212 -0.0006662802436637186 -0.05857588456507859
                      rotation -0.7432950426166904 -0.6666574837329935 -0.05550026129889749 3.009309134898917
                      children [
                        Transform {
                          children [
                            Solid {
                              translation 0.0824507 0 0.0210637
                              rotation 0 -1 0 1.8325953071795864
                              children [
                                Shape {
                                  appearance MattePaint {
                                    baseColor 0.1 0.1 0.6
                                  }
                                  geometry DEF TIBIA_SHAPE Box {
                                    size 0.025 0.025 0.15
                                  }
                                }
                              ]
                              boundingObject USE TIBIA_SHAPE
                              physics Physics {
                              }
                            }
                            DEF ELBOW_SHAPE Shape {
                              appearance MattePaint {
                                baseColor 0 0 0
                              }
                              geometry Cylinder {
                                height 0.025
                                radius 0.0125
                              }
                            }
                          ]
                        }
                      ]
                      boundingObject USE ELBOW_SHAPE
                      physics Physics {
                      }
                      linearVelocity 0.025200475568315957 0.0009068976970757572 0.005721608488969689
                      angularVelocity -0.004465752097268103 0.15685944920531206 -0.3715321459256562
                    }
                  }
                  DEF FEMUR_SHAPE Shape {
                    appearance MattePaint {
                      baseColor 0.2 0.2 1
                    }
                    geometry Box {
                      size 0.025 0.025 0.1
                    }
                  }
                ]
                boundingObject USE FEMUR_SHAPE
                physics Physics {
                }
              }
              Shape {
                appearance MattePaint {
                  baseColor 0 0 0
                }
                geometry DEF SHOULDER_SHAPE Sphere {
                  radius 0.02
                }
              }
            ]
          }
        ]
        name "solid(3)"
        boundingObject USE SHOULDER_SHAPE
        physics Physics {
        }
        linearVelocity 0.02155326710476947 0.006806589313597916 0.008333595655819197
        angularVelocity 0.031995281054658334 0.2590958952111886 -0.1449845741113322
      }
    }
    Hinge2Joint {
      jointParameters HingeJointParameters {
        position -0.09095008922982882
      }
      jointParameters2 JointParameters {
        position -0.11612262806892878
        axis 0 1 0
      }
      device [
        DEF SHOULDER_3_x RotationalMotor {
          name "Hexabot_Leg3_Motor1"
        }
      ]
      device2 [
        DEF SHOULDER_3_y RotationalMotor {
          name "Hexabot_Leg3_Motor2"
        }
      ]
      endPoint DEF SHOULDER_0 Solid {
        translation -0.09179643935525844 0.007131289983731524 -0.03232736612799136
        rotation -0.5287639393094105 0.8479192159607347 -0.03796972070646314 0.1716920236289029
        children [
          Transform {
            translation 0 0 -0.01
            children [
              DEF FEMUR_0 Solid {
                translation 0 0.0259808 -0.045
                rotation 1 0 0 0.523599
                children [
                  HingeJoint {
                    jointParameters HingeJointParameters {
                      position -0.35043128526473655
                      axis 0 0 1
                    }
                    device [
                      DEF ELBOW_3 RotationalMotor {
                        name "Hexabot_Leg3_Motor3"
                      }
                    ]
                    endPoint Solid {
                      translation -1.1769265929869554e-05 -2.2241186399649506e-05 -0.060020559987986395
                      rotation 3.9988894697740466e-05 4.914568225169574e-05 -0.9999999979927949 1.6594296779337625
                      children [
                        Transform {
                          children [
                            Solid {
                              translation 0.0824507 0 0.0210637
                              rotation 0 -1 0 1.8325953071795864
                              children [
                                Shape {
                                  appearance MattePaint {
                                    baseColor 0.1 0.1 0.6
                                  }
                                  geometry DEF TIBIA_SHAPE Box {
                                    size 0.025 0.025 0.15
                                  }
                                }
                              ]
                              boundingObject USE TIBIA_SHAPE
                              physics Physics {
                              }
                            }
                            DEF ELBOW_SHAPE Shape {
                              appearance MattePaint {
                                baseColor 0 0 0
                              }
                              geometry Cylinder {
                                height 0.025
                                radius 0.0125
                              }
                            }
                          ]
                        }
                      ]
                      boundingObject USE ELBOW_SHAPE
                      physics Physics {
                      }
                      linearVelocity -0.01259587130427084 0.00010871682637898978 0.004129635717284956
                      angularVelocity 0.04745383406596696 0.07367724809096868 0.2164679677273462
                    }
                  }
                  DEF FEMUR_SHAPE Shape {
                    appearance MattePaint {
                      baseColor 0.2 0.2 1
                    }
                    geometry Box {
                      size 0.025 0.025 0.1
                    }
                  }
                ]
                boundingObject USE FEMUR_SHAPE
                physics Physics {
                }
              }
              Shape {
                appearance MattePaint {
                  baseColor 0 0 0
                }
                geometry DEF SHOULDER_SHAPE Sphere {
                  radius 0.02
                }
              }
            ]
          }
        ]
        name "solid(2)"
        boundingObject USE SHOULDER_SHAPE
        physics Physics {
        }
        linearVelocity -0.014351013121118457 0.00012855527354746488 0.004495300907950737
        angularVelocity 0.025365873637003388 0.18206731673816556 -0.009071595570029876
      }
    }
    Hinge2Joint {
      jointParameters HingeJointParameters {
        position -0.009054144373873751
      }
      jointParameters2 JointParameters {
        position -0.28388717456701906
        axis 0 1 0
      }
      device [
        DEF SHOULDER_4_x RotationalMotor {
          name "Hexabot_Leg4_Motor1"
        }
      ]
      device2 [
        DEF SHOULDER_4_y RotationalMotor {
          name "Hexabot_Leg4_Motor2"
        }
      ]
      endPoint DEF SHOULDER_0 Solid {
        translation -0.0051888657395080875 -0.00047618745731029097 -0.053615838866164334
        rotation -0.031662983971455866 -0.9994883599871662 0.004524786866611673 0.28403055137027655
        children [
          Transform {
            translation 0 0 -0.01
            children [
              DEF FEMUR_0 Solid {
                translation 0 0.0259808 -0.045
                rotation 1 0 0 0.523599
                children [
                  HingeJoint {
                    jointParameters HingeJointParameters {
                      position 0.15043173870488236
                      axis 0 0 1
                    }
                    device [
                      DEF ELBOW_4 RotationalMotor {
                        name "Hexabot_Leg4_Motor3"
                      }
                    ]
                    endPoint Solid {
                      translation -3.7175113454944005e-12 2.452558824930388e-11 -0.05999999999999913
                      rotation 2.0671468341750026e-10 2.4040880083507784e-10 -1 1.4203635684745262
                      children [
                        Transform {
                          children [
                            Solid {
                              translation 0.0824507 0 0.0210637
                              rotation 0 -1 0 1.8325953071795864
                              children [
                                Shape {
                                  appearance MattePaint {
                                    baseColor 0.1 0.1 0.6
                                  }
                                  geometry DEF TIBIA_SHAPE Box {
                                    size 0.025 0.025 0.15
                                  }
                                }
                              ]
                              boundingObject USE TIBIA_SHAPE
                              physics Physics {
                              }
                            }
                            DEF ELBOW_SHAPE Shape {
                              appearance MattePaint {
                                baseColor 0 0 0
                              }
                              geometry Cylinder {
                                height 0.025
                                radius 0.0125
                              }
                            }
                          ]
                        }
                      ]
                      boundingObject USE ELBOW_SHAPE
                      physics Physics {
                      }
                      linearVelocity -0.10085900196261542 -0.10378139478360092 -0.03397857164190049
                      angularVelocity -0.49970345218865797 0.605083671499435 -0.24064017687681777
                    }
                  }
                  DEF FEMUR_SHAPE Shape {
                    appearance MattePaint {
                      baseColor 0.2 0.2 1
                    }
                    geometry Box {
                      size 0.025 0.025 0.1
                    }
                  }
                ]
                boundingObject USE FEMUR_SHAPE
                physics Physics {
                }
              }
              Shape {
                appearance MattePaint {
                  baseColor 0 0 0
                }
                geometry DEF SHOULDER_SHAPE Sphere {
                  radius 0.02
                }
              }
            ]
          }
        ]
        name "solid(1)"
        boundingObject USE SHOULDER_SHAPE
        physics Physics {
        }
        linearVelocity -0.04288637015093798 -0.052920228345755875 -0.02750292137153756
        angularVelocity -0.571794060830246 0.47896904996624634 -0.035680769297011555
      }
    }
    Hinge2Joint {
      jointParameters HingeJointParameters {
        position 0.009054428338086618
      }
      jointParameters2 JointParameters {
        position -0.11611285952781719
        axis 0 1 0
      }
      device [
        DEF SHOULDER_5_x RotationalMotor {
          name "Hexabot_Leg5_Motor1"
        }
      ]
      device2 [
        DEF SHOULDER_5_y RotationalMotor {
          name "Hexabot_Leg5_Motor2"
        }
      ]
      endPoint DEF SHOULDER_0 Solid {
        translation 0.08641243693803659 0.0004682153541813877 -0.050325601953854854
        rotation 0.07765643244027579 -0.9969699627226807 -0.004513527377310577 0.11646495906732593
        children [
          Transform {
            translation 0 0 -0.01
            children [
              DEF FEMUR_0 Solid {
                translation 0 0.0259808 -0.045
                rotation 1 0 0 0.523599
                children [
                  HingeJoint {
                    jointParameters HingeJointParameters {
                      position 0.04956927624145257
                      axis 0 0 1
                    }
                    device [
                      DEF ELBOW_5 RotationalMotor {
                        name "Hexabot_Leg5_Motor3"
                      }
                    ]
                    endPoint Solid {
                      translation 7.869303350592763e-24 -1.5862359982872364e-22 -0.06000000000000014
                      rotation -1.1884927906979118e-20 -3.981897197758827e-21 -1 1.521226030938054
                      children [
                        Transform {
                          children [
                            Solid {
                              translation 0.0824507 0 0.0210637
                              rotation 0 -1 0 1.8325953071795864
                              children [
                                Shape {
                                  appearance MattePaint {
                                    baseColor 0.1 0.1 0.6
                                  }
                                  geometry DEF TIBIA_SHAPE Box {
                                    size 0.025 0.025 0.15
                                  }
                                }
                              ]
                              boundingObject USE TIBIA_SHAPE
                              physics Physics {
                              }
                            }
                            DEF ELBOW_SHAPE Shape {
                              appearance MattePaint {
                                baseColor 0 0 0
                              }
                              geometry Cylinder {
                                height 0.025
                                radius 0.0125
                              }
                            }
                          ]
                        }
                      ]
                      boundingObject USE ELBOW_SHAPE
                      physics Physics {
                      }
                      recognitionColors [
                        0 0 0
                      ]
                      linearVelocity -0.015502625683162154 -0.0004778137357915687 -0.030392266712495244
                      angularVelocity -0.009320684555603764 0.05321176801187032 0.19017325633119428
                    }
                  }
                  DEF FEMUR_SHAPE Shape {
                    appearance MattePaint {
                      baseColor 0.2 0.2 1
                    }
                    geometry Box {
                      size 0.025 0.025 0.1
                    }
                  }
                ]
                boundingObject USE FEMUR_SHAPE
                physics Physics {
                }
              }
              Shape {
                appearance MattePaint {
                  baseColor 0 0 0
                }
                geometry DEF SHOULDER_SHAPE Sphere {
                  radius 0.02
                }
              }
            ]
          }
        ]
        boundingObject USE SHOULDER_SHAPE
        physics Physics {
        }
        linearVelocity -0.01636676311887249 -0.0025107521103862585 -0.029872865177830027
        angularVelocity 0.02575740818480431 0.18158223211945637 -0.02288808147922123
      }
    }
  ]
  name "Hexabot"
  boundingObject USE BODY_TRAN
  physics Physics {
  }
  controller "my_controller_c"
  linearVelocity -0.000887439105141936 -0.0024989302579534944 -0.01948784851372832
  angularVelocity -0.2730214726157047 0.3302458584124265 -0.029239675122152496
}
RectangleArena {
  translation 0 -0.05 0
  floorSize 9.5 9.5
  wallThickness 0.1
  wallHeight 1
}
Group {
  children [
    Wall {
      translation 0 -0.05 -3.92
      name "wall(1)"
      size 5 1 0.2
    }
    Wall {
      translation 2.6 -0.05 -1.52
      rotation 0 1 0 -1.5707953071795862
      name "wall(2)"
      size 5 1 0.2
    }
    Wall {
      translation -0.37 -0.05 -1.44
      rotation 0 1 0 -1.5707953071795862
      name "wall(21)"
      size 5 1 0.2
    }
    Wall {
      translation 3.26 -0.05 -3.91
      rotation 0 1 0 1.01503e-06
      name "wall(3)"
      size 1.5 1 0.2
    }
    Wall {
      translation 4.25 -0.05 -2.9
      rotation 0 1 0 1.01503e-06
      name "wall(4)"
      size 1.5 1 0.2
    }
    Wall {
      translation 3.29 -0.05 -1.47
      rotation 0 1 0 1.01503e-06
      name "wall(5)"
      size 1.5 1 0.2
    }
    Wall {
      translation -1.16 -0.05 -1.47
      rotation 0 1 0 1.01503e-06
      name "wall(10)"
      size 1.5 1 0.2
    }
    Wall {
      translation -1.97 -0.05 -0.82
      rotation 0 1 0 -1.5707953071795862
      name "wall(22)"
      size 1.5 1 0.2
    }
    Wall {
      translation -2.62 -0.05 0.0300007
      rotation 0 1 0 1.01503e-06
      name "wall(23)"
      size 1.5 1 0.2
    }
    Wall {
      translation -3.41 -0.05 -0.629998
      rotation 0 1 0 -1.5707953071795862
      name "wall(24)"
      size 1.5 1 0.2
    }
    Wall {
      translation -4.25 -0.05 -1.28
      rotation 0 1 0 3.14159
      name "wall(25)"
      size 1.5 1 0.2
    }
    Wall {
      translation 4.25 -0.05 -0.05
      rotation 0 1 0 1.01503e-06
      name "wall(6)"
      size 1.5 1 0.2
    }
    Wall {
      translation 1.95 -0.05 1.09
      rotation 0 1 0 1.01503e-06
      name "wall(7)"
      size 1.5 1 0.2
    }
    Wall {
      translation 1.95 -0.05 2.42
      rotation 0 1 0 1.01503e-06
      name "wall(8)"
      size 1.5 1 0.2
    }
    Wall {
      translation 0.45 -0.05 2.42
      rotation 0 1 0 1.01503e-06
      name "wall(9)"
      size 1.5 1 0.2
    }
    Wall {
      translation 0.9 -0.05 3.24
      rotation 0 1 0 1.5708
      name "wall(11)"
      size 1.5 1 0.2
    }
    Wall {
      translation 0.9 -0.05 4.27
      rotation 0 1 0 1.5708
      name "wall(12)"
      size 1.5 1 0.2
    }
    Wall {
      translation 1.74 -0.05 3.62
      rotation 0 1 0 -3.1415853071795863
      name "wall(13)"
      size 1.5 1 0.2
    }
    Wall {
      translation 3.2 -0.05 3.62
      rotation 0 1 0 -3.1415853071795863
      name "wall(14)"
      size 1.5 1 0.2
    }
    Wall {
      translation 4.04 -0.05 2.96
      rotation 0 1 0 1.5708
      name "wall(15)"
      size 1.5 1 0.2
    }
    Wall {
      translation 4.04 -0.05 2.04
      rotation 0 1 0 1.5708
      name "wall(16)"
      size 1.5 1 0.2
    }
    Wall {
      translation -1.23 -0.05 2.42
      rotation 0 1 0 1.01503e-06
      name "wall(17)"
      size 1.5 1 0.2
    }
    Wall {
      translation -0.71 -0.05 2.42
      rotation 0 1 0 1.01503e-06
      name "wall(27)"
      size 1.5 1 0.2
    }
    Wall {
      translation -2.72 -0.05 2.42
      rotation 0 1 0 1.01503e-06
      name "wall(26)"
      size 1.5 1 0.2
    }
    Wall {
      translation -1.23 -0.05 3.9
      rotation 0 1 0 1.01503e-06
      name "wall(20)"
      size 1.5 1 0.2
    }
    Wall {
      translation -1.87 -0.05 3.25
      rotation 0 1 0 -1.5707953071795862
      name "wall(18)"
      size 1.5 1 0.2
    }
    Wall {
      translation -0.37 -0.05 3.25
      rotation 0 1 0 -1.5707953071795862
      name "wall(19)"
      size 1.5 1 0.2
    }
  ]
}
