#VRML_SIM R2020a utf8
WorldInfo {
}
DEF Terrain_Subway Group {
  children [
    Group {
      children [
        Rock10cm {
          translation 0.22509764347329708 -0.004315113443175748 -2.4306934383818883
          rotation 0.5320156831977432 0.009906882486035105 -0.846676541845259 -3.041532593666827
          physics Physics {
          }
        }
        Rock10cm {
          translation -0.0517250209258817 -0.002893784852449164 -2.557805061891876
          rotation -0.05055916029081608 0.9924366282619635 0.11186290803797574 -3.083565270989623
          name "rock 10 cm(1)"
          physics Physics {
          }
        }
        Rock10cm {
          translation 0.06777036178690299 -0.002893784852449151 -3.8538927444806905
          rotation -0.05389515553045749 0.992443010021016 0.11023694512627458 3.1396051723249627
          name "rock 10 cm(2)"
          physics Physics {
          }
        }
        Rock10cm {
          translation 0.159145252000597 -0.00289378485244916 -2.5876689701957
          rotation -0.1437307601045198 0.9874310011268419 0.06573801497930896 1.77778327512025
          name "rock 10 cm(3)"
          physics Physics {
          }
        }
        Rock10cm {
          translation 0.11366018019804974 -0.0049125867680953166 -2.4633330424725655
          rotation 0.6168690964779756 -0.48563114771571786 0.6193826815295699 2.154536932376679
          name "rock 10 cm(4)"
          physics Physics {
          }
        }
        Rock10cm {
          translation 0.13258819589857304 8.778070447093924e-05 -2.3222431131581214
          rotation 0.7593109566984791 0.16181015662579012 -0.6302890957730253 1.5534105879841387
          name "rock 10 cm(5)"
          physics Physics {
          }
        }
        Rock10cm {
          translation 0.3988385948694987 -0.002893784852449158 -2.0507615036662843
          rotation 0.47561438494430736 -0.8725051472701731 0.11191838464301448 -0.5077078010248532
          name "rock 10 cm(6)"
          physics Physics {
          }
        }
        Rock10cm {
          translation -0.20200608496559788 -0.00993036449159125 -2.28759204664946
          rotation 0.5146927887980117 0.06911297404196907 0.854584536472782 2.9259286973519107
          name "rock 10 cm(7)"
          physics Physics {
          }
        }
      ]
    }
    DEF Rail Solid {
      translation -0.1260362187436024 -0.003924910730435377 -3.5361246486888147
      rotation 4.702292690939118e-15 1 -3.29707269068642e-16 0.0010497431421132477
      children [
        Shape {
          appearance ThreadMetalPlate {
          }
          geometry DEF railShape Box {
            size 7.2 0.1 0.1
          }
        }
      ]
      name "rail(12)"
      boundingObject USE railShape
      physics Physics {
        mass 10
      }
      linearVelocity -3.3953181592178315e-21 7.297827296966113e-06 -3.810279071884751e-17
      angularVelocity -3.6906316045587596e-16 4.505779359131291e-18 -2.066180866925002e-17
    }
    DEF Rail Solid {
      translation -0.12000000005289294 -0.0039249107304353765 3.4760201028359403
      rotation 2.639507471695159e-11 1 1.134824829869498e-13 -1.1708602106460297e-06
      children [
        Shape {
          appearance ThreadMetalPlate {
          }
          geometry DEF railShape Box {
            size 7.2 0.1 0.1
          }
        }
      ]
      name "rail(11)"
      boundingObject USE railShape
      physics Physics {
        mass 10
      }
      linearVelocity 5.270813238894297e-19 7.2978272969907445e-06 -7.799995584172119e-17
      angularVelocity -1.2790407931904022e-15 1.8999662267530462e-18 -2.1050554707720875e-17
    }
    DEF Rail Solid {
      translation -10.39 -0.003924910730435383 3.47602
      rotation 1.8951341723497278e-10 0.9999999999999999 -1.3246165120611337e-12 -1.1708602106438295e-06
      children [
        Shape {
          appearance ThreadMetalPlate {
          }
          geometry DEF railShape Box {
            size 7.2 0.1 0.1
          }
        }
      ]
      name "rail(2)"
      boundingObject USE railShape
      physics Physics {
        mass 10
      }
      linearVelocity 8.286319002340851e-20 7.297827296966156e-06 2.984590927320446e-17
      angularVelocity 4.2632564145547496e-16 -4.4424865766562116e-18 4.989751873491849e-22
    }
    DEF Rail Solid {
      translation -10.39 -0.003924910730435378 0.27602
      rotation -1.4386475042071108e-11 1 -1.7418025649430696e-13 -1.1708602106478239e-06
      children [
        Shape {
          appearance ThreadMetalPlate {
          }
          geometry DEF railShape Box {
            size 7.2 0.1 0.1
          }
        }
      ]
      name "rail(3)"
      boundingObject USE railShape
      physics Physics {
        mass 10
      }
      linearVelocity 1.0809339350988016e-18 7.297827296977303e-06 1.2954048598753767e-17
      angularVelocity 4.2629370704348427e-16 4.015520378056185e-18 -1.052402991589203e-17
    }
    DEF Rail Solid {
      translation -10.39 -0.003924910730435381 -2.70398
      rotation -2.357664190780192e-10 1 1.1332912415694471e-13 -1.1708602106461288e-06
      children [
        Shape {
          appearance ThreadMetalPlate {
          }
          geometry DEF railShape Box {
            size 7.2 0.1 0.1
          }
        }
      ]
      name "rail(6)"
      boundingObject USE railShape
      physics Physics {
        mass 10
      }
      linearVelocity -5.831416274111602e-19 7.2978272969774e-06 9.742423234656677e-17
      angularVelocity 8.527151517349317e-16 1.7260762221620488e-18 2.105005573253352e-17
    }
    DEF Rail Solid {
      translation 3.5300015845560324 -0.003924910730435382 -0.023458884943641407
      rotation -2.640366771486178e-17 1 -2.5976102072083565e-17 -1.57079586967923
      children [
        Shape {
          appearance ThreadMetalPlate {
          }
          geometry DEF railShape Box {
            size 7.1 0.1 0.1
          }
        }
      ]
      name "rail(10)"
      boundingObject USE railShape
      physics Physics {
        mass 10
      }
      linearVelocity 5.3737573583597346e-17 7.297827296935191e-06 1.2036679706027981e-20
      angularVelocity 1.0822828230713276e-17 3.36539907116499e-18 -4.2631317407504337e-16
    }
    DEF Rail Solid {
      translation -5.71 -0.003924910730435383 -0.0234555
      rotation 1.7831941765230154e-16 1 1.78573721418739e-16 -1.57079586967923
      children [
        Shape {
          appearance ThreadMetalPlate {
          }
          geometry DEF railShape Box {
            size 7.1 0.1 0.1
          }
        }
      ]
      name "rail(13)"
      boundingObject USE railShape
      physics Physics {
        mass 10
      }
      linearVelocity -1.549157050931444e-16 7.297827296973234e-06 1.1232661094785602e-18
      angularVelocity 3.247023791758322e-17 4.92942931835562e-19 2.5579912508786176e-15
    }
    DEF Rail Solid {
      translation -6.4 -0.003924910730435381 -0.0234555
      rotation -6.127679665183991e-16 1 -6.12859638157447e-16 -1.57079586967923
      children [
        Shape {
          appearance ThreadMetalPlate {
          }
          geometry DEF railShape Box {
            size 7.1 0.1 0.1
          }
        }
      ]
      name "rail(14)"
      boundingObject USE railShape
      physics Physics {
        mass 10
      }
      linearVelocity 9.095978621863634e-18 7.297827296990798e-06 -1.124017756933319e-18
      angularVelocity -1.9480282704587498e-22 1.027415128038843e-18 -4.263256414559731e-16
    }
    DEF Rail2 Solid {
      translation -0.4777427863043538 -0.004120717107158643 -2.7559732620268185
      rotation 0.14616889459052218 -0.9892590776252685 0.0010637622795792983 -0.014501344718779466
      children [
        Shape {
          appearance ThreadMetalPlate {
          }
          geometry DEF railShape Box {
            size 6.6 0.1 0.1
          }
        }
      ]
      name "rail(9)"
      boundingObject USE railShape
      physics Physics {
        mass 10
      }
      linearVelocity -2.2861014377768182e-05 -0.0007284597835927791 -0.001473641729537046
      angularVelocity -0.02909689807135315 7.248858136958169e-06 0.00029469510912357133
    }
    DEF Rail2 Solid {
      translation -0.47997151845352015 -0.0039252539763234146 2.786903350112968
      rotation 0.6378907038142034 -0.7701263999799833 0.0008820664889031948 0.004012033050706082
      children [
        Shape {
          appearance ThreadMetalPlate {
          }
          geometry DEF railShape Box {
            size 6.6 0.1 0.1
          }
        }
      ]
      name "rail(8)"
      boundingObject USE railShape
      physics Physics {
        mass 10
      }
      linearVelocity 3.5870492185383633e-07 7.08537602567958e-06 1.4972457379120385e-05
      angularVelocity 1.59370400871052e-05 -4.194605434826969e-06 2.0494661087029974e-06
    }
    DEF Rail2 Solid {
      translation -10.599999574546253 -0.00392491073043538 2.7560835928432064
      rotation 2.3172670834429926e-13 -1 6.517508355638872e-16 0.002992788528764745
      children [
        Shape {
          appearance ThreadMetalPlate {
          }
          geometry DEF railShape Box {
            size 6.6 0.1 0.1
          }
        }
      ]
      name "rail(1)"
      boundingObject USE railShape
      physics Physics {
        mass 10
      }
      linearVelocity 4.657765737003833e-19 7.2978272969834355e-06 8.27111121081543e-18
      angularVelocity -4.2632182471393153e-16 -1.784768800941022e-19 -1.2753091947625852e-18
    }
    DEF Rail2 Solid {
      translation -10.590599574546282 -0.00392491073043538 -0.5539054071523585
      rotation -7.361449471039331e-15 -1 2.408192050987946e-16 0.002992788530412035
      children [
        Shape {
          appearance ThreadMetalPlate {
          }
          geometry DEF railShape Box {
            size 6.6 0.1 0.1
          }
        }
      ]
      name "rail(4)"
      boundingObject USE railShape
      physics Physics {
        mass 10
      }
      linearVelocity -9.234783993253007e-20 7.297827296876443e-06 -7.220186863296128e-17
      angularVelocity -8.52643649427864e-16 -1.4934326478598352e-18 -2.5506183909290286e-18
    }
    DEF Rail2 Solid {
      translation -10.58269957454626 -0.003924910730435378 -3.503896407156841
      rotation 4.036599566089791e-15 -1 2.0025621267427729e-16 0.0029927885314647864
      children [
        Shape {
          appearance ThreadMetalPlate {
          }
          geometry DEF railShape Box {
            size 6.6 0.1 0.1
          }
        }
      ]
      name "rail(5)"
      boundingObject USE railShape
      physics Physics {
        mass 10
      }
      linearVelocity 8.031889163839499e-19 7.2978272969163556e-06 8.543304704604485e-18
      angularVelocity 2.9478070089540702e-16 2.6271055021644595e-18 1.3406526072842773e-17
    }
    DEF Rail2 Solid {
      translation 2.77003702722039 -0.003916406546996818 -0.0028444492348312935
      rotation 1.4384202604701663e-05 0.9999999997169303 1.8953463352337184e-05 -1.5707986691738252
      children [
        Shape {
          appearance ThreadMetalPlate {
          }
          geometry DEF railShape Box {
            size 5.5 0.1 0.1
          }
        }
      ]
      name "rail(7)"
      boundingObject USE railShape
      physics Physics {
        mass 10
      }
      linearVelocity 2.474427370163035e-06 0.0001541165230322349 1.3592160717233526e-05
      angularVelocity 5.225479257972425e-05 3.1349330502625533e-07 -7.918798554358325e-05
    }
    DEF wall1 Solid {
      translation 0.3462049460734197 2.6575966419283175 4.6787898594205
      rotation -0.9905032066956054 0.13741696099494738 -0.004469491764843349 -0.014293362556258985
      children [
        Shape {
          appearance StonePavement {
          }
          geometry Box {
            size 9.25 5.5 0.75
          }
        }
      ]
      name "wall1(5)"
      boundingObject Shape {
        appearance StonePavement {
        }
        geometry Box {
          size 9.25 5.5 0.75
        }
      }
      physics Physics {
        mass 108
      }
      linearVelocity -0.00011099679104240266 0.00030299394056999775 -0.005257897656498226
      angularVelocity -0.0020480781823737893 -7.355581060792618e-05 3.7599399932505004e-05
    }
    DEF wall1 Solid {
      translation -14.526932072140545 2.658235648423039 0.3798035795020705
      rotation -0.004010517502524231 0.999984302375325 -0.00391289564092788 -1.5589240748941529
      children [
        Shape {
          appearance StonePavement {
          }
          geometry Box {
            size 9.25 5.5 0.75
          }
        }
      ]
      name "wall1(6)"
      boundingObject Shape {
        appearance StonePavement {
        }
        geometry Box {
          size 9.25 5.5 0.75
        }
      }
      physics Physics {
        mass 108
      }
      linearVelocity -0.0003432918461878573 -3.167551060952768e-06 -1.6202313557599375e-05
      angularVelocity -1.3751248874134621e-05 -9.626397308665301e-06 -0.0005486753099587497
    }
    DEF wall1_5 Solid {
      translation -9.869685914406162 2.658554030791095 -4.621971344233248
      rotation -0.4736743553933493 0.8209327269975707 -0.31890760854364564 -0.0012325303493869802
      children [
        Shape {
          appearance StonePavement {
          }
          geometry Box {
            size 9.75 5.5 0.75
          }
        }
      ]
      name "wall1(7)"
      boundingObject Shape {
        appearance StonePavement {
        }
        geometry DEF Wall1_5Shape Box {
          size 9.75 5.5 0.75
        }
      }
      physics Physics {
        mass 108
      }
      linearVelocity -0.00012193248717995352 -2.089111806304168e-05 3.864585770274774e-05
      angularVelocity 1.4427267857219841e-05 4.0407814626876917e-07 -2.0763711494509685e-05
    }
    DEF wall1_5 Solid {
      translation -9.203579144409625 2.6576225679004075 4.6047486504873545
      rotation -0.6707152177716187 0.7417147747307675 -0.0005381409266001719 -0.0032409182053044546
      children [
        Shape {
          appearance StonePavement {
          }
          geometry Box {
            size 9.75 5.5 0.75
          }
        }
      ]
      name "wall1(2)"
      boundingObject Shape {
        appearance StonePavement {
        }
        geometry DEF Wall1_5Shape Box {
          size 9.75 5.5 0.75
        }
      }
      physics Physics {
        mass 108
      }
      linearVelocity 5.117399425604384e-05 -5.595019743581091e-06 -0.0001085650031549677
      angularVelocity -3.95799167206337e-05 6.817906381101602e-07 7.047905326903661e-07
    }
    DEF wall3 Solid {
      translation -10.531955798213893 2.65758147452647 1.3208862833576647
      rotation 0.7582002670704117 0.6518899093300128 -0.013111107049533565 -0.0026971758995221855
      children [
        Shape {
          appearance StonePavement {
          }
          geometry DEF wall3shape Box {
            size 7.25 5.5 0.75
          }
        }
      ]
      name "wall1(1)"
      boundingObject USE wall3shape
      physics Physics {
        mass 108
      }
      linearVelocity 0.0011036191423141747 -7.11245306349021e-05 1.932439277658178e-05
      angularVelocity 1.1894811294892581e-05 3.464573760477404e-07 2.0227816577949872e-05
    }
    DEF wall3 Solid {
      translation -10.550109013520585 2.6569223876597916 -1.5963891505285301
      rotation 0.9703640630826855 -0.23929522207593595 0.033636018927489186 0.005954500021328587
      children [
        Shape {
          appearance StonePavement {
          }
          geometry DEF wall3shape Box {
            size 7.25 5.5 0.75
          }
        }
      ]
      name "wall1(8)"
      boundingObject USE wall3shape
      physics Physics {
        mass 108
      }
      linearVelocity 0.0006333377668381483 8.550410051544465e-06 0.00024875394993705333
      angularVelocity 9.412424644060155e-05 1.9963879673449674e-06 -2.255540288681851e-06
    }
    DEF wall2 Solid {
      translation -4.637828093639867 2.657671462693319 -1.0925924929085176
      rotation 0.0007413073423011472 -0.9999994365334848 0.0007598658678595548 1.5726454522386581
      children [
        Shape {
          appearance StonePavement {
          }
          geometry DEF Wall2Shape Box {
            size 6.25 5.5 0.75
          }
        }
      ]
      name "wall2(1)"
      boundingObject USE Wall2Shape
      physics Physics {
        mass 108
      }
      linearVelocity 2.834161675445895e-05 -1.1931495209864805e-06 -7.247310754345773e-07
      angularVelocity -4.144350880755431e-07 -3.964144467567636e-06 -1.4955795842793598e-05
    }
    DEF wall3 Solid {
      translation -0.37258981980949124 2.6566216748331555 -4.628228170585206
      rotation 0.6877349207674653 0.7205600143848209 0.0883965181820806 -0.000402248668275058
      children [
        Shape {
          appearance StonePavement {
          }
          geometry Box {
            size 9.25 5.5 0.75
          }
        }
      ]
      name "wall1(4)"
      boundingObject Shape {
        appearance StonePavement {
        }
        geometry Box {
          size 9.25 5.5 0.75
        }
      }
      physics Physics {
        mass 108
      }
      linearVelocity 0.00010165616591796867 -2.1783991952462303e-06 1.829785710601376e-05
      angularVelocity 1.4286196379268514e-05 3.843304547630585e-06 8.591450974263346e-06
    }
    DEF wall4 Solid {
      translation 4.6127816155928985 2.657445402949262 -0.3395270519250979
      rotation 0.0004752485366903336 0.9999997382074082 0.0005456408557187251 -1.5744546906273456
      children [
        Shape {
          appearance StonePavement {
          }
          geometry Box {
            size 9.25 5.5 0.75
          }
        }
      ]
      name "wall1(3)"
      boundingObject Shape {
        appearance StonePavement {
        }
        geometry Box {
          size 9.25 5.5 0.75
        }
      }
      physics Physics {
        mass 108
      }
      linearVelocity -1.3392461880491273e-05 -0.00013975053583305486 -0.00023267686785961118
      angularVelocity 4.1774545628183826e-05 -8.610306221704686e-06 2.625366152434913e-05
    }
    DEF wall5 Solid {
      translation -1.1145288061490692 2.6575670305039725 0.10481737727603889
      rotation -0.0020487994634003485 0.9999970200831154 -0.001327496006630883 -0.01323718308500368
      children [
        DEF wall5 Shape {
          appearance StonePavement {
          }
          geometry Box {
            size 6.25 5.5 4
          }
        }
      ]
      name "wall5(1)"
      boundingObject USE wall5
      physics Physics {
        mass 108
      }
      linearVelocity 1.4974976778007955e-05 2.6541522681294364e-06 -3.9200389909196024e-06
      angularVelocity -1.269920184354914e-06 1.6605045575119663e-06 -8.820746550102482e-07
    }
  ]
}
Viewpoint {
  orientation 0.013330439234675738 0.7884185084023979 0.6149947601389373 3.065090749247407
  position 10.395240228188893 24.412386575773557 -5.962018351019584
  follow "Hexabot"
  followType "None"
}
Background {
  skyColor [
    0.6 0.6 0.8
  ]
}
Robot {
  translation 9.84049 0.517322 -1.5699
  rotation 0.13784889470339223 0.9777912490815622 -0.15786689155288794 -1.7664648780131247
  children [
    Display {
      name "Lidar_Display"
    }
    HokuyoUtm30lx {
      translation 0 0.1 0
      rotation 0 1 0 -1.5708
    }
    Compass {
      name "Hexabot_Compass"
    }
    Gyro {
      name "Hexabot_Gyro"
    }
    GPS {
      name "Hexabot_GPS"
    }
    Camera {
      translation 0.1 -1.12008e-13 -1.49482e-07
      rotation 8.684229999951365e-07 -0.9999999999943995 3.2321499999818985e-06 1.5707853071795865
      children [
        DEF CAM_SHAPE Shape {
          appearance MattePaint {
            baseColor 0.7 0.1 0.1
          }
          geometry Cylinder {
            height 0.05
            radius 0.0125
          }
        }
      ]
      name "Hexabot_Camera"
      boundingObject USE CAM_SHAPE
      physics Physics {
      }
      lens Lens {
      }
      focus Focus {
      }
      recognition Recognition {
      }
    }
    DEF BODY_TRAN Transform {
      children [
        DEF BODY Shape {
          appearance MattePaint {
            baseColor 0.1 0.1 0.7
          }
          geometry Box {
            size 0.2 0.05 0.125
          }
        }
      ]
    }
    Hinge2Joint {
      jointParameters HingeJointParameters {
        position -0.07893302040880361
      }
      jointParameters2 JointParameters {
        position -0.29469064602334494
        axis 0 1 0
      }
      device [
        DEF SHOULDER_2_x RotationalMotor {
          name "Hexabot_Leg0_Motor1"
        }
      ]
      device2 [
        DEF SHOULDER_0_y RotationalMotor {
          name "Hexabot_Leg0_Motor2"
        }
      ]
      endPoint DEF SHOULDER_0 Solid {
        translation 0.07560117126102099 -0.007655186925936823 0.05450335895144945
        rotation 0.9938888290933542 -0.007251676177545154 -0.11014721329229035 1.9962562025567545
        children [
          Transform {
            children [
              DEF FEMUR_0 Solid {
                translation 0 0.025981 -0.0450019
                rotation 1 0 0 0.523599
                children [
                  HingeJoint {
                    jointParameters HingeJointParameters {
                      position -0.2265866717640076
                      axis 0 0 1
                    }
                    device [
                      DEF ELBOW_0 RotationalMotor {
                        name "Hexabot_Leg0_Motor3"
                      }
                    ]
                    endPoint Solid {
                      translation -0.00013015931533983584 -0.0007238198687512913 -0.05856390241636159
                      rotation -0.6955710531765388 -0.7038977179365054 -0.14390591602383926 2.8173616043687764
                      children [
                        Transform {
                          children [
                            Solid {
                              translation 0.0824507 0 0.0210637
                              rotation 0 -1 0 1.8325953071795864
                              children [
                                Shape {
                                  appearance MattePaint {
                                    baseColor 0.1 0.1 0.6
                                  }
                                  geometry DEF TIBIA_SHAPE Box {
                                    size 0.025 0.025 0.15
                                  }
                                }
                              ]
                              boundingObject USE TIBIA_SHAPE
                              physics Physics {
                              }
                            }
                            DEF ELBOW_SHAPE Shape {
                              appearance MattePaint {
                                baseColor 0 0 0
                              }
                              geometry Cylinder {
                                height 0.025
                                radius 0.0125
                              }
                            }
                          ]
                        }
                      ]
                      boundingObject USE ELBOW_SHAPE
                      physics Physics {
                      }
                    }
                  }
                  DEF FEMUR_SHAPE Shape {
                    appearance MattePaint {
                      baseColor 0.2 0.2 1
                    }
                    geometry Box {
                      size 0.025 0.025 0.1
                    }
                  }
                ]
                boundingObject USE FEMUR_SHAPE
                physics Physics {
                }
              }
              Shape {
                appearance MattePaint {
                  baseColor 0 0 0
                }
                geometry DEF SHOULDER_SHAPE Sphere {
                  radius 0.02
                }
              }
            ]
          }
        ]
        name "solid(5)"
        boundingObject USE SHOULDER_SHAPE
        physics Physics {
        }
      }
    }
    Hinge2Joint {
      jointParameters HingeJointParameters {
        position 0.4789214274603377
      }
      jointParameters2 JointParameters {
        position -0.10531301094986467
        axis 0 1 0
      }
      device [
        DEF SHOULDER_2_x RotationalMotor {
          name "Hexabot_Leg1_Motor1"
        }
      ]
      device2 [
        DEF SHOULDER_0_y RotationalMotor {
          name "Hexabot_Leg1_Motor2"
        }
      ]
      endPoint DEF SHOULDER_0 Solid {
        translation 0.004586722925124904 -0.018403365320818536 0.05675424522006856
        rotation 0.9910151053821662 0.08508429826311371 -0.10319749557740042 1.762939108890316
        children [
          Transform {
            children [
              DEF FEMUR_0 Solid {
                translation 0 0.025981 -0.0450019
                rotation 1 0 0 0.523599
                children [
                  HingeJoint {
                    jointParameters HingeJointParameters {
                      position -0.3734090417823984
                      axis 0 0 1
                    }
                    device [
                      DEF ELBOW_0 RotationalMotor {
                        name "Hexabot_Leg1_Motor3"
                      }
                    ]
                    endPoint Solid {
                      translation -0.00022429778910291903 -0.0005856004969712668 -0.05861795080600518
                      rotation -0.7440403436106149 -0.6498793332375126 -0.15511550312771463 2.839128942834957
                      children [
                        Transform {
                          children [
                            Solid {
                              translation 0.0824507 0 0.0210637
                              rotation 0 -1 0 1.8325953071795864
                              children [
                                Shape {
                                  appearance MattePaint {
                                    baseColor 0.1 0.1 0.6
                                  }
                                  geometry DEF TIBIA_SHAPE Box {
                                    size 0.025 0.025 0.15
                                  }
                                }
                              ]
                              boundingObject USE TIBIA_SHAPE
                              physics Physics {
                              }
                            }
                            DEF ELBOW_SHAPE Shape {
                              appearance MattePaint {
                                baseColor 0 0 0
                              }
                              geometry Cylinder {
                                height 0.025
                                radius 0.0125
                              }
                            }
                          ]
                        }
                      ]
                      boundingObject USE ELBOW_SHAPE
                      physics Physics {
                      }
                    }
                  }
                  DEF FEMUR_SHAPE Shape {
                    appearance MattePaint {
                      baseColor 0.2 0.2 1
                    }
                    geometry Box {
                      size 0.025 0.025 0.1
                    }
                  }
                ]
                boundingObject USE FEMUR_SHAPE
                physics Physics {
                }
              }
              Shape {
                appearance MattePaint {
                  baseColor 0 0 0
                }
                geometry DEF SHOULDER_SHAPE Sphere {
                  radius 0.02
                }
              }
            ]
          }
        ]
        name "solid(4)"
        boundingObject USE SHOULDER_SHAPE
        physics Physics {
        }
      }
    }
    Hinge2Joint {
      jointParameters HingeJointParameters {
        position 1.1210791442111776
      }
      jointParameters2 JointParameters {
        position -0.29467651166433473
        axis 0 1 0
      }
      device [
        DEF SHOULDER_2_x RotationalMotor {
          name "Hexabot_Leg2_Motor1"
        }
      ]
      device2 [
        DEF SHOULDER_0_y RotationalMotor {
          name "Hexabot_Leg2_Motor2"
        }
      ]
      endPoint DEF SHOULDER_0 Solid {
        translation -0.0891530221117852 0.010063689329615079 0.04729847162441518
        rotation 0.9914943743598583 -0.0936692581399994 -0.09036025504753468 2.2127284588888045
        children [
          Transform {
            children [
              DEF FEMUR_0 Solid {
                translation 0 0.025981 -0.0450019
                rotation 1 0 0 0.523599
                children [
                  HingeJoint {
                    jointParameters HingeJointParameters {
                      position -0.2265889215250222
                      axis 0 0 1
                    }
                    device [
                      DEF ELBOW_0 RotationalMotor {
                        name "Hexabot_Leg2_Motor3"
                      }
                    ]
                    endPoint Solid {
                      translation -0.0001318623468026977 -0.0006878367776534278 -0.05857588456507879
                      rotation -0.7007737449011121 -0.7115362300845675 -0.05130644924677758 3.0026933542027265
                      children [
                        Transform {
                          children [
                            Solid {
                              translation 0.0824507 0 0.0210637
                              rotation 0 -1 0 1.8325953071795864
                              children [
                                Shape {
                                  appearance MattePaint {
                                    baseColor 0.1 0.1 0.6
                                  }
                                  geometry DEF TIBIA_SHAPE Box {
                                    size 0.025 0.025 0.15
                                  }
                                }
                              ]
                              boundingObject USE TIBIA_SHAPE
                              physics Physics {
                              }
                            }
                            DEF ELBOW_SHAPE Shape {
                              appearance MattePaint {
                                baseColor 0 0 0
                              }
                              geometry Cylinder {
                                height 0.025
                                radius 0.0125
                              }
                            }
                          ]
                        }
                      ]
                      boundingObject USE ELBOW_SHAPE
                      physics Physics {
                      }
                    }
                  }
                  DEF FEMUR_SHAPE Shape {
                    appearance MattePaint {
                      baseColor 0.2 0.2 1
                    }
                    geometry Box {
                      size 0.025 0.025 0.1
                    }
                  }
                ]
                boundingObject USE FEMUR_SHAPE
                physics Physics {
                }
              }
              Shape {
                appearance MattePaint {
                  baseColor 0 0 0
                }
                geometry DEF SHOULDER_SHAPE Sphere {
                  radius 0.02
                }
              }
            ]
          }
        ]
        name "solid(3)"
        boundingObject USE SHOULDER_SHAPE
        physics Physics {
        }
      }
    }
    Hinge2Joint {
      jointParameters HingeJointParameters {
        position -0.12105873923437219
      }
      jointParameters2 JointParameters {
        position -0.2771476024225063
        axis 0 1 0
      }
      device [
        DEF SHOULDER_3_x RotationalMotor {
          name "Hexabot_Leg3_Motor1"
        }
      ]
      device2 [
        DEF SHOULDER_3_y RotationalMotor {
          name "Hexabot_Leg3_Motor2"
        }
      ]
      endPoint DEF SHOULDER_0 Solid {
        translation -0.08555113243678272 0.0044267942717272106 -0.04673229511985125
        rotation -0.9920487665300385 -0.1255682493423634 0.008477003204164233 0.12203056709686204
        children [
          Transform {
            translation 0 0 -0.01
            children [
              DEF FEMUR_0 Solid {
                translation 0 0.0259808 -0.045
                rotation 1 0 0 0.523599
                children [
                  HingeJoint {
                    jointParameters HingeJointParameters {
                      position -0.260323688287426
                      axis 0 0 1
                    }
                    device [
                      DEF ELBOW_3 RotationalMotor {
                        name "Hexabot_Leg3_Motor3"
                      }
                    ]
                    endPoint Solid {
                      translation -9.720129730531783e-06 -2.3210020917991063e-05 -0.06002055998798714
                      rotation 3.939860507583271e-05 5.314090900450725e-05 -0.9999999978118967 1.56932208114524
                      children [
                        Transform {
                          children [
                            Solid {
                              translation 0.0824507 0 0.0210637
                              rotation 0 -1 0 1.8325953071795864
                              children [
                                Shape {
                                  appearance MattePaint {
                                    baseColor 0.1 0.1 0.6
                                  }
                                  geometry DEF TIBIA_SHAPE Box {
                                    size 0.025 0.025 0.15
                                  }
                                }
                              ]
                              boundingObject USE TIBIA_SHAPE
                              physics Physics {
                              }
                            }
                            DEF ELBOW_SHAPE Shape {
                              appearance MattePaint {
                                baseColor 0 0 0
                              }
                              geometry Cylinder {
                                height 0.025
                                radius 0.0125
                              }
                            }
                          ]
                        }
                      ]
                      boundingObject USE ELBOW_SHAPE
                      physics Physics {
                      }
                    }
                  }
                  DEF FEMUR_SHAPE Shape {
                    appearance MattePaint {
                      baseColor 0.2 0.2 1
                    }
                    geometry Box {
                      size 0.025 0.025 0.1
                    }
                  }
                ]
                boundingObject USE FEMUR_SHAPE
                physics Physics {
                }
              }
              Shape {
                appearance MattePaint {
                  baseColor 0 0 0
                }
                geometry DEF SHOULDER_SHAPE Sphere {
                  radius 0.02
                }
              }
            ]
          }
        ]
        name "solid(2)"
        boundingObject USE SHOULDER_SHAPE
        physics Physics {
        }
      }
    }
    Hinge2Joint {
      jointParameters HingeJointParameters {
        position 0.021058461001902784
      }
      jointParameters2 JointParameters {
        position -0.12285175562184077
        axis 0 1 0
      }
      device [
        DEF SHOULDER_4_x RotationalMotor {
          name "Hexabot_Leg4_Motor1"
        }
      ]
      device2 [
        DEF SHOULDER_4_y RotationalMotor {
          name "Hexabot_Leg4_Motor2"
        }
      ]
      endPoint DEF SHOULDER_0 Solid {
        translation -0.01371885053054657 0.0011061704180287076 -0.05208050294118041
        rotation 0.16873995790379598 -0.9856059671905633 -0.010378055934498951 0.12464130435324022
        children [
          Transform {
            translation 0 0 -0.01
            children [
              DEF FEMUR_0 Solid {
                translation 0 0.0259808 -0.045
                rotation 1 0 0 0.523599
                children [
                  HingeJoint {
                    jointParameters HingeJointParameters {
                      position 0.060324914934606885
                      axis 0 0 1
                    }
                    device [
                      DEF ELBOW_4 RotationalMotor {
                        name "Hexabot_Leg4_Motor3"
                      }
                    ]
                    endPoint Solid {
                      translation -1.495496281182258e-12 2.4760611067807705e-11 -0.05999999999999949
                      rotation 2.067146621765132e-10 2.195763292579437e-10 -0.9999999999999999 1.5104703922448253
                      children [
                        Transform {
                          children [
                            Solid {
                              translation 0.0824507 0 0.0210637
                              rotation 0 -1 0 1.8325953071795864
                              children [
                                Shape {
                                  appearance MattePaint {
                                    baseColor 0.1 0.1 0.6
                                  }
                                  geometry DEF TIBIA_SHAPE Box {
                                    size 0.025 0.025 0.15
                                  }
                                }
                              ]
                              boundingObject USE TIBIA_SHAPE
                              physics Physics {
                              }
                            }
                            DEF ELBOW_SHAPE Shape {
                              appearance MattePaint {
                                baseColor 0 0 0
                              }
                              geometry Cylinder {
                                height 0.025
                                radius 0.0125
                              }
                            }
                          ]
                        }
                      ]
                      boundingObject USE ELBOW_SHAPE
                      physics Physics {
                      }
                    }
                  }
                  DEF FEMUR_SHAPE Shape {
                    appearance MattePaint {
                      baseColor 0.2 0.2 1
                    }
                    geometry Box {
                      size 0.025 0.025 0.1
                    }
                  }
                ]
                boundingObject USE FEMUR_SHAPE
                physics Physics {
                }
              }
              Shape {
                appearance MattePaint {
                  baseColor 0 0 0
                }
                geometry DEF SHOULDER_SHAPE Sphere {
                  radius 0.02
                }
              }
            ]
          }
        ]
        name "solid(1)"
        boundingObject USE SHOULDER_SHAPE
        physics Physics {
        }
      }
    }
    Hinge2Joint {
      jointParameters HingeJointParameters {
        position -0.021059215738421747
      }
      jointParameters2 JointParameters {
        position -0.27714556207221597
        axis 0 1 0
      }
      device [
        DEF SHOULDER_5_x RotationalMotor {
          name "Hexabot_Leg5_Motor1"
        }
      ]
      device2 [
        DEF SHOULDER_5_y RotationalMotor {
          name "Hexabot_Leg5_Motor2"
        }
      ]
      endPoint DEF SHOULDER_0 Solid {
        translation 0.09336388948429904 -0.0007417865381203121 -0.03581380443768271
        rotation -0.07528347849145008 -0.9971068938086161 0.010499532635333752 0.27793940128299943
        children [
          Transform {
            translation 0 0 -0.01
            children [
              DEF FEMUR_0 Solid {
                translation 0 0.0259808 -0.045
                rotation 1 0 0 0.523599
                children [
                  HingeJoint {
                    jointParameters HingeJointParameters {
                      position 0.13967466995353262
                      axis 0 0 1
                    }
                    device [
                      DEF ELBOW_5 RotationalMotor {
                        name "Hexabot_Leg5_Motor3"
                      }
                    ]
                    endPoint Solid {
                      translation 2.211088880240743e-23 -1.5727199672609955e-22 -0.06000000000000022
                      rotation -1.228753658586121e-20 -4.742379320295257e-21 -0.9999999999999999 1.431120637226016
                      children [
                        Transform {
                          children [
                            Solid {
                              translation 0.0824507 0 0.0210637
                              rotation 0 -1 0 1.8325953071795864
                              children [
                                Shape {
                                  appearance MattePaint {
                                    baseColor 0.1 0.1 0.6
                                  }
                                  geometry DEF TIBIA_SHAPE Box {
                                    size 0.025 0.025 0.15
                                  }
                                }
                              ]
                              boundingObject USE TIBIA_SHAPE
                              physics Physics {
                              }
                            }
                            DEF ELBOW_SHAPE Shape {
                              appearance MattePaint {
                                baseColor 0 0 0
                              }
                              geometry Cylinder {
                                height 0.025
                                radius 0.0125
                              }
                            }
                          ]
                        }
                      ]
                      boundingObject USE ELBOW_SHAPE
                      physics Physics {
                      }
                      recognitionColors [
                        0 0 0
                      ]
                    }
                  }
                  DEF FEMUR_SHAPE Shape {
                    appearance MattePaint {
                      baseColor 0.2 0.2 1
                    }
                    geometry Box {
                      size 0.025 0.025 0.1
                    }
                  }
                ]
                boundingObject USE FEMUR_SHAPE
                physics Physics {
                }
              }
              Shape {
                appearance MattePaint {
                  baseColor 0 0 0
                }
                geometry DEF SHOULDER_SHAPE Sphere {
                  radius 0.02
                }
              }
            ]
          }
        ]
        boundingObject USE SHOULDER_SHAPE
        physics Physics {
        }
      }
    }
  ]
  name "Hexabot"
  boundingObject USE BODY_TRAN
  physics Physics {
  }
  controller "my_controller_c"
}
RectangleArena {
  translation 0 -0.05 0
  floorSize 35 20
  wallHeight 0.5
}
OilBarrel {
  translation 12.48 0.44 0.14
  name "oil barrel(4)"
}
