#VRML_SIM R2020a utf8
DEF wall5 WorldInfo {
}
Viewpoint {
  orientation -0.508116819417028 0.7852286830071166 0.35388305018527344 1.9326355645189384
  position 5.825231139311421 13.164166935809769 -1.5551095493129745
  follow "Hexabot"
  followType "None"
}
TexturedBackground {
}
TexturedBackgroundLight {
}
RectangleArena {
  translation -4.97 -0.05 0
  floorSize 20 10
  wallHeight 0.5
}
DEF Hexabot Robot {
  translation 0.18131386549383818 0.05128307370475763 -3.1242694766658454
  rotation -7.452469131340891e-05 0.9999999972079261 -5.49712587704946e-06 -2.9694750575829243
  children [
    Camera {
      translation 0.1 -1.12008e-13 -1.49482e-07
      rotation 8.684229999951365e-07 -0.9999999999943995 3.2321499999818985e-06 1.5707853071795865
      children [
        DEF CAM_SHAPE Shape {
          appearance MattePaint {
            baseColor 0.7 0.1 0.1
          }
          geometry Cylinder {
            height 0.05
            radius 0.0125
          }
        }
      ]
      name "Hexabot_Camera"
      boundingObject USE CAM_SHAPE
      physics Physics {
      }
      lens Lens {
      }
      focus Focus {
      }
    }
    DEF BODY_TRAN Transform {
      children [
        DEF BODY Shape {
          appearance MattePaint {
            baseColor 0.1 0.1 0.7
          }
          geometry Box {
            size 0.2 0.05 0.125
          }
        }
      ]
    }
    Hinge2Joint {
      jointParameters HingeJointParameters {
        position -8.521689127746998e-06
      }
      jointParameters2 JointParameters {
        position -7.848246200429926e-06
      }
      device [
        DEF SHOULDER_2_x RotationalMotor {
          name "Hexabot_Leg0_Motor1"
        }
      ]
      device2 [
        DEF SHOULDER_0_y RotationalMotor {
          name "Hexabot_Leg0_Motor2"
        }
      ]
      endPoint DEF SHOULDER_0 Solid {
        translation 0.07999999723094131 3.604252785697183e-05 0.07000003613490254
        rotation 3.924119181789025e-06 0.9999999999832234 -4.26084840647023e-06 3.141590814547129
        children [
          Transform {
            children [
              DEF FEMUR_0 Solid {
                translation 0 0.025981 -0.0450019
                rotation 1 0 0 0.523599
                children [
                  HingeJoint {
                    jointParameters HingeJointParameters {
                      position 2.280410118890426e-06
                      axis 0 0 1
                    }
                    device [
                      DEF ELBOW_0 RotationalMotor {
                        name "Hexabot_Leg0_Motor3"
                      }
                    ]
                    endPoint Solid {
                      translation 2.1124670711324336e-17 -9.263447297837367e-12 -0.05999999999999815
                      rotation -7.771335033213857e-11 -7.667759613451816e-11 -1 1.5707930267685066
                      children [
                        Transform {
                          children [
                            Solid {
                              translation 0.0824507 0 0.0210637
                              rotation 0 -1 0 1.8325953071795864
                              children [
                                Shape {
                                  appearance MattePaint {
                                    baseColor 0.1 0.1 0.6
                                  }
                                  geometry DEF TIBIA_SHAPE Box {
                                    size 0.025 0.025 0.15
                                  }
                                }
                              ]
                              boundingObject USE TIBIA_SHAPE
                              physics Physics {
                              }
                            }
                            DEF ELBOW_SHAPE Shape {
                              appearance MattePaint {
                                baseColor 0 0 0
                              }
                              geometry Cylinder {
                                height 0.025
                                radius 0.0125
                              }
                            }
                          ]
                        }
                      ]
                      boundingObject USE ELBOW_SHAPE
                      physics Physics {
                      }
                      linearVelocity -2.414791980267761e-07 -3.9474090545883065e-07 4.914573449038473e-08
                      angularVelocity 6.169365515089894e-07 -1.5585252233812505e-06 3.5593332137768267e-06
                    }
                  }
                  DEF FEMUR_SHAPE Shape {
                    appearance MattePaint {
                      baseColor 0.2 0.2 1
                    }
                    geometry Box {
                      size 0.025 0.025 0.1
                    }
                  }
                ]
                boundingObject USE FEMUR_SHAPE
                physics Physics {
                }
              }
              Shape {
                appearance MattePaint {
                  baseColor 0 0 0
                }
                geometry DEF SHOULDER_SHAPE Sphere {
                  radius 0.02
                }
              }
            ]
          }
        ]
        name "solid(5)"
        boundingObject USE SHOULDER_SHAPE
        physics Physics {
        }
        linearVelocity -3.235262073010742e-07 -3.9482769623536537e-07 7.988246844517715e-08
        angularVelocity -9.322079689243843e-11 5.113878655313725e-07 2.3970986548906042e-08
      }
    }
    Hinge2Joint {
      jointParameters HingeJointParameters {
        position -9.519315166545366e-06
      }
      jointParameters2 JointParameters {
        position -8.985456769238489e-06
      }
      device [
        DEF SHOULDER_1_x RotationalMotor {
          name "Hexabot_Leg1_Motor1"
        }
      ]
      device2 [
        DEF SHOULDER_1_y RotationalMotor {
          name "Hexabot_Leg1_Motor2"
        }
      ]
      endPoint DEF SHOULDER_0 Solid {
        translation 6.572664658376685e-10 1.3262828229204977e-05 0.06999996636086878
        rotation 4.492722069533944e-06 0.9999999999785807 -4.759663544017712e-06 3.14159000005575
        children [
          Transform {
            children [
              DEF FEMUR_0 Solid {
                translation 0 0.0259808 -0.045
                rotation 1 0 0 0.523599
                children [
                  HingeJoint {
                    jointParameters HingeJointParameters {
                      position 5.105658657512822e-06
                    }
                    device [
                      DEF ELBOW_1 RotationalMotor {
                        name "Hexabot_Leg1_Motor3"
                      }
                    ]
                    endPoint Solid {
                      translation 0 3.0632674514349296e-07 -0.05999999999921781
                      rotation 2.5527256555616694e-06 2.552722699463058e-06 -0.9999999999934835 1.5707953071876726
                      children [
                        Transform {
                          children [
                            Solid {
                              translation 0.0824507 0 0.0210637
                              rotation 0 -1 0 1.8325953071795864
                              children [
                                Shape {
                                  appearance MattePaint {
                                    baseColor 0.1 0.1 0.6
                                  }
                                  geometry DEF TIBIA_SHAPE Box {
                                    size 0.025 0.025 0.15
                                  }
                                }
                              ]
                              boundingObject USE TIBIA_SHAPE
                              physics Physics {
                              }
                            }
                            DEF ELBOW_SHAPE Shape {
                              appearance MattePaint {
                                baseColor 0 0 0
                              }
                              geometry Cylinder {
                                height 0.025
                                radius 0.0125
                              }
                            }
                          ]
                        }
                      ]
                      boundingObject USE ELBOW_SHAPE
                      physics Physics {
                      }
                      linearVelocity -3.5677554086429495e-08 -3.9460811603306224e-07 5.559756036360646e-09
                      angularVelocity 4.523554237598179e-09 4.5582950291340403e-07 6.114119944494115e-08
                    }
                  }
                  DEF FEMUR_SHAPE Shape {
                    appearance MattePaint {
                      baseColor 0.2 0.2 1
                    }
                    geometry Box {
                      size 0.025 0.025 0.1
                    }
                  }
                ]
                boundingObject USE FEMUR_SHAPE
                physics Physics {
                }
              }
              Shape {
                appearance MattePaint {
                  baseColor 0 0 0
                }
                geometry DEF SHOULDER_SHAPE Sphere {
                  radius 0.02
                }
              }
            ]
          }
        ]
        name "solid(4)"
        boundingObject USE SHOULDER_SHAPE
        physics Physics {
        }
        linearVelocity -7.624719948917576e-08 -3.93726262623543e-07 1.2138432159036095e-08
        angularVelocity 2.8320411371847398e-09 4.625032508483819e-07 5.117786920477732e-08
      }
    }
    Hinge2Joint {
      jointParameters HingeJointParameters {
        position -9.980063156362626e-06
      }
      jointParameters2 JointParameters {
        position -9.638578983399481e-06
      }
      device [
        DEF SHOULDER_2_x RotationalMotor {
        }
      ]
      device2 [
        DEF SHOULDER_2_y RotationalMotor {
        }
      ]
      endPoint DEF SHOULDER_0 Solid {
        translation -0.07999999727936746 1.3884479635529928e-05 0.0699999616401627
        rotation 4.81928286476742e-06 0.999999999975937 -4.990037973290123e-06 3.141589997449081
        children [
          Transform {
            children [
              DEF FEMUR_0 Solid {
                translation 0 0.0259808 -0.045
                rotation 1 0 0 0.523599
                children [
                  HingeJoint {
                    jointParameters HingeJointParameters {
                      position 5.205896195168712e-06
                    }
                    device [
                      DEF ELBOW_2 RotationalMotor {
                        name "Hexabot_Leg2_Motor3"
                      }
                    ]
                    endPoint Solid {
                      translation 0 3.123403164250091e-07 -0.059999999999188
                      rotation 2.602838624102033e-06 2.602835970208876e-06 -0.9999999999932251 1.5707953071861787
                      children [
                        Transform {
                          children [
                            Solid {
                              translation 0.0824507 0 0.0210637
                              rotation 0 -1 0 1.8325953071795864
                              children [
                                Shape {
                                  appearance MattePaint {
                                    baseColor 0.1 0.1 0.6
                                  }
                                  geometry DEF TIBIA_SHAPE Box {
                                    size 0.025 0.025 0.15
                                  }
                                }
                              ]
                              boundingObject USE TIBIA_SHAPE
                              physics Physics {
                              }
                            }
                            DEF ELBOW_SHAPE Shape {
                              appearance MattePaint {
                                baseColor 0 0 0
                              }
                              geometry Cylinder {
                                height 0.025
                                radius 0.0125
                              }
                            }
                          ]
                        }
                      ]
                      boundingObject USE ELBOW_SHAPE
                      physics Physics {
                      }
                      linearVelocity -3.6851302269455395e-08 -3.902994845802069e-07 -1.338673953837787e-09
                      angularVelocity 9.396318007192755e-10 4.546439643031436e-07 6.17464272507552e-08
                    }
                  }
                  DEF FEMUR_SHAPE Shape {
                    appearance MattePaint {
                      baseColor 0.2 0.2 1
                    }
                    geometry Box {
                      size 0.025 0.025 0.1
                    }
                  }
                ]
                boundingObject USE FEMUR_SHAPE
                physics Physics {
                }
              }
              Shape {
                appearance MattePaint {
                  baseColor 0 0 0
                }
                geometry DEF SHOULDER_SHAPE Sphere {
                  radius 0.02
                }
              }
            ]
          }
        ]
        name "solid(3)"
        boundingObject USE SHOULDER_SHAPE
        physics Physics {
        }
        linearVelocity -8.000156476035438e-08 -3.894715909354485e-07 -9.573274376714757e-09
        angularVelocity 1.2497941005247404e-09 4.613095841279698e-07 5.14476075261693e-08
      }
    }
    Hinge2Joint {
      jointParameters HingeJointParameters {
        position 9.671535003129409e-06
      }
      jointParameters2 JointParameters {
        position 9.026830863533524e-06
      }
      device [
        DEF SHOULDER_3_x RotationalMotor {
          name "Hexabot_Leg3_Motor1"
        }
      ]
      device2 [
        DEF SHOULDER_3_y RotationalMotor {
          name "Hexabot_Leg3_Motor2"
        }
      ]
      endPoint DEF SHOULDER_0 Solid {
        translation -0.07999999885772581 1.2123365058605328e-05 -0.059999969807129724
        rotation 0.7310528227124101 -3.299545091489247e-06 0.6823208705538257 1.3229579541749834e-05
        children [
          Transform {
            translation 0 0 -0.01
            children [
              DEF FEMUR_0 Solid {
                translation 0 0.0259808 -0.045
                rotation 1 0 0 0.523599
                children [
                  HingeJoint {
                    jointParameters HingeJointParameters {
                      position 5.318441002333017e-06
                    }
                    device [
                      DEF ELBOW_3 RotationalMotor {
                        name "Hexabot_Leg3_Motor3"
                      }
                    ]
                    endPoint Solid {
                      translation 0 3.1910799033545376e-07 -0.05999999999915116
                      rotation 2.6592359641949195e-06 2.6592332527951744e-06 -0.9999999999929284 1.5707953071864686
                      children [
                        Transform {
                          children [
                            Solid {
                              translation 0.0824507 0 0.0210637
                              rotation 0 -1 0 1.8325953071795864
                              children [
                                Shape {
                                  appearance MattePaint {
                                    baseColor 0.1 0.1 0.6
                                  }
                                  geometry DEF TIBIA_SHAPE Box {
                                    size 0.025 0.025 0.15
                                  }
                                }
                              ]
                              boundingObject USE TIBIA_SHAPE
                              physics Physics {
                              }
                            }
                            DEF ELBOW_SHAPE Shape {
                              appearance MattePaint {
                                baseColor 0 0 0
                              }
                              geometry Cylinder {
                                height 0.025
                                radius 0.0125
                              }
                            }
                          ]
                        }
                      ]
                      boundingObject USE ELBOW_SHAPE
                      physics Physics {
                      }
                      linearVelocity -1.165800201740858e-08 -3.87292028305535e-07 -5.930044099510731e-09
                      angularVelocity -2.249010740939363e-09 4.779405453801794e-07 4.4389417962554575e-08
                    }
                  }
                  DEF FEMUR_SHAPE Shape {
                    appearance MattePaint {
                      baseColor 0.2 0.2 1
                    }
                    geometry Box {
                      size 0.025 0.025 0.1
                    }
                  }
                ]
                boundingObject USE FEMUR_SHAPE
                physics Physics {
                }
              }
              Shape {
                appearance MattePaint {
                  baseColor 0 0 0
                }
                geometry DEF SHOULDER_SHAPE Sphere {
                  radius 0.02
                }
              }
            ]
          }
        ]
        name "solid(2)"
        boundingObject USE SHOULDER_SHAPE
        physics Physics {
        }
        linearVelocity -6.330271008418383e-08 -3.883858810536641e-07 -1.3253308307564183e-08
        angularVelocity -2.2664779509882538e-10 4.777400010641652e-07 4.345971445570189e-08
      }
    }
    Hinge2Joint {
      jointParameters HingeJointParameters {
        position 8.997281377204894e-06
      }
      jointParameters2 JointParameters {
        position 8.481823761556474e-06
      }
      device [
        DEF SHOULDER_4_x RotationalMotor {
          name "Hexabot_Leg4_Motor1"
        }
      ]
      device2 [
        DEF SHOULDER_4_y RotationalMotor {
          name "Hexabot_Leg4_Motor2"
        }
      ]
      endPoint DEF SHOULDER_0 Solid {
        translation -1.3799385393757057e-09 1.2948020277902479e-05 -0.05999996473306952
        rotation 0.7276429810147153 -3.0858697631687e-06 0.6859560424476894 1.2364983199523806e-05
        children [
          Transform {
            translation 0 0 -0.01
            children [
              DEF FEMUR_0 Solid {
                translation 0 0.0259808 -0.045
                rotation 1 0 0 0.523599
                children [
                  HingeJoint {
                    jointParameters HingeJointParameters {
                      position 4.785828655420721e-06
                    }
                    device [
                      DEF ELBOW_4 RotationalMotor {
                        name "Hexabot_Leg4_Motor3"
                      }
                    ]
                    endPoint Solid {
                      translation 0 2.871745250567568e-07 -0.059999999999312735
                      rotation 2.393123482202235e-06 2.393121042140123e-06 -0.9999999999942728 1.5707953071851353
                      children [
                        Transform {
                          children [
                            Solid {
                              translation 0.0824507 0 0.0210637
                              rotation 0 -1 0 1.8325953071795864
                              children [
                                Shape {
                                  appearance MattePaint {
                                    baseColor 0.1 0.1 0.6
                                  }
                                  geometry DEF TIBIA_SHAPE Box {
                                    size 0.025 0.025 0.15
                                  }
                                }
                              ]
                              boundingObject USE TIBIA_SHAPE
                              physics Physics {
                              }
                            }
                            DEF ELBOW_SHAPE Shape {
                              appearance MattePaint {
                                baseColor 0 0 0
                              }
                              geometry Cylinder {
                                height 0.025
                                radius 0.0125
                              }
                            }
                          ]
                        }
                      ]
                      boundingObject USE ELBOW_SHAPE
                      physics Physics {
                      }
                      linearVelocity -1.0382957676658895e-08 -3.9173646334257085e-07 1.1915466319696297e-09
                      angularVelocity 1.4991208338295508e-09 4.791704363610027e-07 4.370937701034103e-08
                    }
                  }
                  DEF FEMUR_SHAPE Shape {
                    appearance MattePaint {
                      baseColor 0.2 0.2 1
                    }
                    geometry Box {
                      size 0.025 0.025 0.1
                    }
                  }
                ]
                boundingObject USE FEMUR_SHAPE
                physics Physics {
                }
              }
              Shape {
                appearance MattePaint {
                  baseColor 0 0 0
                }
                geometry DEF SHOULDER_SHAPE Sphere {
                  radius 0.02
                }
              }
            ]
          }
        ]
        name "solid(1)"
        boundingObject USE SHOULDER_SHAPE
        physics Physics {
        }
        linearVelocity -5.9373615378151195e-08 -3.9224646216516953e-07 9.219576304478834e-09
        angularVelocity 1.4397541002217317e-09 4.789779348909956e-07 4.315418949653581e-08
      }
    }
    Hinge2Joint {
      jointParameters HingeJointParameters {
        position 9.352246513532522e-06
      }
      jointParameters2 JointParameters {
        position 8.987700145975666e-06
      }
      device [
        DEF SHOULDER_5_x RotationalMotor {
          name "Hexabot_Leg5_Motor1"
        }
      ]
      device2 [
        DEF SHOULDER_5_y RotationalMotor {
          name "Hexabot_Leg5_Motor2"
        }
      ]
      endPoint DEF SHOULDER_0 Solid {
        translation 0.07999999615578769 1.3812981608408812e-05 -0.05999995932898854
        rotation 0.7210196437476007 -3.240154178702628e-06 0.6929146219553923 1.2970859537913666e-05
        children [
          Transform {
            translation 0 0 -0.01
            children [
              DEF FEMUR_0 Solid {
                translation 0 0.0259808 -0.045
                rotation 1 0 0 0.523599
                children [
                  HingeJoint {
                    jointParameters HingeJointParameters {
                      position 5.261351056792351e-06
                    }
                    device [
                      DEF ELBOW_5 RotationalMotor {
                        name "Hexabot_Leg5_Motor3"
                      }
                    ]
                    endPoint Solid {
                      translation 0 3.1568106340618996e-07 -0.059999999999168996
                      rotation 2.6306782106619817e-06 2.6306755283840446e-06 -0.9999999999930794 1.5707953071864478
                      children [
                        Transform {
                          children [
                            Solid {
                              translation 0.0824507 0 0.0210637
                              rotation 0 -1 0 1.8325953071795864
                              children [
                                Shape {
                                  appearance MattePaint {
                                    baseColor 0.1 0.1 0.6
                                  }
                                  geometry DEF TIBIA_SHAPE Box {
                                    size 0.025 0.025 0.15
                                  }
                                }
                              ]
                              boundingObject USE TIBIA_SHAPE
                              physics Physics {
                              }
                            }
                            DEF ELBOW_SHAPE Shape {
                              appearance MattePaint {
                                baseColor 0 0 0
                              }
                              geometry Cylinder {
                                height 0.025
                                radius 0.0125
                              }
                            }
                          ]
                        }
                      ]
                      boundingObject USE ELBOW_SHAPE
                      physics Physics {
                      }
                      recognitionColors [
                        0 0 0
                      ]
                      linearVelocity -9.16992126658272e-09 -3.961583914149985e-07 8.325534183690369e-09
                      angularVelocity 5.257910853290351e-09 4.779867989349565e-07 4.308616214709288e-08
                    }
                  }
                  DEF FEMUR_SHAPE Shape {
                    appearance MattePaint {
                      baseColor 0.2 0.2 1
                    }
                    geometry Box {
                      size 0.025 0.025 0.1
                    }
                  }
                ]
                boundingObject USE FEMUR_SHAPE
                physics Physics {
                }
              }
              Shape {
                appearance MattePaint {
                  baseColor 0 0 0
                }
                geometry DEF SHOULDER_SHAPE Sphere {
                  radius 0.02
                }
              }
            ]
          }
        ]
        boundingObject USE SHOULDER_SHAPE
        physics Physics {
        }
        linearVelocity -5.5482334627107236e-08 -3.9609586445794554e-07 3.170167960040366e-08
        angularVelocity 3.1121499929535294e-09 4.777855219920152e-07 4.288101916408544e-08
      }
    }
  ]
  name "Hexabot"
  boundingObject USE BODY_TRAN
  physics Physics {
  }
  controller "my_controller_c"
  linearVelocity -1.0804097002429519e-07 -3.9287187760946866e-07 1.8429392658585373e-08
  angularVelocity 1.3856333101908028e-09 4.782837577832677e-07 4.268184561066571e-08
}
DEF dummy Solid {
  translation 2.9563150938025577 -0.0010273005904520634 -3.672864026527829
  rotation -0.7110748584059972 -0.05984334749870509 0.7005650001984401 -1.574390419526474
  children [
    DEF TEST_SHAPE Shape {
      appearance GenericTireAppearance {
      }
      geometry Capsule {
        height 0.1
        radius 0.05
      }
    }
  ]
  boundingObject USE TEST_SHAPE
  physics Physics {
  }
  locked TRUE
  linearVelocity 1.6963818304392082e-05 -1.6297954315055293e-09 -1.8839729454758262e-05
  angularVelocity -0.0003767945925271229 -7.931408910816145e-12 -0.00033927636227449356
}
DEF Terrain_Subway Group {
  children [
    Group {
      children [
        Rock10cm {
          translation 0.22508371862239604 -0.004258846412877913 -2.430740273241004
          rotation 0.5323030514449174 0.009193587961437641 -0.8465039511796888 -3.0420761580145426
          physics Physics {
          }
        }
        Rock10cm {
          translation -0.051725010822645315 -0.0028927287543592224 -2.557805076578908
          rotation -0.05055911906327704 0.9924366366716316 0.11186285206200186 -3.083565247433879
          name "rock 10 cm(1)"
          physics Physics {
          }
        }
        Rock10cm {
          translation 0.06777037275928531 -0.002892728754359226 -3.8538927585302845
          rotation -0.053895112628516956 0.9924430184289206 0.11023689040630938 3.1396051953722846
          name "rock 10 cm(2)"
          physics Physics {
          }
        }
        Rock10cm {
          translation 0.15914526792280698 -0.0028927287543592277 -2.587668962179001
          rotation -0.14373067214321464 0.987431015240838 0.06573799529729954 1.7777832843129333
          name "rock 10 cm(3)"
          physics Physics {
          }
        }
        Rock10cm {
          translation 0.11365974956804878 -0.00491154543679132 -2.4633326522777454
          rotation 0.6168722567691728 -0.48562926345447494 0.61938101141799 2.1545322607879482
          name "rock 10 cm(4)"
          physics Physics {
          }
        }
        Rock10cm {
          translation 0.1325955389984502 9.223630238055537e-05 -2.3223388778265925
          rotation 0.7586659017333074 0.16185632863731175 -0.6310535464025522 1.5523010110500282
          name "rock 10 cm(5)"
          physics Physics {
          }
        }
        Rock10cm {
          translation 0.39883859105252395 -0.0028927287543592146 -2.050761486253213
          rotation 0.47561417587347676 -0.8725052751607874 0.1119182760981971 -0.5077077559965734
          name "rock 10 cm(6)"
          physics Physics {
          }
        }
        Rock10cm {
          translation -0.20200558419287143 -0.009929320446820721 -2.2875914741340337
          rotation 0.514691729071699 0.06911283443205607 0.8545851860066099 2.925928568533312
          name "rock 10 cm(7)"
          physics Physics {
          }
        }
      ]
    }
    DEF Rail Solid {
      translation -0.12603621968953585 -0.003923713298997853 -3.536124645627568
      rotation 4.115212032330221e-06 0.9999999999915322 -1.7549264367810682e-08 0.001049742429970322
      children [
        Shape {
          appearance ThreadMetalPlate {
          }
          geometry DEF railShape Box {
            size 7.2 0.1 0.1
          }
        }
      ]
      name "rail(12)"
      boundingObject USE railShape
      physics Physics {
        mass 10
      }
      linearVelocity -8.027464460665063e-12 -2.297380561959409e-06 -1.5847772480939223e-09
      angularVelocity -3.168973118554331e-08 -4.30553462544651e-19 1.6051813629465186e-10
    }
    DEF Rail Solid {
      translation -0.12000000005289294 -0.003923999751327801 3.4760201028359403
      rotation -1.8916036776552617e-10 1 -3.046305388281488e-14 -1.1708602106461017e-06
      children [
        Shape {
          appearance ThreadMetalPlate {
          }
          geometry DEF railShape Box {
            size 7.2 0.1 0.1
          }
        }
      ]
      name "rail(11)"
      boundingObject USE railShape
      physics Physics {
        mass 10
      }
      linearVelocity 8.277165038958861e-20 -1.9926497316189666e-09 5.557495799344468e-17
      angularVelocity 1.2790088587784134e-15 -1.5085177554956456e-20 1.0526025816641463e-17
    }
    DEF Rail Solid {
      translation -10.39 -0.003923999751327799 3.47602
      rotation -1.3672806900651688e-10 1 -3.0432382116804283e-14 -1.1708602106459886e-06
      children [
        Shape {
          appearance ThreadMetalPlate {
          }
          geometry DEF railShape Box {
            size 7.2 0.1 0.1
          }
        }
      ]
      name "rail(2)"
      boundingObject USE railShape
      physics Physics {
        mass 10
      }
      linearVelocity -2.7594691243076726e-19 -1.992649686144502e-09 3.258573651526595e-17
      angularVelocity 8.526832173229424e-16 -2.4194965382424185e-18 1.0525526841454104e-17
    }
    DEF Rail Solid {
      translation -10.39 -0.003923999751327801 0.27602
      rotation 8.916768850785286e-12 1 -1.7416662459834065e-13 -1.1708602106475242e-06
      children [
        Shape {
          appearance ThreadMetalPlate {
          }
          geometry DEF railShape Box {
            size 7.2 0.1 0.1
          }
        }
      ]
      name "rail(3)"
      boundingObject USE railShape
      physics Physics {
        mass 10
      }
      linearVelocity 1.578398726926418e-18 -1.9926497770937352e-09 4.206516654656635e-18
      angularVelocity -8.527151517349336e-16 -1.3860232015157442e-18 -2.1050055732533504e-17
    }
    DEF Rail Solid {
      translation -10.39 -0.003923999751327801 -2.70398
      rotation 3.934189836637032e-10 1 -6.054000238098637e-13 -1.170860210646063e-06
      children [
        Shape {
          appearance ThreadMetalPlate {
          }
          geometry DEF railShape Box {
            size 7.2 0.1 0.1
          }
        }
      ]
      name "rail(6)"
      boundingObject USE railShape
      physics Physics {
        mass 10
      }
      linearVelocity -5.834514149238919e-19 -1.9926497316191626e-09 -7.433949080730877e-17
      angularVelocity -2.131596272865387e-15 2.8327566952238434e-18 1.0522034015142601e-17
    }
    DEF Rail Solid {
      translation 3.5300015845560324 -0.003923999751327808 -0.023458884943641407
      rotation -4.669393992950032e-17 1 -4.6612701756035074e-17 -1.57079586967923
      children [
        Shape {
          appearance ThreadMetalPlate {
          }
          geometry DEF railShape Box {
            size 7.1 0.1 0.1
          }
        }
      ]
      name "rail(10)"
      boundingObject USE railShape
      physics Physics {
        mass 10
      }
      linearVelocity 6.755341421194589e-17 -1.992649777093893e-09 -3.323974041796205e-19
      angularVelocity -1.9202170418422395e-33 -2.1609765521991174e-19 4.388038785291878e-30
    }
    DEF Rail Solid {
      translation -5.71 -0.003923999751327805 -0.0234555
      rotation 2.8396154108160827e-16 1 2.843889649641748e-16 -1.57079586967923
      children [
        Shape {
          appearance ThreadMetalPlate {
          }
          geometry DEF railShape Box {
            size 7.1 0.1 0.1
          }
        }
      ]
      name "rail(13)"
      boundingObject USE railShape
      physics Physics {
        mass 10
      }
      linearVelocity 3.185795597958013e-16 -1.9926496406695384e-09 6.655364426653777e-19
      angularVelocity 1.0820295793961626e-17 -2.119629972684165e-18 -5.968546513002664e-15
    }
    DEF Rail Solid {
      translation -6.4 -0.003923999751327803 -0.0234555
      rotation 6.55717670299367e-16 1 6.561449243812358e-16 -1.57079586967923
      children [
        Shape {
          appearance ThreadMetalPlate {
          }
          geometry DEF railShape Box {
            size 7.1 0.1 0.1
          }
        }
      ]
      name "rail(14)"
      boundingObject USE railShape
      physics Physics {
        mass 10
      }
      linearVelocity 1.8917585728906908e-17 -1.992649686144568e-09 8.875316862052704e-19
      angularVelocity -1.9480282704319064e-22 2.259357900949921e-18 -4.263256414559701e-16
    }
    DEF Rail2 Solid {
      translation -0.4777417872478905 -0.00391050845475556 -2.756148633387383
      rotation 0.5569090285640201 -0.8305626593081522 -0.004242978535120554 -0.017178075273251627
      children [
        Shape {
          appearance ThreadMetalPlate {
          }
          geometry DEF railShape Box {
            size 6.6 0.1 0.1
          }
        }
      ]
      name "rail(9)"
      boundingObject USE railShape
      physics Physics {
        mass 10
      }
      linearVelocity -2.9986802800952017e-07 4.6567558274546243e-08 -1.519652289931486e-05
      angularVelocity 0.0006212581231441502 1.3633119317595361e-05 -8.934873168877446e-06
    }
    DEF Rail2 Solid {
      translation -0.4799714410599952 -0.003933539905089245 2.7867432650271886
      rotation 0.7179999112401638 -0.6960430366033028 0.00046760578531435717 0.004358841341485556
      children [
        Shape {
          appearance ThreadMetalPlate {
          }
          geometry DEF railShape Box {
            size 6.6 0.1 0.1
          }
        }
      ]
      name "rail(8)"
      boundingObject USE railShape
      physics Physics {
        mass 10
      }
      linearVelocity -1.0315277136343505e-07 1.0647955037711649e-06 1.59258678582944e-05
      angularVelocity -6.681478388679208e-05 -5.704539724669593e-06 1.066279380897428e-07
    }
    DEF Rail2 Solid {
      translation -10.59999957454626 -0.003923713118345179 2.756083592843671
      rotation -2.86668066108054e-12 -1 -6.324690859115206e-16 0.0029927885287647366
      children [
        Shape {
          appearance ThreadMetalPlate {
          }
          geometry DEF railShape Box {
            size 6.6 0.1 0.1
          }
        }
      ]
      name "rail(1)"
      boundingObject USE railShape
      physics Physics {
        mass 10
      }
      linearVelocity 1.0328376016047752e-19 -2.2988281605643243e-06 2.6975006290329588e-17
      angularVelocity -2.5397080658937103e-16 2.3588860229728234e-18 -7.022090334604017e-18
    }
    DEF Rail2 Solid {
      translation -10.590599574546275 -0.003923713118345181 -0.5539054071519056
      rotation -2.891282122936129e-12 -1 1.3820017226638103e-17 0.0029927885304120343
      children [
        Shape {
          appearance ThreadMetalPlate {
          }
          geometry DEF railShape Box {
            size 6.6 0.1 0.1
          }
        }
      ]
      name "rail(4)"
      boundingObject USE railShape
      physics Physics {
        mass 10
      }
      linearVelocity -1.4995214281179635e-19 -2.298828160519279e-06 5.4528422473296894e-18
      angularVelocity 1.3154112384723698e-16 2.557625247301433e-18 -1.2131216876982117e-17
    }
    DEF Rail2 Solid {
      translation -10.582699574546261 -0.0039237131183451745 -3.5038964071565686
      rotation -2.9573756641067377e-12 -1 -1.4260598995482736e-16 0.0029927885314647903
      children [
        Shape {
          appearance ThreadMetalPlate {
          }
          geometry DEF railShape Box {
            size 6.6 0.1 0.1
          }
        }
      ]
      name "rail(5)"
      boundingObject USE railShape
      physics Physics {
        mass 10
      }
      linearVelocity -7.24130691735237e-19 -2.298828160518745e-06 -4.660850990294041e-17
      angularVelocity -5.578629485324507e-16 6.0207745779711726e-18 1.0855907681016553e-17
    }
    DEF Rail2 Solid {
      translation 2.770035268535714 -0.003930484189570679 -0.003087325934911433
      rotation 6.791491089860034e-05 0.9999999958577461 6.059762846636775e-05 -1.5707981380171592
      children [
        Shape {
          appearance ThreadMetalPlate {
          }
          geometry DEF railShape Box {
            size 5.5 0.1 0.1
          }
        }
      ]
      name "rail(7)"
      boundingObject USE railShape
      physics Physics {
        mass 10
      }
      linearVelocity -1.071288972510853e-07 -8.092586915608989e-07 2.7007309748873354e-05
      angularVelocity 3.139034136309301e-07 -6.281840587284393e-08 1.888237094042129e-05
    }
    DEF wall1 Solid {
      translation 0.34506650258915933 2.6626830204391005 4.649214288573813
      rotation -0.8588222497819817 0.49177268423353504 -0.14347114804433383 -0.0033063456486497763
      children [
        Shape {
          appearance StonePavement {
          }
          geometry Box {
            size 9.25 5.5 0.75
          }
        }
      ]
      name "wall1(5)"
      boundingObject Shape {
        appearance StonePavement {
        }
        geometry Box {
          size 9.25 5.5 0.75
        }
      }
      physics Physics {
        mass 108
      }
      linearVelocity 6.06392121107901e-05 -0.00032559337915565137 -0.0003571699097322598
      angularVelocity 2.7324809985826266e-05 -2.736785481739559e-05 -2.1039147893554736e-05
    }
    DEF wall1 Solid {
      translation -14.564430450161973 2.658678530351356 0.3825864623394759
      rotation -0.004496171362403591 0.9999777794283052 -0.004921899299616473 -1.5658406246787884
      children [
        Shape {
          appearance StonePavement {
          }
          geometry Box {
            size 9.25 5.5 0.75
          }
        }
      ]
      name "wall1(6)"
      boundingObject Shape {
        appearance StonePavement {
        }
        geometry Box {
          size 9.25 5.5 0.75
        }
      }
      physics Physics {
        mass 108
      }
      linearVelocity 0.0003831627177886418 -0.00011676345485998523 -0.00025674837251071564
      angularVelocity 4.823493410274694e-05 4.190476219933735e-05 -0.0004854862779221934
    }
    DEF wall1_5 Solid {
      translation -9.868172761459798 2.659517670085562 -4.619385218913546
      rotation -0.82659935264354 0.4796422057859197 -0.29440934876137714 -0.0022997101599148903
      children [
        Shape {
          appearance StonePavement {
          }
          geometry Box {
            size 9.75 5.5 0.75
          }
        }
      ]
      name "wall1(7)"
      boundingObject Shape {
        appearance StonePavement {
        }
        geometry DEF Wall1_5Shape Box {
          size 9.75 5.5 0.75
        }
      }
      physics Physics {
        mass 108
      }
      linearVelocity -0.00019217444747017808 -0.00020454884529074946 -4.827777624478549e-05
      angularVelocity -7.968720664457054e-05 1.3263396767944456e-05 -4.1308663676559833e-05
    }
    DEF wall1_5 Solid {
      translation -9.203970001217215 2.6575848908686237 4.61295586762194
      rotation -0.9999999993067189 3.72364493174254e-05 -9.491688290254346e-08 -0.0050980519993586645
      children [
        Shape {
          appearance StonePavement {
          }
          geometry Box {
            size 9.75 5.5 0.75
          }
        }
      ]
      name "wall1(2)"
      boundingObject Shape {
        appearance StonePavement {
        }
        geometry DEF Wall1_5Shape Box {
          size 9.75 5.5 0.75
        }
      }
      physics Physics {
        mass 108
      }
      linearVelocity -1.239152768430616e-10 -3.354867617193488e-06 0.0006527567671518869
      angularVelocity 0.000236579943757231 -3.943455265744463e-19 4.491086058445185e-11
    }
    DEF wall3 Solid {
      translation -10.558510044483523 2.6588283814139846 1.3221503238318908
      rotation 0.7574670230906706 0.6379705503804246 0.13869854280941596 -0.002470956622748556
      children [
        Shape {
          appearance StonePavement {
          }
          geometry DEF wall3shape Box {
            size 7.25 5.5 0.75
          }
        }
      ]
      name "wall1(1)"
      boundingObject USE wall3shape
      physics Physics {
        mass 108
      }
      linearVelocity 0.0006116105289664042 -0.00022934033229911514 0.0001181005078148093
      angularVelocity 8.195859984893032e-05 -2.750348218612999e-05 6.466124084680975e-05
    }
    DEF wall3 Solid {
      translation -10.559911324485746 2.6577901871910155 -1.6233088333101358
      rotation 0.9526701886692777 0.30371619758966184 0.013265856267897771 -0.004389616920290318
      children [
        Shape {
          appearance StonePavement {
          }
          geometry DEF wall3shape Box {
            size 7.25 5.5 0.75
          }
        }
      ]
      name "wall1(8)"
      boundingObject USE wall3shape
      physics Physics {
        mass 108
      }
      linearVelocity 0.0003527218580720371 1.1682501388484692e-05 0.002240070636882947
      angularVelocity 0.0008185427500303461 -9.440547222359137e-07 5.813047928939298e-07
    }
    DEF wall2 Solid {
      translation -4.640872530159867 2.657798772603779 -1.0923169564298538
      rotation 0.0013113777642508268 -0.9999981954090563 0.001374578841118533 1.572569856288412
      children [
        Shape {
          appearance StonePavement {
          }
          geometry DEF Wall2Shape Box {
            size 6.25 5.5 0.75
          }
        }
      ]
      name "wall2(1)"
      boundingObject USE Wall2Shape
      physics Physics {
        mass 108
      }
      linearVelocity -7.740753277818915e-05 -1.0088365146169674e-05 1.0477757763828187e-05
      angularVelocity 3.2183102985523507e-06 -1.6460634837121597e-05 9.289410216743124e-06
    }
    DEF wall3 Solid {
      translation -0.3739541807614398 2.6558470206821165 -4.6273299903709395
      rotation -0.451145708003525 0.8042955184877 0.38675091349678786 -0.0005196918949207385
      children [
        Shape {
          appearance StonePavement {
          }
          geometry Box {
            size 9.25 5.5 0.75
          }
        }
      ]
      name "wall1(4)"
      boundingObject Shape {
        appearance StonePavement {
        }
        geometry Box {
          size 9.25 5.5 0.75
        }
      }
      physics Physics {
        mass 108
      }
      linearVelocity 0.00025001396788436374 5.180526307493793e-05 -0.0001476470258043694
      angularVelocity -9.131424370140873e-05 1.9333863425744106e-05 1.5443382672363315e-05
    }
    DEF wall4 Solid {
      translation 4.611102295296987 2.65782534832723 -0.3352241002170779
      rotation 0.0004134370328903857 0.9999999020049359 0.00015830331062992566 -1.5743872349979207
      children [
        Shape {
          appearance StonePavement {
          }
          geometry Box {
            size 9.25 5.5 0.75
          }
        }
      ]
      name "wall1(3)"
      boundingObject Shape {
        appearance StonePavement {
        }
        geometry Box {
          size 9.25 5.5 0.75
        }
      }
      physics Physics {
        mass 108
      }
      linearVelocity 9.293349887281387e-05 -0.00014068933027556338 -0.0004640466354847972
      angularVelocity 5.533536094952918e-05 -2.8599463717775742e-06 -2.3603882144251558e-05
    }
    DEF wall5 Solid {
      translation -1.1162898749596117 2.6574328727541356 0.10479513472177202
      rotation -0.007061551691715333 0.9999646935675924 -0.004554789344883132 -0.013458368582399223
      children [
        DEF wall5 Shape {
          appearance StonePavement {
          }
          geometry Box {
            size 6.25 5.5 4
          }
        }
      ]
      name "wall5(1)"
      boundingObject USE wall5
      physics Physics {
        mass 108
      }
      linearVelocity 6.0999634282686185e-05 9.960182506475803e-06 -1.5606443634453022e-05
      angularVelocity -5.039963448624574e-06 6.8812101294526765e-06 -3.2855876997830048e-06
    }
  ]
}
