#VRML_SIM R2020a utf8
WorldInfo {
  basicTimeStep 8
}
Robot {
  translation -2.2230839564303047 0.29786014905369423 -0.4727247906199888
  rotation 0.040256900931296316 0.9991544744106914 -0.00834974206204679 -0.4882891956037564
  children [
    Display {
      name "Lidar_Display"
    }
    HokuyoUtm30lx {
      translation 0 0.1 0
      rotation 0 1 0 -1.5708
    }
    Compass {
      name "Hexabot_Compass"
    }
    Gyro {
      name "Hexabot_Gyro"
    }
    GPS {
      name "Hexabot_GPS"
    }
    Camera {
      translation 0.1 -1.12008e-13 -1.49482e-07
      rotation 8.684229999951365e-07 -0.9999999999943995 3.2321499999818985e-06 1.5707853071795865
      children [
        DEF CAM_SHAPE Shape {
          appearance MattePaint {
            baseColor 0.7 0.1 0.1
          }
          geometry Cylinder {
            height 0.05
            radius 0.0125
          }
        }
      ]
      name "Hexabot_Camera"
      boundingObject USE CAM_SHAPE
      physics Physics {
      }
      lens Lens {
      }
      focus Focus {
      }
      recognition Recognition {
      }
    }
    DEF BODY_TRAN Transform {
      children [
        DEF BODY Shape {
          appearance MattePaint {
            baseColor 0.1 0.1 0.7
          }
          geometry Box {
            size 0.2 0.05 0.125
          }
        }
      ]
    }
    Hinge2Joint {
      jointParameters HingeJointParameters {
        position -0.06798130756925067
      }
      jointParameters2 JointParameters {
        position -0.29566278244328886
        axis 0 1 0
      }
      device [
        DEF SHOULDER_2_x RotationalMotor {
          name "Hexabot_Leg0_Motor1"
        }
      ]
      device2 [
        DEF SHOULDER_0_y RotationalMotor {
          name "Hexabot_Leg0_Motor2"
        }
      ]
      endPoint DEF SHOULDER_0 Solid {
        translation 0.07554890261918476 -0.008246630363200495 0.054489554233719796
        rotation 0.9939850056776617 -0.0069013933096989 -0.10929857848281335 2.0071405471130745
        children [
          Transform {
            children [
              DEF FEMUR_0 Solid {
                translation 0 0.025981 -0.0450019
                rotation 1 0 0 0.523599
                children [
                  HingeJoint {
                    jointParameters HingeJointParameters {
                      position -0.2201649538601267
                      axis 0 0 1
                    }
                    device [
                      DEF ELBOW_0 RotationalMotor {
                        name "Hexabot_Leg0_Motor3"
                      }
                    ]
                    endPoint Solid {
                      translation -0.00012550849650094288 -0.0007246407848547753 -0.0585639024163616
                      rotation -0.6933597328502711 -0.7061808123254191 -0.14339086848614913 2.816439134077731
                      children [
                        Transform {
                          children [
                            Solid {
                              translation 0.0824507 0 0.0210637
                              rotation 0 -1 0 1.8325953071795864
                              children [
                                Shape {
                                  appearance MattePaint {
                                    baseColor 0.1 0.1 0.6
                                  }
                                  geometry DEF TIBIA_SHAPE Box {
                                    size 0.025 0.025 0.15
                                  }
                                }
                              ]
                              boundingObject USE TIBIA_SHAPE
                              physics Physics {
                              }
                            }
                            DEF ELBOW_SHAPE Shape {
                              appearance MattePaint {
                                baseColor 0 0 0
                              }
                              geometry Cylinder {
                                height 0.025
                                radius 0.0125
                              }
                            }
                          ]
                        }
                      ]
                      boundingObject USE ELBOW_SHAPE
                      physics Physics {
                      }
                      linearVelocity 0.018704238007220854 0.007253403141514141 0.01423549236201424
                      angularVelocity 0.25533237525577607 -0.20505416310534869 -0.04112754743334487
                    }
                  }
                  DEF FEMUR_SHAPE Shape {
                    appearance MattePaint {
                      baseColor 0.2 0.2 1
                    }
                    geometry Box {
                      size 0.025 0.025 0.1
                    }
                  }
                ]
                boundingObject USE FEMUR_SHAPE
                physics Physics {
                }
              }
              Shape {
                appearance MattePaint {
                  baseColor 0 0 0
                }
                geometry DEF SHOULDER_SHAPE Sphere {
                  radius 0.02
                }
              }
            ]
          }
        ]
        name "solid(5)"
        boundingObject USE SHOULDER_SHAPE
        physics Physics {
        }
        linearVelocity 0.03753969603308961 0.02812667184993004 0.02703220906359505
        angularVelocity 0.2227692811384653 -0.11572346483275586 0.07855748537001743
      }
    }
    Hinge2Joint {
      jointParameters HingeJointParameters {
        position 0.4679806232426418
      }
      jointParameters2 JointParameters {
        position -0.10433815167014665
        axis 0 1 0
      }
      device [
        DEF SHOULDER_2_x RotationalMotor {
          name "Hexabot_Leg1_Motor1"
        }
      ]
      device2 [
        DEF SHOULDER_0_y RotationalMotor {
          name "Hexabot_Leg1_Motor2"
        }
      ]
      endPoint DEF SHOULDER_0 Solid {
        translation 0.004644090858942131 -0.017779309582380033 0.05694817647379786
        rotation 0.9908578802311624 0.08547846089618204 -0.10437477619917267 1.7521253247584383
        children [
          Transform {
            children [
              DEF FEMUR_0 Solid {
                translation 0 0.025981 -0.0450019
                rotation 1 0 0 0.523599
                children [
                  HingeJoint {
                    jointParameters HingeJointParameters {
                      position -0.37983500029913025
                      axis 0 0 1
                    }
                    device [
                      DEF ELBOW_0 RotationalMotor {
                        name "Hexabot_Leg1_Motor3"
                      }
                    ]
                    endPoint Solid {
                      translation -0.00022805617676406503 -0.0005841470880601995 -0.05861795080600524
                      rotation -0.7460678893361208 -0.6474362281213462 -0.15559252879733682 2.840127242193215
                      children [
                        Transform {
                          children [
                            Solid {
                              translation 0.0824507 0 0.0210637
                              rotation 0 -1 0 1.8325953071795864
                              children [
                                Shape {
                                  appearance MattePaint {
                                    baseColor 0.1 0.1 0.6
                                  }
                                  geometry DEF TIBIA_SHAPE Box {
                                    size 0.025 0.025 0.15
                                  }
                                }
                              ]
                              boundingObject USE TIBIA_SHAPE
                              physics Physics {
                              }
                            }
                            DEF ELBOW_SHAPE Shape {
                              appearance MattePaint {
                                baseColor 0 0 0
                              }
                              geometry Cylinder {
                                height 0.025
                                radius 0.0125
                              }
                            }
                          ]
                        }
                      ]
                      boundingObject USE ELBOW_SHAPE
                      physics Physics {
                      }
                      linearVelocity 0.05519287206084374 0.09413240167555337 0.016732547742325108
                      angularVelocity -0.24470030407484944 0.06566601758043333 -0.04926345450031995
                    }
                  }
                  DEF FEMUR_SHAPE Shape {
                    appearance MattePaint {
                      baseColor 0.2 0.2 1
                    }
                    geometry Box {
                      size 0.025 0.025 0.1
                    }
                  }
                ]
                boundingObject USE FEMUR_SHAPE
                physics Physics {
                }
              }
              Shape {
                appearance MattePaint {
                  baseColor 0 0 0
                }
                geometry DEF SHOULDER_SHAPE Sphere {
                  radius 0.02
                }
              }
            ]
          }
        ]
        name "solid(4)"
        boundingObject USE SHOULDER_SHAPE
        physics Physics {
        }
        linearVelocity 0.04878465463087018 0.0699845349226518 0.016551971077892486
        angularVelocity -0.2179347984193152 -0.0534556878310889 -0.14123430150916394
      }
    }
    Hinge2Joint {
      jointParameters HingeJointParameters {
        position 1.1319143676109504
      }
      jointParameters2 JointParameters {
        position -0.29565672911721913
        axis 0 1 0
      }
      device [
        DEF SHOULDER_2_x RotationalMotor {
          name "Hexabot_Leg2_Motor1"
        }
      ]
      device2 [
        DEF SHOULDER_0_y RotationalMotor {
          name "Hexabot_Leg2_Motor2"
        }
      ]
      endPoint DEF SHOULDER_0 Solid {
        translation -0.08916424991946147 0.009629731320514465 0.04736759887927177
        rotation 0.991488228669132 -0.0934696884227252 -0.09063393270020746 2.2235910058926476
        children [
          Transform {
            children [
              DEF FEMUR_0 Solid {
                translation 0 0.025981 -0.0450019
                rotation 1 0 0 0.523599
                children [
                  HingeJoint {
                    jointParameters HingeJointParameters {
                      position -0.2201633757833534
                      axis 0 0 1
                    }
                    device [
                      DEF ELBOW_0 RotationalMotor {
                        name "Hexabot_Leg2_Motor3"
                      }
                    ]
                    endPoint Solid {
                      translation -0.0001274399284053072 -0.0006886698598348972 -0.05857588456507886
                      rotation -0.6984921289944952 -0.7137921572597019 -0.051083284617168045 3.0023643989571975
                      children [
                        Transform {
                          children [
                            Solid {
                              translation 0.0824507 0 0.0210637
                              rotation 0 -1 0 1.8325953071795864
                              children [
                                Shape {
                                  appearance MattePaint {
                                    baseColor 0.1 0.1 0.6
                                  }
                                  geometry DEF TIBIA_SHAPE Box {
                                    size 0.025 0.025 0.15
                                  }
                                }
                              ]
                              boundingObject USE TIBIA_SHAPE
                              physics Physics {
                              }
                            }
                            DEF ELBOW_SHAPE Shape {
                              appearance MattePaint {
                                baseColor 0 0 0
                              }
                              geometry Cylinder {
                                height 0.025
                                radius 0.0125
                              }
                            }
                          ]
                        }
                      ]
                      boundingObject USE ELBOW_SHAPE
                      physics Physics {
                      }
                      linearVelocity 0.030096614217425304 0.015622293719585907 -0.0026388068020528153
                      angularVelocity 0.2849470636924085 -0.15621495782231043 -0.08487336501286494
                    }
                  }
                  DEF FEMUR_SHAPE Shape {
                    appearance MattePaint {
                      baseColor 0.2 0.2 1
                    }
                    geometry Box {
                      size 0.025 0.025 0.1
                    }
                  }
                ]
                boundingObject USE FEMUR_SHAPE
                physics Physics {
                }
              }
              Shape {
                appearance MattePaint {
                  baseColor 0 0 0
                }
                geometry DEF SHOULDER_SHAPE Sphere {
                  radius 0.02
                }
              }
            ]
          }
        ]
        name "solid(3)"
        boundingObject USE SHOULDER_SHAPE
        physics Physics {
        }
        linearVelocity 0.04742231660560258 0.037594482086027864 0.015034494662231798
        angularVelocity 0.23981887570412774 -0.0963058322238469 0.04831810794565
      }
    }
    Hinge2Joint {
      jointParameters HingeJointParameters {
        position -0.13128134576827694
      }
      jointParameters2 JointParameters {
        position -0.26928929827601683
        axis 0 1 0
      }
      device [
        DEF SHOULDER_3_x RotationalMotor {
          name "Hexabot_Leg3_Motor1"
        }
      ]
      device2 [
        DEF SHOULDER_3_y RotationalMotor {
          name "Hexabot_Leg3_Motor2"
        }
      ]
      endPoint DEF SHOULDER_0 Solid {
        translation -0.08590883512830753 0.0040370352776938016 -0.046107207343027486
        rotation -0.9983738591814079 -0.05682447494477392 0.00454052314974636 0.13149806321025972
        children [
          Transform {
            translation 0 0 -0.01
            children [
              DEF FEMUR_0 Solid {
                translation 0 0.0259808 -0.045
                rotation 1 0 0 0.523599
                children [
                  HingeJoint {
                    jointParameters HingeJointParameters {
                      position -0.2708870006116019
                      axis 0 0 1
                    }
                    device [
                      DEF ELBOW_3 RotationalMotor {
                        name "Hexabot_Leg3_Motor3"
                      }
                    ]
                    endPoint Solid {
                      translation -9.964757572654563e-06 -2.3106051144887867e-05 -0.060020559987987145
                      rotation 3.9470500579525476e-05 5.2654302381359875e-05 -0.999999997834802 1.5798853934464263
                      children [
                        Transform {
                          children [
                            Solid {
                              translation 0.0824507 0 0.0210637
                              rotation 0 -1 0 1.8325953071795864
                              children [
                                Shape {
                                  appearance MattePaint {
                                    baseColor 0.1 0.1 0.6
                                  }
                                  geometry DEF TIBIA_SHAPE Box {
                                    size 0.025 0.025 0.15
                                  }
                                }
                              ]
                              boundingObject USE TIBIA_SHAPE
                              physics Physics {
                              }
                            }
                            DEF ELBOW_SHAPE Shape {
                              appearance MattePaint {
                                baseColor 0 0 0
                              }
                              geometry Cylinder {
                                height 0.025
                                radius 0.0125
                              }
                            }
                          ]
                        }
                      ]
                      boundingObject USE ELBOW_SHAPE
                      physics Physics {
                      }
                      linearVelocity 0.013351677664467394 0.009867539837868209 0.018129843105448053
                      angularVelocity -0.09837865439447631 0.17604206509676634 -0.3845812773577371
                    }
                  }
                  DEF FEMUR_SHAPE Shape {
                    appearance MattePaint {
                      baseColor 0.2 0.2 1
                    }
                    geometry Box {
                      size 0.025 0.025 0.1
                    }
                  }
                ]
                boundingObject USE FEMUR_SHAPE
                physics Physics {
                }
              }
              Shape {
                appearance MattePaint {
                  baseColor 0 0 0
                }
                geometry DEF SHOULDER_SHAPE Sphere {
                  radius 0.02
                }
              }
            ]
          }
        ]
        name "solid(2)"
        boundingObject USE SHOULDER_SHAPE
        physics Physics {
        }
        linearVelocity 0.044133163102845326 0.032876993667518506 0.0204679189614023
        angularVelocity -0.20701773385989847 0.08537616871022013 -0.1816128549366082
      }
    }
    Hinge2Joint {
      jointParameters HingeJointParameters {
        position 0.031281739967537504
      }
      jointParameters2 JointParameters {
        position -0.13071249717943978
        axis 0 1 0
      }
      device [
        DEF SHOULDER_4_x RotationalMotor {
          name "Hexabot_Leg4_Motor1"
        }
      ]
      device2 [
        DEF SHOULDER_4_y RotationalMotor {
          name "Hexabot_Leg4_Motor2"
        }
      ]
      endPoint DEF SHOULDER_0 Solid {
        translation -0.013308947197701987 0.0016418593597581398 -0.05217265070715754
        rotation 0.23242243421984657 -0.9724959688630692 -0.015211923494456598 0.13439832769155372
        children [
          Transform {
            translation 0 0 -0.01
            children [
              DEF FEMUR_0 Solid {
                translation 0 0.0259808 -0.045
                rotation 1 0 0 0.523599
                children [
                  HingeJoint {
                    jointParameters HingeJointParameters {
                      position 0.07088730199510332
                      axis 0 0 1
                    }
                    device [
                      DEF ELBOW_4 RotationalMotor {
                        name "Hexabot_Leg4_Motor3"
                      }
                    ]
                    endPoint Solid {
                      translation -1.756939155237487e-12 2.4743434167129343e-11 -0.05999999999999947
                      rotation 2.0671466455894128e-10 2.2191293782987331e-10 -1 1.4999080051843303
                      children [
                        Transform {
                          children [
                            Solid {
                              translation 0.0824507 0 0.0210637
                              rotation 0 -1 0 1.8325953071795864
                              children [
                                Shape {
                                  appearance MattePaint {
                                    baseColor 0.1 0.1 0.6
                                  }
                                  geometry DEF TIBIA_SHAPE Box {
                                    size 0.025 0.025 0.15
                                  }
                                }
                              ]
                              boundingObject USE TIBIA_SHAPE
                              physics Physics {
                              }
                            }
                            DEF ELBOW_SHAPE Shape {
                              appearance MattePaint {
                                baseColor 0 0 0
                              }
                              geometry Cylinder {
                                height 0.025
                                radius 0.0125
                              }
                            }
                          ]
                        }
                      ]
                      boundingObject USE ELBOW_SHAPE
                      physics Physics {
                      }
                      linearVelocity 0.10554064599191047 0.09408731429239711 0.05085691783259539
                      angularVelocity 0.11100215509830905 -0.3797649413391296 0.25211815197726406
                    }
                  }
                  DEF FEMUR_SHAPE Shape {
                    appearance MattePaint {
                      baseColor 0.2 0.2 1
                    }
                    geometry Box {
                      size 0.025 0.025 0.1
                    }
                  }
                ]
                boundingObject USE FEMUR_SHAPE
                physics Physics {
                }
              }
              Shape {
                appearance MattePaint {
                  baseColor 0 0 0
                }
                geometry DEF SHOULDER_SHAPE Sphere {
                  radius 0.02
                }
              }
            ]
          }
        ]
        name "solid(1)"
        boundingObject USE SHOULDER_SHAPE
        physics Physics {
        }
        linearVelocity 0.07057335045173319 0.07159690251460729 0.032793748465282255
        angularVelocity 0.23335674094408906 -0.2531409228553072 0.07829482442314997
      }
    }
    Hinge2Joint {
      jointParameters HingeJointParameters {
        position -0.03127936451100641
      }
      jointParameters2 JointParameters {
        position -0.26928724377713953
        axis 0 1 0
      }
      device [
        DEF SHOULDER_5_x RotationalMotor {
          name "Hexabot_Leg5_Motor1"
        }
      ]
      device2 [
        DEF SHOULDER_5_y RotationalMotor {
          name "Hexabot_Leg5_Motor2"
        }
      ]
      endPoint DEF SHOULDER_0 Solid {
        translation 0.09307951301947559 -0.0011306744099393124 -0.03653656424242835
        rotation -0.11468688144905038 -0.9932802003873743 0.015535853433558339 0.2710868838935906
        children [
          Transform {
            translation 0 0 -0.01
            children [
              DEF FEMUR_0 Solid {
                translation 0 0.0259808 -0.045
                rotation 1 0 0 0.523599
                children [
                  HingeJoint {
                    jointParameters HingeJointParameters {
                      position 0.1291128956345326
                      axis 0 0 1
                    }
                    device [
                      DEF ELBOW_5 RotationalMotor {
                        name "Hexabot_Leg5_Motor3"
                      }
                    ]
                    endPoint Solid {
                      translation 2.0448615113235338e-23 -1.5749675075314228e-22 -0.06000000000000022
                      rotation -1.2238229566965238e-20 -4.649243954982105e-21 -1 1.4416824115450166
                      children [
                        Transform {
                          children [
                            Solid {
                              translation 0.0824507 0 0.0210637
                              rotation 0 -1 0 1.8325953071795864
                              children [
                                Shape {
                                  appearance MattePaint {
                                    baseColor 0.1 0.1 0.6
                                  }
                                  geometry DEF TIBIA_SHAPE Box {
                                    size 0.025 0.025 0.15
                                  }
                                }
                              ]
                              boundingObject USE TIBIA_SHAPE
                              physics Physics {
                              }
                            }
                            DEF ELBOW_SHAPE Shape {
                              appearance MattePaint {
                                baseColor 0 0 0
                              }
                              geometry Cylinder {
                                height 0.025
                                radius 0.0125
                              }
                            }
                          ]
                        }
                      ]
                      boundingObject USE ELBOW_SHAPE
                      physics Physics {
                      }
                      recognitionColors [
                        0 0 0
                      ]
                      linearVelocity 0.029012951652002905 -0.000408861680987166 -0.004886309347419306
                      angularVelocity -0.06605682806595074 0.2011439251658068 -0.3277141265746453
                    }
                  }
                  DEF FEMUR_SHAPE Shape {
                    appearance MattePaint {
                      baseColor 0.2 0.2 1
                    }
                    geometry Box {
                      size 0.025 0.025 0.1
                    }
                  }
                ]
                boundingObject USE FEMUR_SHAPE
                physics Physics {
                }
              }
              Shape {
                appearance MattePaint {
                  baseColor 0 0 0
                }
                geometry DEF SHOULDER_SHAPE Sphere {
                  radius 0.02
                }
              }
            ]
          }
        ]
        boundingObject USE SHOULDER_SHAPE
        physics Physics {
        }
        linearVelocity 0.05239528392355179 0.02602055676479168 0.006267978094375446
        angularVelocity -0.2150643713637107 0.08707645776118304 -0.16645754885757968
      }
    }
  ]
  name "Hexabot(1)"
  boundingObject USE BODY_TRAN
  physics Physics {
  }
  controller "my_controller_c"
  linearVelocity 0.0521146287568078 0.049941876867259934 0.020437540295544482
  angularVelocity 0.006686739465242317 -0.08293651398990176 -0.039443763913028
}
Viewpoint {
  orientation -0.28800623026392236 -0.8895913956152434 -0.35451313117638955 1.887832834495092
  position -4.767545550237557 3.367304395155548 -1.3674591092907542
}
TexturedBackground {
}
TexturedBackgroundLight {
}
RectangleArena {
  floorSize 10 10
  floorTileSize 1 1
  wallThickness 0.025
  wallHeight 2
}
DEF Cave_system Group {
  children [
    Wall {
      translation -4.04556 -0.08 -2.02135
      rotation 0 1 0 2.87979
      size 2 1 0.15
      appearance DEF SAND Sand {
      }
    }
    Wall {
      translation -4.15892 -0.08 -4.22603
      rotation 0 1 0 2.87979
      name "wall(3)"
      size 2 1 0.15
      appearance DEF SAND Sand {
      }
    }
    Wall {
      translation -2.51674 -0.08 -3.78592
      rotation 0 1 0 2.87979
      name "wall(5)"
      size 2 1 0.15
      appearance DEF SAND Sand {
      }
    }
    Wall {
      translation -4.01967 -0.08 -3.16151
      rotation 0 1 0 3.14159
      name "wall(4)"
      size 2 1 0.15
      appearance DEF SAND Sand {
      }
    }
    Wall {
      translation -2.1455 -0.08 -3.39978
      rotation 0 1 0 -2.8797953071795863
      name "wall(6)"
      size 2 1 0.15
      appearance DEF SAND Sand {
      }
    }
    Wall {
      translation -2.18749 -0.08 -1.79057
      rotation 0 1 0 3.14159
      name "wall(1)"
      size 2 1 0.15
      appearance DEF SAND Sand {
      }
    }
    Wall {
      translation -0.50902 -0.08 -2.23517
      rotation 0 1 0 -2.6179953071795863
      name "wall(2)"
      size 2 1 0.15
      appearance DEF SAND Sand {
      }
    }
    Wall {
      translation -1.84882 -0.08 -0.895825
      rotation 0 1 0 2.09439
      name "wall(7)"
      size 2 1 0.15
      appearance DEF SAND Sand {
      }
    }
    Wall {
      translation -1.42683 -0.08 0.795988
      rotation 0 -1 0 -1.5707953071795862
      name "wall(22)"
      size 2 1 0.15
      appearance DEF SAND Sand {
      }
    }
    Wall {
      translation -3.96683 -0.08 0.795988
      rotation 0 -1 0 -1.5707953071795862
      name "wall(23)"
      size 2 1 0.15
      appearance DEF SAND Sand {
      }
    }
    Wall {
      translation -3.73333 -0.08 2.13275
      rotation 0 1 0 -1.0472053071795866
      name "wall(24)"
      size 1 1 0.15
      appearance DEF SAND Sand {
      }
    }
    Wall {
      translation -3.32325 -0.08 2.175
      rotation 0 -1 0 1.83261
      name "wall(26)"
      size 1 1 0.15
      appearance DEF SAND Sand {
      }
    }
    Wall {
      translation -3.46045 -0.08 3.12697
      rotation 0 -1 0 1.57081
      name "wall(27)"
      size 1 1 0.15
      appearance DEF SAND Sand {
      }
    }
    Wall {
      translation -3.21683 -0.08 0.795988
      rotation 0 -1 0 -1.5707953071795862
      name "wall(25)"
      size 2 1 0.15
      appearance DEF SAND Sand {
      }
    }
    Wall {
      translation 0.21957 -0.08 -0.173232
      rotation 0 1 0 2.09439
      name "wall(8)"
      size 2 1 0.15
      appearance DEF SAND Sand {
      }
    }
    Wall {
      translation 0.0993956 -0.08 1.41778
      rotation 0 -1 0 -0.785395307179586
      name "wall(15)"
      size 2 1 0.15
      appearance DEF SAND Sand {
      }
    }
    Wall {
      translation 0.369391 -0.08 2.13778
      rotation 0 1 0 -5.307179586466759e-06
      name "wall(18)"
      size 2 1 0.15
      appearance DEF SAND Sand {
      }
    }
    Wall {
      translation 1.85139 -0.08 2.35257
      rotation 0 1 0 -0.2618053071795865
      name "wall(19)"
      size 2 1 0.15
      appearance DEF SAND Sand {
      }
    }
    Wall {
      translation 2.11985 -0.08 3.13757
      rotation 0 -1 0 1.04721
      name "wall(28)"
      size 2 1 0.15
      appearance DEF SAND Sand {
      }
    }
    Wall {
      translation 4.56315 -0.08 2.26959
      rotation 0 -1 0 1.04721
      name "wall(30)"
      size 2 1 0.15
      appearance DEF SAND Sand {
      }
    }
    Wall {
      translation 4.07345 -0.08 4.13459
      rotation 0 1 0 1.57078
      name "wall(31)"
      size 2 1 0.15
      appearance DEF SAND Sand {
      }
    }
    Wall {
      translation 4.06345 -0.08 2.44459
      rotation 0 1 0 1.57078
      name "wall(32)"
      size 2 1 0.15
      appearance DEF SAND Sand {
      }
    }
    Wall {
      translation 1.24927 -0.08 4.23884
      rotation 0 -1 0 0.785411
      name "wall(29)"
      size 2 1 0.15
      appearance DEF SAND Sand {
      }
    }
    Wall {
      translation 0.52927 -0.08 4.23884
      rotation 0 1 0 -1.5708053071795867
      name "wall(33)"
      size 2 1 0.15
      appearance DEF SAND Sand {
      }
    }
    Wall {
      translation -1.45073 -0.08 4.23884
      rotation 0 1 0 -1.5708053071795867
      name "wall(34)"
      size 2 1 0.15
      appearance DEF SAND Sand {
      }
    }
    Wall {
      translation -1.93073 -0.08 4.23884
      rotation 0 1 0 -2.094405307179586
      name "wall(35)"
      size 2 1 0.15
      appearance DEF SAND Sand {
      }
    }
    Wall {
      translation 2.86139 -0.08 1.66257
      rotation 0 1 0 -1.5708053071795867
      name "wall(20)"
      size 2 1 0.15
      appearance DEF SAND Sand {
      }
    }
    Wall {
      translation 2.80483 -0.08 1.09126
      rotation 0 1 0 -2.3562053071795863
      name "wall(21)"
      size 2 1 0.15
      appearance DEF SAND Sand {
      }
    }
    Wall {
      translation 0.558211 -0.08 -1.48776
      rotation 0 1 0 0.523595
      name "wall(9)"
      size 2 1 0.15
      appearance DEF SAND Sand {
      }
    }
    Wall {
      translation 1.09038 -0.08 -1.80397
      rotation 0 1 0 0.785394
      name "wall(17)"
      size 2 1 0.15
      appearance DEF SAND Sand {
      }
    }
    Wall {
      translation 2.53547 -0.08 -1.48714
      rotation 0 1 0 -5.307179586466759e-06
      name "wall(11)"
      size 2 1 0.15
      appearance DEF SAND Sand {
      }
    }
    Wall {
      translation 2.64704 -0.08 -1.97269
      rotation 0 -1 0 0.523606
      name "wall(16)"
      size 2 1 0.15
      appearance DEF SAND Sand {
      }
    }
    Wall {
      translation 1.29709 -0.08 -4.47214
      rotation 0 1 0 -0.5236053071795865
      name "wall(12)"
      size 2 1 0.15
      appearance DEF SAND Sand {
      }
    }
    Wall {
      translation 2.99339 -0.08 -3.74932
      rotation 0 1 0 2.87979
      name "wall(13)"
      size 2 1 0.15
      appearance DEF SAND Sand {
      }
    }
    Wall {
      translation 4.3154 -0.08 -3.18345
      rotation 0 -1 0 -2.6179953071795863
      name "wall(14)"
      size 2 1 0.15
      appearance DEF SAND Sand {
      }
    }
    Wall {
      translation 3.4905 -0.08 -0.541368
      rotation 0 1 0 -1.5708053071795867
      name "wall(10)"
      size 2 1 0.15
      appearance DEF SAND Sand {
      }
    }
    Pit {
      translation 0 0.12 0
      size 10 2 10
      noiseAmplitude 0.85
    }
  ]
}
