#VRML_SIM R2020a utf8
WorldInfo {
  basicTimeStep 8
}
Viewpoint {
  orientation -0.28800623026392236 -0.8895913956152434 -0.35451313117638955 1.887832834495092
  position -8.90690534870912 7.045042880577179 -3.200240392738593
}
TexturedBackground {
}
TexturedBackgroundLight {
}
RectangleArena {
  floorSize 10 10
  floorTileSize 1 1
  wallThickness 0.025
  wallHeight 2
}
Robot {
  translation -0.4301217474491246 0.23748726570611273 0.5478022311075235
  rotation -0.06784936586832502 0.9906720800618912 -0.11817484223434396 0.6456316183462141
  children [
    Camera {
      translation 0.1 -1.12008e-13 -1.49482e-07
      rotation 8.684229999951365e-07 -0.9999999999943995 3.2321499999818985e-06 1.5707853071795865
      children [
        DEF CAM_SHAPE Shape {
          appearance MattePaint {
            baseColor 0.7 0.1 0.1
          }
          geometry Cylinder {
            height 0.05
            radius 0.0125
          }
        }
      ]
      name "Hexabot_Camera"
      boundingObject USE CAM_SHAPE
      physics Physics {
      }
      lens Lens {
      }
      focus Focus {
      }
    }
    DEF BODY_TRAN Transform {
      children [
        DEF BODY Shape {
          appearance MattePaint {
            baseColor 0.1 0.1 0.7
          }
          geometry Box {
            size 0.2 0.05 0.125
          }
        }
      ]
    }
    Hinge2Joint {
      jointParameters HingeJointParameters {
        position -8.99095842076538e-06
      }
      jointParameters2 JointParameters {
        position -6.079741408854054e-06
      }
      device [
        DEF SHOULDER_2_x RotationalMotor {
          name "Hexabot_Leg0_Motor1"
        }
      ]
      device2 [
        DEF SHOULDER_0_y RotationalMotor {
          name "Hexabot_Leg0_Motor2"
        }
      ]
      endPoint DEF SHOULDER_0 Solid {
        translation 0.07999999716812879 3.621685710281461e-05 0.07000003611670848
        rotation 3.0398665703128562e-06 0.9999999999852749 -4.495482239886574e-06 3.1415908145532376
        children [
          Transform {
            children [
              DEF FEMUR_0 Solid {
                translation 0 0.025981 -0.0450019
                rotation 1 0 0 0.523599
                children [
                  HingeJoint {
                    jointParameters HingeJointParameters {
                      position 3.860467880110018e-06
                      axis 0 0 1
                    }
                    device [
                      DEF ELBOW_0 RotationalMotor {
                        name "Hexabot_Leg0_Motor3"
                      }
                    ]
                    endPoint Solid {
                      translation 3.5761452510608655e-17 -9.26344729779238e-12 -0.059999999999999276
                      rotation -7.771335115061502e-11 -7.667771810811849e-11 -0.9999999999999999 1.5707914467107948
                      children [
                        Transform {
                          children [
                            Solid {
                              translation 0.0824507 0 0.0210637
                              rotation 0 -1 0 1.8325953071795864
                              children [
                                Shape {
                                  appearance MattePaint {
                                    baseColor 0.1 0.1 0.6
                                  }
                                  geometry DEF TIBIA_SHAPE Box {
                                    size 0.025 0.025 0.15
                                  }
                                }
                              ]
                              boundingObject USE TIBIA_SHAPE
                              physics Physics {
                              }
                            }
                            DEF ELBOW_SHAPE Shape {
                              appearance MattePaint {
                                baseColor 0 0 0
                              }
                              geometry Cylinder {
                                height 0.025
                                radius 0.0125
                              }
                            }
                          ]
                        }
                      ]
                      boundingObject USE ELBOW_SHAPE
                      physics Physics {
                      }
                      linearVelocity 3.982774194627548e-06 -2.1702156498502947e-07 -3.529519771910111e-06
                      angularVelocity 1.6348186968634307e-06 2.4577534887277396e-06 2.121472925070721e-06
                    }
                  }
                  DEF FEMUR_SHAPE Shape {
                    appearance MattePaint {
                      baseColor 0.2 0.2 1
                    }
                    geometry Box {
                      size 0.025 0.025 0.1
                    }
                  }
                ]
                boundingObject USE FEMUR_SHAPE
                physics Physics {
                }
              }
              Shape {
                appearance MattePaint {
                  baseColor 0 0 0
                }
                geometry DEF SHOULDER_SHAPE Sphere {
                  radius 0.02
                }
              }
            ]
          }
        ]
        name "solid(5)"
        boundingObject USE SHOULDER_SHAPE
        physics Physics {
        }
        linearVelocity 3.727316716693242e-06 -2.0553750447447336e-07 -3.3603878796639394e-06
        angularVelocity 3.879771148861982e-07 1.2858419522588594e-06 6.087004875875185e-07
      }
    }
    Hinge2Joint {
      jointParameters HingeJointParameters {
        position -7.4804096911981355e-06
      }
      jointParameters2 JointParameters {
        position -7.767562288567313e-06
      }
      device [
        DEF SHOULDER_1_x RotationalMotor {
          name "Hexabot_Leg1_Motor1"
        }
      ]
      device2 [
        DEF SHOULDER_1_y RotationalMotor {
          name "Hexabot_Leg1_Motor2"
        }
      ]
      endPoint DEF SHOULDER_0 Solid {
        translation 6.419252862070583e-10 1.312010491527781e-05 0.06999996638776472
        rotation 3.883776181804017e-06 0.9999999999854637 -3.7402099984522426e-06 3.141590000069465
        children [
          Transform {
            children [
              DEF FEMUR_0 Solid {
                translation 0 0.0259808 -0.045
                rotation 1 0 0 0.523599
                children [
                  HingeJoint {
                    jointParameters HingeJointParameters {
                      position 3.7441923660738216e-06
                    }
                    device [
                      DEF ELBOW_1 RotationalMotor {
                        name "Hexabot_Leg1_Motor3"
                      }
                    ]
                    endPoint Solid {
                      translation 0 2.2463876765755282e-07 -0.059999999999579695
                      rotation 1.8719918157684023e-06 1.8719895537600593e-06 -0.9999999999964957 1.5707953071847136
                      children [
                        Transform {
                          children [
                            Solid {
                              translation 0.0824507 0 0.0210637
                              rotation 0 -1 0 1.8325953071795864
                              children [
                                Shape {
                                  appearance MattePaint {
                                    baseColor 0.1 0.1 0.6
                                  }
                                  geometry DEF TIBIA_SHAPE Box {
                                    size 0.025 0.025 0.15
                                  }
                                }
                              ]
                              boundingObject USE TIBIA_SHAPE
                              physics Physics {
                              }
                            }
                            DEF ELBOW_SHAPE Shape {
                              appearance MattePaint {
                                baseColor 0 0 0
                              }
                              geometry Cylinder {
                                height 0.025
                                radius 0.0125
                              }
                            }
                          ]
                        }
                      ]
                      boundingObject USE ELBOW_SHAPE
                      physics Physics {
                      }
                      linearVelocity 3.887513762237956e-06 -2.631652574082892e-07 -3.3604139472824905e-06
                      angularVelocity 3.9675393083886884e-07 1.284807986564885e-06 5.935080570884341e-07
                    }
                  }
                  DEF FEMUR_SHAPE Shape {
                    appearance MattePaint {
                      baseColor 0.2 0.2 1
                    }
                    geometry Box {
                      size 0.025 0.025 0.1
                    }
                  }
                ]
                boundingObject USE FEMUR_SHAPE
                physics Physics {
                }
              }
              Shape {
                appearance MattePaint {
                  baseColor 0 0 0
                }
                geometry DEF SHOULDER_SHAPE Sphere {
                  radius 0.02
                }
              }
            ]
          }
        ]
        name "solid(4)"
        boundingObject USE SHOULDER_SHAPE
        physics Physics {
        }
        linearVelocity 3.7751889734403665e-06 -2.644029156858318e-07 -3.282633635024644e-06
        angularVelocity 3.967472623785988e-07 1.2847979585763453e-06 5.93505273832809e-07
      }
    }
    Hinge2Joint {
      jointParameters HingeJointParameters {
        position -8.490743182093741e-06
      }
      jointParameters2 JointParameters {
        position -8.619925973284504e-06
      }
      device [
        DEF SHOULDER_2_x RotationalMotor {
        }
      ]
      device2 [
        DEF SHOULDER_2_y RotationalMotor {
        }
      ]
      endPoint DEF SHOULDER_0 Solid {
        translation -0.07999999729275897 1.3698735056402498e-05 0.06999996166145624
        rotation 4.3099573485227744e-06 0.9999999999817006 -4.245377309680592e-06 3.141589997460638
        children [
          Transform {
            children [
              DEF FEMUR_0 Solid {
                translation 0 0.0259808 -0.045
                rotation 1 0 0 0.523599
                children [
                  HingeJoint {
                    jointParameters HingeJointParameters {
                      position 4.138827786386812e-06
                    }
                    device [
                      DEF ELBOW_2 RotationalMotor {
                        name "Hexabot_Leg2_Motor3"
                      }
                    ]
                    endPoint Solid {
                      translation 0 2.483162118991748e-07 -0.05999999999948699
                      rotation 2.0693038757208123e-06 2.069301765826233e-06 -0.999999999995718 1.5707953071837395
                      children [
                        Transform {
                          children [
                            Solid {
                              translation 0.0824507 0 0.0210637
                              rotation 0 -1 0 1.8325953071795864
                              children [
                                Shape {
                                  appearance MattePaint {
                                    baseColor 0.1 0.1 0.6
                                  }
                                  geometry DEF TIBIA_SHAPE Box {
                                    size 0.025 0.025 0.15
                                  }
                                }
                              ]
                              boundingObject USE TIBIA_SHAPE
                              physics Physics {
                              }
                            }
                            DEF ELBOW_SHAPE Shape {
                              appearance MattePaint {
                                baseColor 0 0 0
                              }
                              geometry Cylinder {
                                height 0.025
                                radius 0.0125
                              }
                            }
                          ]
                        }
                      ]
                      boundingObject USE ELBOW_SHAPE
                      physics Physics {
                      }
                      linearVelocity 3.9446424647106625e-06 -3.200742513117787e-07 -3.275469313271162e-06
                      angularVelocity 3.969922970488706e-07 1.2847938053652561e-06 5.934397733217962e-07
                    }
                  }
                  DEF FEMUR_SHAPE Shape {
                    appearance MattePaint {
                      baseColor 0.2 0.2 1
                    }
                    geometry Box {
                      size 0.025 0.025 0.1
                    }
                  }
                ]
                boundingObject USE FEMUR_SHAPE
                physics Physics {
                }
              }
              Shape {
                appearance MattePaint {
                  baseColor 0 0 0
                }
                geometry DEF SHOULDER_SHAPE Sphere {
                  radius 0.02
                }
              }
            ]
          }
        ]
        name "solid(3)"
        boundingObject USE SHOULDER_SHAPE
        physics Physics {
        }
        linearVelocity 3.832304324570853e-06 -3.2128203131274403e-07 -3.1977057406666945e-06
        angularVelocity 3.9693867771915487e-07 1.2847887385247115e-06 5.934718491723714e-07
      }
    }
    Hinge2Joint {
      jointParameters HingeJointParameters {
        position 2.367253632350129e-05
      }
      jointParameters2 JointParameters {
        position 2.0876868867250972e-05
      }
      device [
        DEF SHOULDER_3_x RotationalMotor {
          name "Hexabot_Leg3_Motor1"
        }
      ]
      device2 [
        DEF SHOULDER_3_y RotationalMotor {
          name "Hexabot_Leg3_Motor2"
        }
      ]
      endPoint DEF SHOULDER_0 Solid {
        translation -0.07999999898889448 1.2015421686600707e-05 -0.059999969653951137
        rotation 0.75000543496176 -7.828882557995442e-06 0.6614316650014044 3.156314987298764e-05
        children [
          Transform {
            translation 0 0 -0.01
            children [
              DEF FEMUR_0 Solid {
                translation 0 0.0259808 -0.045
                rotation 1 0 0 0.523599
                children [
                  HingeJoint {
                    jointParameters HingeJointParameters {
                      position -0.028888453188976558
                    }
                    device [
                      DEF ELBOW_3 RotationalMotor {
                        name "Hexabot_Leg3_Motor3"
                      }
                    ]
                    endPoint Solid {
                      translation 0 -0.0017330661133834592 -0.05997496545931996
                      rotation -0.014442232648256188 -0.014442217922740284 -0.9997914003719003 1.571003928565993
                      children [
                        Transform {
                          children [
                            Solid {
                              translation 0.0824507 0 0.0210637
                              rotation 0 -1 0 1.8325953071795864
                              children [
                                Shape {
                                  appearance MattePaint {
                                    baseColor 0.1 0.1 0.6
                                  }
                                  geometry DEF TIBIA_SHAPE Box {
                                    size 0.025 0.025 0.15
                                  }
                                }
                              ]
                              boundingObject USE TIBIA_SHAPE
                              physics Physics {
                              }
                            }
                            DEF ELBOW_SHAPE Shape {
                              appearance MattePaint {
                                baseColor 0 0 0
                              }
                              geometry Cylinder {
                                height 0.025
                                radius 0.0125
                              }
                            }
                          ]
                        }
                      ]
                      boundingObject USE ELBOW_SHAPE
                      physics Physics {
                      }
                      linearVelocity 3.543217575140097e-06 -3.305362894705837e-07 -3.005536207560557e-06
                      angularVelocity 4.20768674754244e-07 1.282582381193067e-06 5.660776866025617e-07
                    }
                  }
                  DEF FEMUR_SHAPE Shape {
                    appearance MattePaint {
                      baseColor 0.2 0.2 1
                    }
                    geometry Box {
                      size 0.025 0.025 0.1
                    }
                  }
                ]
                boundingObject USE FEMUR_SHAPE
                physics Physics {
                }
              }
              Shape {
                appearance MattePaint {
                  baseColor 0 0 0
                }
                geometry DEF SHOULDER_SHAPE Sphere {
                  radius 0.02
                }
              }
            ]
          }
        ]
        name "solid(2)"
        boundingObject USE SHOULDER_SHAPE
        physics Physics {
        }
        linearVelocity 3.6229341623331598e-06 -3.2713238792498e-07 -3.055384507574142e-06
        angularVelocity 4.0531855266594865e-07 1.2835883401887845e-06 5.783288080087489e-07
      }
    }
    Hinge2Joint {
      jointParameters HingeJointParameters {
        position 9.007224807288738e-06
      }
      jointParameters2 JointParameters {
        position 9.29126224306279e-06
      }
      device [
        DEF SHOULDER_4_x RotationalMotor {
          name "Hexabot_Leg4_Motor1"
        }
      ]
      device2 [
        DEF SHOULDER_4_y RotationalMotor {
          name "Hexabot_Leg4_Motor2"
        }
      ]
      endPoint DEF SHOULDER_0 Solid {
        translation -1.3899822007574243e-09 1.294861688223761e-05 -0.059999964732941426
        rotation 0.6960468982088356 -3.233577132387624e-06 0.7179963199650838 1.2940523917169885e-05
        children [
          Transform {
            translation 0 0 -0.01
            children [
              DEF FEMUR_0 Solid {
                translation 0 0.0259808 -0.045
                rotation 1 0 0 0.523599
                children [
                  HingeJoint {
                    jointParameters HingeJointParameters {
                      position 4.850350339888724e-06
                    }
                    device [
                      DEF ELBOW_4 RotationalMotor {
                        name "Hexabot_Leg4_Motor3"
                      }
                    ]
                    endPoint Solid {
                      translation 0 2.9104582612477833e-07 -0.05999999999929424
                      rotation 2.425384357331224e-06 2.4253818843731485e-06 -0.9999999999941174 1.5707953071853384
                      children [
                        Transform {
                          children [
                            Solid {
                              translation 0.0824507 0 0.0210637
                              rotation 0 -1 0 1.8325953071795864
                              children [
                                Shape {
                                  appearance MattePaint {
                                    baseColor 0.1 0.1 0.6
                                  }
                                  geometry DEF TIBIA_SHAPE Box {
                                    size 0.025 0.025 0.15
                                  }
                                }
                              ]
                              boundingObject USE TIBIA_SHAPE
                              physics Physics {
                              }
                            }
                            DEF ELBOW_SHAPE Shape {
                              appearance MattePaint {
                                baseColor 0 0 0
                              }
                              geometry Cylinder {
                                height 0.025
                                radius 0.0125
                              }
                            }
                          ]
                        }
                      ]
                      boundingObject USE ELBOW_SHAPE
                      physics Physics {
                      }
                      linearVelocity 3.5053512537528586e-06 -2.7689376407564066e-07 -3.0751393496298888e-06
                      angularVelocity 3.967354429352855e-07 1.2847605754080947e-06 5.935114879400053e-07
                    }
                  }
                  DEF FEMUR_SHAPE Shape {
                    appearance MattePaint {
                      baseColor 0.2 0.2 1
                    }
                    geometry Box {
                      size 0.025 0.025 0.1
                    }
                  }
                ]
                boundingObject USE FEMUR_SHAPE
                physics Physics {
                }
              }
              Shape {
                appearance MattePaint {
                  baseColor 0 0 0
                }
                geometry DEF SHOULDER_SHAPE Sphere {
                  radius 0.02
                }
              }
            ]
          }
        ]
        name "solid(1)"
        boundingObject USE SHOULDER_SHAPE
        physics Physics {
        }
        linearVelocity 3.5761183665016534e-06 -2.7155166485005825e-07 -3.134031971348838e-06
        angularVelocity 3.9673287375609726e-07 1.284760957649876e-06 5.935131589669597e-07
      }
    }
    Hinge2Joint {
      jointParameters HingeJointParameters {
        position 6.32011059773487e-06
      }
      jointParameters2 JointParameters {
        position 6.360841150752749e-06
      }
      device [
        DEF SHOULDER_5_x RotationalMotor {
          name "Hexabot_Leg5_Motor1"
        }
      ]
      device2 [
        DEF SHOULDER_5_y RotationalMotor {
          name "Hexabot_Leg5_Motor2"
        }
      ]
      endPoint DEF SHOULDER_0 Solid {
        translation 0.07999999619032125 1.3420904867160744e-05 -0.05999995937192261
        rotation 0.704831955501031 -2.2416620534658024e-06 0.7093743119817406 8.966834881959627e-06
        children [
          Transform {
            translation 0 0 -0.01
            children [
              DEF FEMUR_0 Solid {
                translation 0 0.0259808 -0.045
                rotation 1 0 0 0.523599
                children [
                  HingeJoint {
                    jointParameters HingeJointParameters {
                      position 4.8377700586876924e-05
                    }
                    device [
                      DEF ELBOW_5 RotationalMotor {
                        name "Hexabot_Leg5_Motor3"
                      }
                    ]
                    endPoint Solid {
                      translation 0 2.9026620340803782e-06 -0.05999999992978783
                      rotation 2.4188874947338135e-05 2.4188850284003206e-05 -0.999999999414899 1.5707953077646737
                      children [
                        Transform {
                          children [
                            Solid {
                              translation 0.0824507 0 0.0210637
                              rotation 0 -1 0 1.8325953071795864
                              children [
                                Shape {
                                  appearance MattePaint {
                                    baseColor 0.1 0.1 0.6
                                  }
                                  geometry DEF TIBIA_SHAPE Box {
                                    size 0.025 0.025 0.15
                                  }
                                }
                              ]
                              boundingObject USE TIBIA_SHAPE
                              physics Physics {
                              }
                            }
                            DEF ELBOW_SHAPE Shape {
                              appearance MattePaint {
                                baseColor 0 0 0
                              }
                              geometry Cylinder {
                                height 0.025
                                radius 0.0125
                              }
                            }
                          ]
                        }
                      ]
                      boundingObject USE ELBOW_SHAPE
                      physics Physics {
                      }
                      recognitionColors [
                        0 0 0
                      ]
                      linearVelocity 3.4482125211196056e-06 -2.184276156412184e-07 -3.1601462962802763e-06
                      angularVelocity 3.966560823086432e-07 1.284788524627456e-06 5.935664855104295e-07
                    }
                  }
                  DEF FEMUR_SHAPE Shape {
                    appearance MattePaint {
                      baseColor 0.2 0.2 1
                    }
                    geometry Box {
                      size 0.025 0.025 0.1
                    }
                  }
                ]
                boundingObject USE FEMUR_SHAPE
                physics Physics {
                }
              }
              Shape {
                appearance MattePaint {
                  baseColor 0 0 0
                }
                geometry DEF SHOULDER_SHAPE Sphere {
                  radius 0.02
                }
              }
            ]
          }
        ]
        boundingObject USE SHOULDER_SHAPE
        physics Physics {
        }
        linearVelocity 3.519000352525196e-06 -2.138956141781667e-07 -3.218987315266845e-06
        angularVelocity 3.9667496703714185e-07 1.28478218168633e-06 5.935473597058091e-07
      }
    }
  ]
  name "Hexabot"
  boundingObject USE BODY_TRAN
  physics Physics {
  }
  controller "my_controller_c"
}
DEF Cave_system Group {
  children [
    Wall {
      translation -4.04556 -0.08 -2.02135
      rotation 0 1 0 2.87979
      size 2 1 0.15
      appearance DEF SAND Sand {
      }
    }
    Wall {
      translation -4.15892 -0.08 -4.22603
      rotation 0 1 0 2.87979
      name "wall(3)"
      size 2 1 0.15
      appearance DEF SAND Sand {
      }
    }
    Wall {
      translation -2.51674 -0.08 -3.78592
      rotation 0 1 0 2.87979
      name "wall(5)"
      size 2 1 0.15
      appearance DEF SAND Sand {
      }
    }
    Wall {
      translation -4.01967 -0.08 -3.16151
      rotation 0 1 0 3.14159
      name "wall(4)"
      size 2 1 0.15
      appearance DEF SAND Sand {
      }
    }
    Wall {
      translation -2.1455 -0.08 -3.39978
      rotation 0 1 0 -2.8797953071795863
      name "wall(6)"
      size 2 1 0.15
      appearance DEF SAND Sand {
      }
    }
    Wall {
      translation -2.18749 -0.08 -1.79057
      rotation 0 1 0 3.14159
      name "wall(1)"
      size 2 1 0.15
      appearance DEF SAND Sand {
      }
    }
    Wall {
      translation -0.50902 -0.08 -2.23517
      rotation 0 1 0 -2.6179953071795863
      name "wall(2)"
      size 2 1 0.15
      appearance DEF SAND Sand {
      }
    }
    Wall {
      translation -1.84882 -0.08 -0.895825
      rotation 0 1 0 2.09439
      name "wall(7)"
      size 2 1 0.15
      appearance DEF SAND Sand {
      }
    }
    Wall {
      translation -1.42683 -0.08 0.795988
      rotation 0 -1 0 -1.5707953071795862
      name "wall(22)"
      size 2 1 0.15
      appearance DEF SAND Sand {
      }
    }
    Wall {
      translation -3.96683 -0.08 0.795988
      rotation 0 -1 0 -1.5707953071795862
      name "wall(23)"
      size 2 1 0.15
      appearance DEF SAND Sand {
      }
    }
    Wall {
      translation -3.73333 -0.08 2.13275
      rotation 0 1 0 -1.0472053071795866
      name "wall(24)"
      size 1 1 0.15
      appearance DEF SAND Sand {
      }
    }
    Wall {
      translation -3.32325 -0.08 2.175
      rotation 0 -1 0 1.83261
      name "wall(26)"
      size 1 1 0.15
      appearance DEF SAND Sand {
      }
    }
    Wall {
      translation -3.46045 -0.08 3.12697
      rotation 0 -1 0 1.57081
      name "wall(27)"
      size 1 1 0.15
      appearance DEF SAND Sand {
      }
    }
    Wall {
      translation -3.21683 -0.08 0.795988
      rotation 0 -1 0 -1.5707953071795862
      name "wall(25)"
      size 2 1 0.15
      appearance DEF SAND Sand {
      }
    }
    Wall {
      translation 0.21957 -0.08 -0.173232
      rotation 0 1 0 2.09439
      name "wall(8)"
      size 2 1 0.15
      appearance DEF SAND Sand {
      }
    }
    Wall {
      translation 0.0993956 -0.08 1.41778
      rotation 0 -1 0 -0.785395307179586
      name "wall(15)"
      size 2 1 0.15
      appearance DEF SAND Sand {
      }
    }
    Wall {
      translation 0.369391 -0.08 2.13778
      rotation 0 1 0 -5.307179586466759e-06
      name "wall(18)"
      size 2 1 0.15
      appearance DEF SAND Sand {
      }
    }
    Wall {
      translation 1.85139 -0.08 2.35257
      rotation 0 1 0 -0.2618053071795865
      name "wall(19)"
      size 2 1 0.15
      appearance DEF SAND Sand {
      }
    }
    Wall {
      translation 2.11985 -0.08 3.13757
      rotation 0 -1 0 1.04721
      name "wall(28)"
      size 2 1 0.15
      appearance DEF SAND Sand {
      }
    }
    Wall {
      translation 4.56315 -0.08 2.26959
      rotation 0 -1 0 1.04721
      name "wall(30)"
      size 2 1 0.15
      appearance DEF SAND Sand {
      }
    }
    Wall {
      translation 4.07345 -0.08 4.13459
      rotation 0 1 0 1.57078
      name "wall(31)"
      size 2 1 0.15
      appearance DEF SAND Sand {
      }
    }
    Wall {
      translation 4.06345 -0.08 2.44459
      rotation 0 1 0 1.57078
      name "wall(32)"
      size 2 1 0.15
      appearance DEF SAND Sand {
      }
    }
    Wall {
      translation 1.24927 -0.08 4.23884
      rotation 0 -1 0 0.785411
      name "wall(29)"
      size 2 1 0.15
      appearance DEF SAND Sand {
      }
    }
    Wall {
      translation 0.52927 -0.08 4.23884
      rotation 0 1 0 -1.5708053071795867
      name "wall(33)"
      size 2 1 0.15
      appearance DEF SAND Sand {
      }
    }
    Wall {
      translation -1.45073 -0.08 4.23884
      rotation 0 1 0 -1.5708053071795867
      name "wall(34)"
      size 2 1 0.15
      appearance DEF SAND Sand {
      }
    }
    Wall {
      translation -1.93073 -0.08 4.23884
      rotation 0 1 0 -2.094405307179586
      name "wall(35)"
      size 2 1 0.15
      appearance DEF SAND Sand {
      }
    }
    Wall {
      translation 2.86139 -0.08 1.66257
      rotation 0 1 0 -1.5708053071795867
      name "wall(20)"
      size 2 1 0.15
      appearance DEF SAND Sand {
      }
    }
    Wall {
      translation 2.80483 -0.08 1.09126
      rotation 0 1 0 -2.3562053071795863
      name "wall(21)"
      size 2 1 0.15
      appearance DEF SAND Sand {
      }
    }
    Wall {
      translation 0.558211 -0.08 -1.48776
      rotation 0 1 0 0.523595
      name "wall(9)"
      size 2 1 0.15
      appearance DEF SAND Sand {
      }
    }
    Wall {
      translation 1.09038 -0.08 -1.80397
      rotation 0 1 0 0.785394
      name "wall(17)"
      size 2 1 0.15
      appearance DEF SAND Sand {
      }
    }
    Wall {
      translation 2.53547 -0.08 -1.48714
      rotation 0 1 0 -5.307179586466759e-06
      name "wall(11)"
      size 2 1 0.15
      appearance DEF SAND Sand {
      }
    }
    Wall {
      translation 2.64704 -0.08 -1.97269
      rotation 0 -1 0 0.523606
      name "wall(16)"
      size 2 1 0.15
      appearance DEF SAND Sand {
      }
    }
    Wall {
      translation 1.29709 -0.08 -4.47214
      rotation 0 1 0 -0.5236053071795865
      name "wall(12)"
      size 2 1 0.15
      appearance DEF SAND Sand {
      }
    }
    Wall {
      translation 2.99339 -0.08 -3.74932
      rotation 0 1 0 2.87979
      name "wall(13)"
      size 2 1 0.15
      appearance DEF SAND Sand {
      }
    }
    Wall {
      translation 4.3154 -0.08 -3.18345
      rotation 0 -1 0 -2.6179953071795863
      name "wall(14)"
      size 2 1 0.15
      appearance DEF SAND Sand {
      }
    }
    Wall {
      translation 3.4905 -0.08 -0.541368
      rotation 0 1 0 -1.5708053071795867
      name "wall(10)"
      size 2 1 0.15
      appearance DEF SAND Sand {
      }
    }
    Pit {
      translation 0 0.12 0
      size 10 2 10
      noiseAmplitude 0.85
    }
  ]
}
